Workbook

Sheet Economic Hierarchy Scores w HHI
A1: US | B1: Armenia | C1: Austria | D1: Azerbaijan | E1: Belarus | F1: Belgium | G1: Bulgaria | H1: Croatia | I1: Cyprus | J1: Czech | K1: Denmark | L1: Estonia | M1: Finland | N1: France | O1: Georgia | P1: Germany | Q1: Greece | R1: Hungary | S1: Ireland | T1: Italy | U1: Kazakhstan | V1: Kyrgyzstan | W1: latvia | X1: Lithuania | Y1: Luxembourg | Z1: Malta | AA1: Moldova | AB1: Netherlands | AC1: Poland | AD1: Portugal | AE1: Romania | AF1: Slovakia | AG1: Slovenia | AH1: Spain | AI1: Sweden | AJ1: Tajikistan | AK1: Turkmenistan | AL1: UK | AM1: Ukraine | AN1: Uzbekistan
A2: 1991
A3: 1992
A4: 1993
A5: 1994
A6: 1995
A7: 1996
A8: 1997
A9: 1998
A10: 1999
A11: 2000 | B11: ='Import HHI Hierarchy Scores'!B11*0.25+'Export HHI Hierarchy Scores'!B11*0.25+'Import Dependence'!B11*0.25+'Export Dependence'!B11*0.25 -> 0.06425 | C11: ='Import HHI Hierarchy Scores'!C11*0.25+'Export HHI Hierarchy Scores'!C11*0.25+'Import Dependence'!C11*0.25+'Export Dependence'!C11*0.25 -> 0.14768515 | D11: ='Import HHI Hierarchy Scores'!D11*0.25+'Export HHI Hierarchy Scores'!D11*0.25+'Import Dependence'!D11*0.25+'Export Dependence'!D11*0.25 -> 0.04445 | E11: ='Import HHI Hierarchy Scores'!E11*0.25+'Export HHI Hierarchy Scores'!E11*0.25+'Import Dependence'!E11*0.25+'Export Dependence'!E11*0.25 -> 0.507675 | F11: ='Import HHI Hierarchy Scores'!F11*0.25+'Export HHI Hierarchy Scores'!F11*0.25+'Import Dependence'!F11*0.25+'Export Dependence'!F11*0.25 -> 0.028582874 | G11: ='Import HHI Hierarchy Scores'!G11*0.25+'Export HHI Hierarchy Scores'!G11*0.25+'Import Dependence'!G11*0.25+'Export Dependence'!G11*0.25 -> 0.015448358 | H11: ='Import HHI Hierarchy Scores'!H11*0.25+'Export HHI Hierarchy Scores'!H11*0.25+'Import Dependence'!H11*0.25+'Export Dependence'!H11*0.25 -> 0.0070494003 | I11: ='Import HHI Hierarchy Scores'!I11*0.25+'Export HHI Hierarchy Scores'!I11*0.25+'Import Dependence'!I11*0.25+'Export Dependence'!I11*0.25 -> 0.041016785 | ... AN11: ='Import HHI Hierarchy Scores'!AN11*0.25+'Export HHI Hierarchy Scores'!AN11*0.25+'Import Dependence'!AN11*0.25+'Export Dependence'!AN11*0.25 -> 0.024825
A12: 2001 | B12: ='Import HHI Hierarchy Scores'!B12*0.25+'Export HHI Hierarchy Scores'!B12*0.25+'Import Dependence'!B12*0.25+'Export Dependence'!B12*0.25 -> 0.067475 | C12: ='Import HHI Hierarchy Scores'!C12*0.25+'Export HHI Hierarchy Scores'!C12*0.25+'Import Dependence'!C12*0.25+'Export Dependence'!C12*0.25 -> 0.14746781 | D12: ='Import HHI Hierarchy Scores'!D12*0.25+'Export HHI Hierarchy Scores'!D12*0.25+'Import Dependence'!D12*0.25+'Export Dependence'!D12*0.25 -> 0.16045 | E12: ='Import HHI Hierarchy Scores'!E12*0.25+'Export HHI Hierarchy Scores'!E12*0.25+'Import Dependence'!E12*0.25+'Export Dependence'!E12*0.25 -> 0.5073 | F12: ='Import HHI Hierarchy Scores'!F12*0.25+'Export HHI Hierarchy Scores'!F12*0.25+'Import Dependence'!F12*0.25+'Export Dependence'!F12*0.25 -> 0.031438852 | G12: ='Import HHI Hierarchy Scores'!G12*0.25+'Export HHI Hierarchy Scores'!G12*0.25+'Import Dependence'!G12*0.25+'Export Dependence'!G12*0.25 -> 0.013896119 | H12: ='Import HHI Hierarchy Scores'!H12*0.25+'Export HHI Hierarchy Scores'!H12*0.25+'Import Dependence'!H12*0.25+'Export Dependence'!H12*0.25 -> 0.007117909 | I12: ='Import HHI Hierarchy Scores'!I12*0.25+'Export HHI Hierarchy Scores'!I12*0.25+'Import Dependence'!I12*0.25+'Export Dependence'!I12*0.25 -> 0.04527698 | ... AN12: ='Import HHI Hierarchy Scores'!AN12*0.25+'Export HHI Hierarchy Scores'!AN12*0.25+'Import Dependence'!AN12*0.25+'Export Dependence'!AN12*0.25 -> 0.023
A13: 2002 | B13: ='Import HHI Hierarchy Scores'!B13*0.25+'Export HHI Hierarchy Scores'!B13*0.25+'Import Dependence'!B13*0.25+'Export Dependence'!B13*0.25 -> 0.054675 | C13: ='Import HHI Hierarchy Scores'!C13*0.25+'Export HHI Hierarchy Scores'!C13*0.25+'Import Dependence'!C13*0.25+'Export Dependence'!C13*0.25 -> 0.14620651 | D13: ='Import HHI Hierarchy Scores'!D13*0.25+'Export HHI Hierarchy Scores'!D13*0.25+'Import Dependence'!D13*0.25+'Export Dependence'!D13*0.25 -> 0.01885 | E13: ='Import HHI Hierarchy Scores'!E13*0.25+'Export HHI Hierarchy Scores'!E13*0.25+'Import Dependence'!E13*0.25+'Export Dependence'!E13*0.25 -> 0.381225 | F13: ='Import HHI Hierarchy Scores'!F13*0.25+'Export HHI Hierarchy Scores'!F13*0.25+'Import Dependence'!F13*0.25+'Export Dependence'!F13*0.25 -> 0.028234743 | G13: ='Import HHI Hierarchy Scores'!G13*0.25+'Export HHI Hierarchy Scores'!G13*0.25+'Import Dependence'!G13*0.25+'Export Dependence'!G13*0.25 -> 0.014100306 | H13: ='Import HHI Hierarchy Scores'!H13*0.25+'Export HHI Hierarchy Scores'!H13*0.25+'Import Dependence'!H13*0.25+'Export Dependence'!H13*0.25 -> 0.0071346889 | I13: ='Import HHI Hierarchy Scores'!I13*0.25+'Export HHI Hierarchy Scores'!I13*0.25+'Import Dependence'!I13*0.25+'Export Dependence'!I13*0.25 -> 0.035646819 | ... AN13: ='Import HHI Hierarchy Scores'!AN13*0.25+'Export HHI Hierarchy Scores'!AN13*0.25+'Import Dependence'!AN13*0.25+'Export Dependence'!AN13*0.25 -> 0.029975
A14: 2003 | B14: ='Import HHI Hierarchy Scores'!B14*0.25+'Export HHI Hierarchy Scores'!B14*0.25+'Import Dependence'!B14*0.25+'Export Dependence'!B14*0.25 -> 0.047575 | C14: ='Import HHI Hierarchy Scores'!C14*0.25+'Export HHI Hierarchy Scores'!C14*0.25+'Import Dependence'!C14*0.25+'Export Dependence'!C14*0.25 -> 0.14282344 | D14: ='Import HHI Hierarchy Scores'!D14*0.25+'Export HHI Hierarchy Scores'!D14*0.25+'Import Dependence'!D14*0.25+'Export Dependence'!D14*0.25 -> 0.01915 | E14: ='Import HHI Hierarchy Scores'!E14*0.25+'Export HHI Hierarchy Scores'!E14*0.25+'Import Dependence'!E14*0.25+'Export Dependence'!E14*0.25 -> 0.385225 | F14: ='Import HHI Hierarchy Scores'!F14*0.25+'Export HHI Hierarchy Scores'!F14*0.25+'Import Dependence'!F14*0.25+'Export Dependence'!F14*0.25 -> 0.026056031 | G14: ='Import HHI Hierarchy Scores'!G14*0.25+'Export HHI Hierarchy Scores'!G14*0.25+'Import Dependence'!G14*0.25+'Export Dependence'!G14*0.25 -> 0.013538742 | H14: ='Import HHI Hierarchy Scores'!H14*0.25+'Export HHI Hierarchy Scores'!H14*0.25+'Import Dependence'!H14*0.25+'Export Dependence'!H14*0.25 -> 0.0061203877 | I14: ='Import HHI Hierarchy Scores'!I14*0.25+'Export HHI Hierarchy Scores'!I14*0.25+'Import Dependence'!I14*0.25+'Export Dependence'!I14*0.25 -> 0.03413473 | ... AN14: ='Import HHI Hierarchy Scores'!AN14*0.25+'Export HHI Hierarchy Scores'!AN14*0.25+'Import Dependence'!AN14*0.25+'Export Dependence'!AN14*0.25 -> 0.036025
A15: 2004 | B15: ='Import HHI Hierarchy Scores'!B15*0.25+'Export HHI Hierarchy Scores'!B15*0.25+'Import Dependence'!B15*0.25+'Export Dependence'!B15*0.25 -> 0.043475 | C15: ='Import HHI Hierarchy Scores'!C15*0.25+'Export HHI Hierarchy Scores'!C15*0.25+'Import Dependence'!C15*0.25+'Export Dependence'!C15*0.25 -> 0.14474386 | D15: ='Import HHI Hierarchy Scores'!D15*0.25+'Export HHI Hierarchy Scores'!D15*0.25+'Import Dependence'!D15*0.25+'Export Dependence'!D15*0.25 -> 0.013 | E15: ='Import HHI Hierarchy Scores'!E15*0.25+'Export HHI Hierarchy Scores'!E15*0.25+'Import Dependence'!E15*0.25+'Export Dependence'!E15*0.25 -> 0.381625 | F15: ='Import HHI Hierarchy Scores'!F15*0.25+'Export HHI Hierarchy Scores'!F15*0.25+'Import Dependence'!F15*0.25+'Export Dependence'!F15*0.25 -> 0.025559035 | G15: ='Import HHI Hierarchy Scores'!G15*0.25+'Export HHI Hierarchy Scores'!G15*0.25+'Import Dependence'!G15*0.25+'Export Dependence'!G15*0.25 -> 0.0098440339 | H15: ='Import HHI Hierarchy Scores'!H15*0.25+'Export HHI Hierarchy Scores'!H15*0.25+'Import Dependence'!H15*0.25+'Export Dependence'!H15*0.25 -> 0.0056950901 | I15: ='Import HHI Hierarchy Scores'!I15*0.25+'Export HHI Hierarchy Scores'!I15*0.25+'Import Dependence'!I15*0.25+'Export Dependence'!I15*0.25 -> 0.028256981 | ... AN15: ='Import HHI Hierarchy Scores'!AN15*0.25+'Export HHI Hierarchy Scores'!AN15*0.25+'Import Dependence'!AN15*0.25+'Export Dependence'!AN15*0.25 -> 0.02495
A16: 2005 | B16: ='Import HHI Hierarchy Scores'!B16*0.25+'Export HHI Hierarchy Scores'!B16*0.25+'Import Dependence'!B16*0.25+'Export Dependence'!B16*0.25 -> 0.030225 | C16: ='Import HHI Hierarchy Scores'!C16*0.25+'Export HHI Hierarchy Scores'!C16*0.25+'Import Dependence'!C16*0.25+'Export Dependence'!C16*0.25 -> 0.14514751 | D16: ='Import HHI Hierarchy Scores'!D16*0.25+'Export HHI Hierarchy Scores'!D16*0.25+'Import Dependence'!D16*0.25+'Export Dependence'!D16*0.25 -> 0.0103 | E16: ='Import HHI Hierarchy Scores'!E16*0.25+'Export HHI Hierarchy Scores'!E16*0.25+'Import Dependence'!E16*0.25+'Export Dependence'!E16*0.25 -> 0.382525 | F16: ='Import HHI Hierarchy Scores'!F16*0.25+'Export HHI Hierarchy Scores'!F16*0.25+'Import Dependence'!F16*0.25+'Export Dependence'!F16*0.25 -> 0.021142696 | G16: ='Import HHI Hierarchy Scores'!G16*0.25+'Export HHI Hierarchy Scores'!G16*0.25+'Import Dependence'!G16*0.25+'Export Dependence'!G16*0.25 -> 0.011053457 | H16: ='Import HHI Hierarchy Scores'!H16*0.25+'Export HHI Hierarchy Scores'!H16*0.25+'Import Dependence'!H16*0.25+'Export Dependence'!H16*0.25 -> 0.0066617032 | I16: ='Import HHI Hierarchy Scores'!I16*0.25+'Export HHI Hierarchy Scores'!I16*0.25+'Import Dependence'!I16*0.25+'Export Dependence'!I16*0.25 -> 0.02592237 | ... AN16: ='Import HHI Hierarchy Scores'!AN16*0.25+'Export HHI Hierarchy Scores'!AN16*0.25+'Import Dependence'!AN16*0.25+'Export Dependence'!AN16*0.25 -> 0.010075
A17: 2006 | B17: ='Import HHI Hierarchy Scores'!B17*0.25+'Export HHI Hierarchy Scores'!B17*0.25+'Import Dependence'!B17*0.25+'Export Dependence'!B17*0.25 -> 0.026275 | C17: ='Import HHI Hierarchy Scores'!C17*0.25+'Export HHI Hierarchy Scores'!C17*0.25+'Import Dependence'!C17*0.25+'Export Dependence'!C17*0.25 -> 0.1451239 | D17: ='Import HHI Hierarchy Scores'!D17*0.25+'Export HHI Hierarchy Scores'!D17*0.25+'Import Dependence'!D17*0.25+'Export Dependence'!D17*0.25 -> 0.020175 | E17: ='Import HHI Hierarchy Scores'!E17*0.25+'Export HHI Hierarchy Scores'!E17*0.25+'Import Dependence'!E17*0.25+'Export Dependence'!E17*0.25 -> 0.3846 | F17: ='Import HHI Hierarchy Scores'!F17*0.25+'Export HHI Hierarchy Scores'!F17*0.25+'Import Dependence'!F17*0.25+'Export Dependence'!F17*0.25 -> 0.020921146 | G17: ='Import HHI Hierarchy Scores'!G17*0.25+'Export HHI Hierarchy Scores'!G17*0.25+'Import Dependence'!G17*0.25+'Export Dependence'!G17*0.25 -> 0.0078858389 | H17: ='Import HHI Hierarchy Scores'!H17*0.25+'Export HHI Hierarchy Scores'!H17*0.25+'Import Dependence'!H17*0.25+'Export Dependence'!H17*0.25 -> 0.0057497722 | I17: ='Import HHI Hierarchy Scores'!I17*0.25+'Export HHI Hierarchy Scores'!I17*0.25+'Import Dependence'!I17*0.25+'Export Dependence'!I17*0.25 -> 0.025373589 | ... AN17: ='Import HHI Hierarchy Scores'!AN17*0.25+'Export HHI Hierarchy Scores'!AN17*0.25+'Import Dependence'!AN17*0.25+'Export Dependence'!AN17*0.25 -> 0.0101
A18: 2007 | B18: ='Import HHI Hierarchy Scores'!B18*0.25+'Export HHI Hierarchy Scores'!B18*0.25+'Import Dependence'!B18*0.25+'Export Dependence'!B18*0.25 -> 0.019975 | C18: ='Import HHI Hierarchy Scores'!C18*0.25+'Export HHI Hierarchy Scores'!C18*0.25+'Import Dependence'!C18*0.25+'Export Dependence'!C18*0.25 -> 0.14283274 | D18: ='Import HHI Hierarchy Scores'!D18*0.25+'Export HHI Hierarchy Scores'!D18*0.25+'Import Dependence'!D18*0.25+'Export Dependence'!D18*0.25 -> 0.02765 | E18: ='Import HHI Hierarchy Scores'!E18*0.25+'Export HHI Hierarchy Scores'!E18*0.25+'Import Dependence'!E18*0.25+'Export Dependence'!E18*0.25 -> 0.381825 | F18: ='Import HHI Hierarchy Scores'!F18*0.25+'Export HHI Hierarchy Scores'!F18*0.25+'Import Dependence'!F18*0.25+'Export Dependence'!F18*0.25 -> 0.019725861 | G18: ='Import HHI Hierarchy Scores'!G18*0.25+'Export HHI Hierarchy Scores'!G18*0.25+'Import Dependence'!G18*0.25+'Export Dependence'!G18*0.25 -> 0.0042706141 | H18: ='Import HHI Hierarchy Scores'!H18*0.25+'Export HHI Hierarchy Scores'!H18*0.25+'Import Dependence'!H18*0.25+'Export Dependence'!H18*0.25 -> 0.0048329646 | I18: ='Import HHI Hierarchy Scores'!I18*0.25+'Export HHI Hierarchy Scores'!I18*0.25+'Import Dependence'!I18*0.25+'Export Dependence'!I18*0.25 -> 0.021975793 | ... AN18: ='Import HHI Hierarchy Scores'!AN18*0.25+'Export HHI Hierarchy Scores'!AN18*0.25+'Import Dependence'!AN18*0.25+'Export Dependence'!AN18*0.25 -> 0.0088
A19: 2008 | B19: ='Import HHI Hierarchy Scores'!B19*0.25+'Export HHI Hierarchy Scores'!B19*0.25+'Import Dependence'!B19*0.25+'Export Dependence'!B19*0.25 -> 0.022875 | C19: ='Import HHI Hierarchy Scores'!C19*0.25+'Export HHI Hierarchy Scores'!C19*0.25+'Import Dependence'!C19*0.25+'Export Dependence'!C19*0.25 -> 0.14020789 | D19: ='Import HHI Hierarchy Scores'!D19*0.25+'Export HHI Hierarchy Scores'!D19*0.25+'Import Dependence'!D19*0.25+'Export Dependence'!D19*0.25 -> 0.0427 | E19: ='Import HHI Hierarchy Scores'!E19*0.25+'Export HHI Hierarchy Scores'!E19*0.25+'Import Dependence'!E19*0.25+'Export Dependence'!E19*0.25 -> 0.253975 | F19: ='Import HHI Hierarchy Scores'!F19*0.25+'Export HHI Hierarchy Scores'!F19*0.25+'Import Dependence'!F19*0.25+'Export Dependence'!F19*0.25 -> 0.017769448 | G19: ='Import HHI Hierarchy Scores'!G19*0.25+'Export HHI Hierarchy Scores'!G19*0.25+'Import Dependence'!G19*0.25+'Export Dependence'!G19*0.25 -> 0.0044138318 | H19: ='Import HHI Hierarchy Scores'!H19*0.25+'Export HHI Hierarchy Scores'!H19*0.25+'Import Dependence'!H19*0.25+'Export Dependence'!H19*0.25 -> 0.0044278498 | I19: ='Import HHI Hierarchy Scores'!I19*0.25+'Export HHI Hierarchy Scores'!I19*0.25+'Import Dependence'!I19*0.25+'Export Dependence'!I19*0.25 -> 0.022348705 | ... AN19: ='Import HHI Hierarchy Scores'!AN19*0.25+'Export HHI Hierarchy Scores'!AN19*0.25+'Import Dependence'!AN19*0.25+'Export Dependence'!AN19*0.25 -> 0.017075
A20: 2009 | B20: ='Import HHI Hierarchy Scores'!B20*0.25+'Export HHI Hierarchy Scores'!B20*0.25+'Import Dependence'!B20*0.25+'Export Dependence'!B20*0.25 -> 0.03215 | C20: ='Import HHI Hierarchy Scores'!C20*0.25+'Export HHI Hierarchy Scores'!C20*0.25+'Import Dependence'!C20*0.25+'Export Dependence'!C20*0.25 -> 0.13903565 | D20: ='Import HHI Hierarchy Scores'!D20*0.25+'Export HHI Hierarchy Scores'!D20*0.25+'Import Dependence'!D20*0.25+'Export Dependence'!D20*0.25 -> 0.034175 | E20: ='Import HHI Hierarchy Scores'!E20*0.25+'Export HHI Hierarchy Scores'!E20*0.25+'Import Dependence'!E20*0.25+'Export Dependence'!E20*0.25 -> 0.253825 | F20: ='Import HHI Hierarchy Scores'!F20*0.25+'Export HHI Hierarchy Scores'!F20*0.25+'Import Dependence'!F20*0.25+'Export Dependence'!F20*0.25 -> 0.01867578 | G20: ='Import HHI Hierarchy Scores'!G20*0.25+'Export HHI Hierarchy Scores'!G20*0.25+'Import Dependence'!G20*0.25+'Export Dependence'!G20*0.25 -> 0.0057310178 | H20: ='Import HHI Hierarchy Scores'!H20*0.25+'Export HHI Hierarchy Scores'!H20*0.25+'Import Dependence'!H20*0.25+'Export Dependence'!H20*0.25 -> 0.0040011789 | I20: ='Import HHI Hierarchy Scores'!I20*0.25+'Export HHI Hierarchy Scores'!I20*0.25+'Import Dependence'!I20*0.25+'Export Dependence'!I20*0.25 -> 0.020685579 | ... AN20: ='Import HHI Hierarchy Scores'!AN20*0.25+'Export HHI Hierarchy Scores'!AN20*0.25+'Import Dependence'!AN20*0.25+'Export Dependence'!AN20*0.25 -> 0.130925
A21: 2010 | B21: ='Import HHI Hierarchy Scores'!B21*0.25+'Export HHI Hierarchy Scores'!B21*0.25+'Import Dependence'!B21*0.25+'Export Dependence'!B21*0.25 -> 0.029875 | C21: ='Import HHI Hierarchy Scores'!C21*0.25+'Export HHI Hierarchy Scores'!C21*0.25+'Import Dependence'!C21*0.25+'Export Dependence'!C21*0.25 -> 0.14001509 | D21: ='Import HHI Hierarchy Scores'!D21*0.25+'Export HHI Hierarchy Scores'!D21*0.25+'Import Dependence'!D21*0.25+'Export Dependence'!D21*0.25 -> 0.0227 | E21: ='Import HHI Hierarchy Scores'!E21*0.25+'Export HHI Hierarchy Scores'!E21*0.25+'Import Dependence'!E21*0.25+'Export Dependence'!E21*0.25 -> 0.379 | F21: ='Import HHI Hierarchy Scores'!F21*0.25+'Export HHI Hierarchy Scores'!F21*0.25+'Import Dependence'!F21*0.25+'Export Dependence'!F21*0.25 -> 0.017843281 | G21: ='Import HHI Hierarchy Scores'!G21*0.25+'Export HHI Hierarchy Scores'!G21*0.25+'Import Dependence'!G21*0.25+'Export Dependence'!G21*0.25 -> 0.0047988014 | H21: ='Import HHI Hierarchy Scores'!H21*0.25+'Export HHI Hierarchy Scores'!H21*0.25+'Import Dependence'!H21*0.25+'Export Dependence'!H21*0.25 -> 0.0043696866 | I21: ='Import HHI Hierarchy Scores'!I21*0.25+'Export HHI Hierarchy Scores'!I21*0.25+'Import Dependence'!I21*0.25+'Export Dependence'!I21*0.25 -> 0.020426068 | ... AN21: ='Import HHI Hierarchy Scores'!AN21*0.25+'Export HHI Hierarchy Scores'!AN21*0.25+'Import Dependence'!AN21*0.25+'Export Dependence'!AN21*0.25 -> 0.004725
A22: 2011 | B22: ='Import HHI Hierarchy Scores'!B22*0.25+'Export HHI Hierarchy Scores'!B22*0.25+'Import Dependence'!B22*0.25+'Export Dependence'!B22*0.25 -> 0.027225 | C22: ='Import HHI Hierarchy Scores'!C22*0.25+'Export HHI Hierarchy Scores'!C22*0.25+'Import Dependence'!C22*0.25+'Export Dependence'!C22*0.25 -> 0.14149537 | D22: ='Import HHI Hierarchy Scores'!D22*0.25+'Export HHI Hierarchy Scores'!D22*0.25+'Import Dependence'!D22*0.25+'Export Dependence'!D22*0.25 -> 0.030275 | E22: ='Import HHI Hierarchy Scores'!E22*0.25+'Export HHI Hierarchy Scores'!E22*0.25+'Import Dependence'!E22*0.25+'Export Dependence'!E22*0.25 -> 0.253825 | F22: ='Import HHI Hierarchy Scores'!F22*0.25+'Export HHI Hierarchy Scores'!F22*0.25+'Import Dependence'!F22*0.25+'Export Dependence'!F22*0.25 -> 0.017621335 | G22: ='Import HHI Hierarchy Scores'!G22*0.25+'Export HHI Hierarchy Scores'!G22*0.25+'Import Dependence'!G22*0.25+'Export Dependence'!G22*0.25 -> 0.0055064844 | H22: ='Import HHI Hierarchy Scores'!H22*0.25+'Export HHI Hierarchy Scores'!H22*0.25+'Import Dependence'!H22*0.25+'Export Dependence'!H22*0.25 -> 0.0048497859 | I22: ='Import HHI Hierarchy Scores'!I22*0.25+'Export HHI Hierarchy Scores'!I22*0.25+'Import Dependence'!I22*0.25+'Export Dependence'!I22*0.25 -> 0.023078979 | ... AN22: ='Import HHI Hierarchy Scores'!AN22*0.25+'Export HHI Hierarchy Scores'!AN22*0.25+'Import Dependence'!AN22*0.25+'Export Dependence'!AN22*0.25 -> 0.0035
... A28: 2017 | B28: ='Import HHI Hierarchy Scores'!B28*0.25+'Export HHI Hierarchy Scores'!B28*0.25+'Import Dependence'!B28*0.25+'Export Dependence'!B28*0.25 -> 0.014025 | C28: ='Import HHI Hierarchy Scores'!C28*0.25+'Export HHI Hierarchy Scores'!C28*0.25+'Import Dependence'!C28*0.25+'Export Dependence'!C28*0.25 -> 0.14695477 | D28: ='Import HHI Hierarchy Scores'!D28*0.25+'Export HHI Hierarchy Scores'!D28*0.25+'Import Dependence'!D28*0.25+'Export Dependence'!D28*0.25 -> 0.010125 | E28: ='Import HHI Hierarchy Scores'!E28*0.25+'Export HHI Hierarchy Scores'!E28*0.25+'Import Dependence'!E28*0.25+'Export Dependence'!E28*0.25 -> 0.37975 | F28: ='Import HHI Hierarchy Scores'!F28*0.25+'Export HHI Hierarchy Scores'!F28*0.25+'Import Dependence'!F28*0.25+'Export Dependence'!F28*0.25 -> 0.021348081 | G28: ='Import HHI Hierarchy Scores'!G28*0.25+'Export HHI Hierarchy Scores'!G28*0.25+'Import Dependence'!G28*0.25+'Export Dependence'!G28*0.25 -> 0.0057348463 | H28: ='Import HHI Hierarchy Scores'!H28*0.25+'Export HHI Hierarchy Scores'!H28*0.25+'Import Dependence'!H28*0.25+'Export Dependence'!H28*0.25 -> 0.0051460762 | I28: ='Import HHI Hierarchy Scores'!I28*0.25+'Export HHI Hierarchy Scores'!I28*0.25+'Import Dependence'!I28*0.25+'Export Dependence'!I28*0.25 -> 0.024367703 | ... AN28: ='Import HHI Hierarchy Scores'!AN28*0.25+'Export HHI Hierarchy Scores'!AN28*0.25+'Import Dependence'!AN28*0.25+'Export Dependence'!AN28*0.25 -> 0.25115
A31: Russia | B31: Armenia | C31: Austria | D31: Azerbaijan | E31: Belarus | F31: Belgium | G31: Bulgaria | H31: Croatia | I31: Cyprus | J31: Czech | K31: Denmark | L31: Estonia | M31: Finland | N31: France | O31: Georgia | P31: Germany | Q31: Greece | R31: Hungary | S31: Ireland | T31: Italy | U31: Kazakhstan | V31: Kyrgyzstan | W31: latvia | X31: Lithuania | Y31: Luxembourg | Z31: Malta | AA31: Moldova | AB31: Netherlands | AC31: Poland | AD31: Portugal | AE31: Romania | AF31: Slovakia | AG31: Slovenia | AH31: Spain | AI31: Sweden | AJ31: Tajikistan | AK31: Turkmenistan | AL31: UK | AM31: Ukraine | AN31: Uzbekistan
A32: 1991
A33: 1992
A34: 1993
A35: 1994
A36: 1995
A37: 1996
A38: 1997
A39: 1998
A40: 1999
A41: 2000 | B41: ='Import HHI Hierarchy Scores'!B11*0.25+'Export HHI Hierarchy Scores'!B11*0.25+'Import Dependence'!B41*0.25+'Export Dependence'!B41*0.25 -> 0.068925 | C41: ='Import HHI Hierarchy Scores'!C11*0.25+'Export HHI Hierarchy Scores'!C11*0.25+'Import Dependence'!C41*0.25+'Export Dependence'!C41*0.25 -> 0.13103667 | D41: ='Import HHI Hierarchy Scores'!D11*0.25+'Export HHI Hierarchy Scores'!D11*0.25+'Import Dependence'!D41*0.25+'Export Dependence'!D41*0.25 -> 0.04745 | E41: ='Import HHI Hierarchy Scores'!E11*0.25+'Export HHI Hierarchy Scores'!E11*0.25+'Import Dependence'!E41*0.25+'Export Dependence'!E41*0.25 -> 0.7837 | F41: ='Import HHI Hierarchy Scores'!F11*0.25+'Export HHI Hierarchy Scores'!F11*0.25+'Import Dependence'!F41*0.25+'Export Dependence'!F41*0.25 -> 0.0032563236 | G41: ='Import HHI Hierarchy Scores'!G11*0.25+'Export HHI Hierarchy Scores'!G11*0.25+'Import Dependence'!G41*0.25+'Export Dependence'!G41*0.25 -> 0.064021384 | H41: ='Import HHI Hierarchy Scores'!H11*0.25+'Export HHI Hierarchy Scores'!H11*0.25+'Import Dependence'!H41*0.25+'Export Dependence'!H41*0.25 -> 0.015090183 | I41: ='Import HHI Hierarchy Scores'!I11*0.25+'Export HHI Hierarchy Scores'!I11*0.25+'Import Dependence'!I41*0.25+'Export Dependence'!I41*0.25 -> 0.02048322 | ... AN41: ='Import HHI Hierarchy Scores'!AN11*0.25+'Export HHI Hierarchy Scores'!AN11*0.25+'Import Dependence'!AN41*0.25+'Export Dependence'!AN41*0.25 -> 0.121475
A42: 2001 | B42: ='Import HHI Hierarchy Scores'!B12*0.25+'Export HHI Hierarchy Scores'!B12*0.25+'Import Dependence'!B42*0.25+'Export Dependence'!B42*0.25 -> 0.0706 | C42: ='Import HHI Hierarchy Scores'!C12*0.25+'Export HHI Hierarchy Scores'!C12*0.25+'Import Dependence'!C42*0.25+'Export Dependence'!C42*0.25 -> 0.1313727 | D42: ='Import HHI Hierarchy Scores'!D12*0.25+'Export HHI Hierarchy Scores'!D12*0.25+'Import Dependence'!D42*0.25+'Export Dependence'!D42*0.25 -> 0.156 | E42: ='Import HHI Hierarchy Scores'!E12*0.25+'Export HHI Hierarchy Scores'!E12*0.25+'Import Dependence'!E42*0.25+'Export Dependence'!E42*0.25 -> 0.7852 | F42: ='Import HHI Hierarchy Scores'!F12*0.25+'Export HHI Hierarchy Scores'!F12*0.25+'Import Dependence'!F42*0.25+'Export Dependence'!F42*0.25 -> 0.0038007058 | G42: ='Import HHI Hierarchy Scores'!G12*0.25+'Export HHI Hierarchy Scores'!G12*0.25+'Import Dependence'!G42*0.25+'Export Dependence'!G42*0.25 -> 0.054386331 | H42: ='Import HHI Hierarchy Scores'!H12*0.25+'Export HHI Hierarchy Scores'!H12*0.25+'Import Dependence'!H42*0.25+'Export Dependence'!H42*0.25 -> 0.014001265 | I42: ='Import HHI Hierarchy Scores'!I12*0.25+'Export HHI Hierarchy Scores'!I12*0.25+'Import Dependence'!I42*0.25+'Export Dependence'!I42*0.25 -> 0.018654971 | ... AN42: ='Import HHI Hierarchy Scores'!AN12*0.25+'Export HHI Hierarchy Scores'!AN12*0.25+'Import Dependence'!AN42*0.25+'Export Dependence'!AN42*0.25 -> 0.120275
A43: 2002 | B43: ='Import HHI Hierarchy Scores'!B13*0.25+'Export HHI Hierarchy Scores'!B13*0.25+'Import Dependence'!B43*0.25+'Export Dependence'!B43*0.25 -> 0.073875 | C43: ='Import HHI Hierarchy Scores'!C13*0.25+'Export HHI Hierarchy Scores'!C13*0.25+'Import Dependence'!C43*0.25+'Export Dependence'!C43*0.25 -> 0.13098833 | D43: ='Import HHI Hierarchy Scores'!D13*0.25+'Export HHI Hierarchy Scores'!D13*0.25+'Import Dependence'!D43*0.25+'Export Dependence'!D43*0.25 -> 0.042875 | E43: ='Import HHI Hierarchy Scores'!E13*0.25+'Export HHI Hierarchy Scores'!E13*0.25+'Import Dependence'!E43*0.25+'Export Dependence'!E43*0.25 -> 0.650775 | F43: ='Import HHI Hierarchy Scores'!F13*0.25+'Export HHI Hierarchy Scores'!F13*0.25+'Import Dependence'!F43*0.25+'Export Dependence'!F43*0.25 -> 0.0035829528 | G43: ='Import HHI Hierarchy Scores'!G13*0.25+'Export HHI Hierarchy Scores'!G13*0.25+'Import Dependence'!G43*0.25+'Export Dependence'!G43*0.25 -> 0.038043376 | H43: ='Import HHI Hierarchy Scores'!H13*0.25+'Export HHI Hierarchy Scores'!H13*0.25+'Import Dependence'!H43*0.25+'Export Dependence'!H43*0.25 -> 0.013531583 | I43: ='Import HHI Hierarchy Scores'!I13*0.25+'Export HHI Hierarchy Scores'!I13*0.25+'Import Dependence'!I43*0.25+'Export Dependence'!I43*0.25 -> 0.017902427 | ... AN43: ='Import HHI Hierarchy Scores'!AN13*0.25+'Export HHI Hierarchy Scores'!AN13*0.25+'Import Dependence'!AN43*0.25+'Export Dependence'!AN43*0.25 -> 0.117475
A44: 2003 | B44: ='Import HHI Hierarchy Scores'!B14*0.25+'Export HHI Hierarchy Scores'!B14*0.25+'Import Dependence'!B44*0.25+'Export Dependence'!B44*0.25 -> 0.069425 | C44: ='Import HHI Hierarchy Scores'!C14*0.25+'Export HHI Hierarchy Scores'!C14*0.25+'Import Dependence'!C44*0.25+'Export Dependence'!C44*0.25 -> 0.1323094 | D44: ='Import HHI Hierarchy Scores'!D14*0.25+'Export HHI Hierarchy Scores'!D14*0.25+'Import Dependence'!D44*0.25+'Export Dependence'!D44*0.25 -> 0.04555 | E44: ='Import HHI Hierarchy Scores'!E14*0.25+'Export HHI Hierarchy Scores'!E14*0.25+'Import Dependence'!E44*0.25+'Export Dependence'!E44*0.25 -> 0.631425 | F44: ='Import HHI Hierarchy Scores'!F14*0.25+'Export HHI Hierarchy Scores'!F14*0.25+'Import Dependence'!F44*0.25+'Export Dependence'!F44*0.25 -> 0.0041628554 | G44: ='Import HHI Hierarchy Scores'!G14*0.25+'Export HHI Hierarchy Scores'!G14*0.25+'Import Dependence'!G44*0.25+'Export Dependence'!G44*0.25 -> 0.033001599 | H44: ='Import HHI Hierarchy Scores'!H14*0.25+'Export HHI Hierarchy Scores'!H14*0.25+'Import Dependence'!H44*0.25+'Export Dependence'!H44*0.25 -> 0.011022343 | I44: ='Import HHI Hierarchy Scores'!I14*0.25+'Export HHI Hierarchy Scores'!I14*0.25+'Import Dependence'!I44*0.25+'Export Dependence'!I44*0.25 -> 0.018403571 | ... AN44: ='Import HHI Hierarchy Scores'!AN14*0.25+'Export HHI Hierarchy Scores'!AN14*0.25+'Import Dependence'!AN44*0.25+'Export Dependence'!AN44*0.25 -> 0.111875
A45: 2004 | B45: ='Import HHI Hierarchy Scores'!B15*0.25+'Export HHI Hierarchy Scores'!B15*0.25+'Import Dependence'!B45*0.25+'Export Dependence'!B45*0.25 -> 0.05905 | C45: ='Import HHI Hierarchy Scores'!C15*0.25+'Export HHI Hierarchy Scores'!C15*0.25+'Import Dependence'!C45*0.25+'Export Dependence'!C45*0.25 -> 0.13259192 | D45: ='Import HHI Hierarchy Scores'!D15*0.25+'Export HHI Hierarchy Scores'!D15*0.25+'Import Dependence'!D45*0.25+'Export Dependence'!D45*0.25 -> 0.0476 | E45: ='Import HHI Hierarchy Scores'!E15*0.25+'Export HHI Hierarchy Scores'!E15*0.25+'Import Dependence'!E45*0.25+'Export Dependence'!E45*0.25 -> 0.653525 | F45: ='Import HHI Hierarchy Scores'!F15*0.25+'Export HHI Hierarchy Scores'!F15*0.25+'Import Dependence'!F45*0.25+'Export Dependence'!F45*0.25 -> 0.0050842464 | G45: ='Import HHI Hierarchy Scores'!G15*0.25+'Export HHI Hierarchy Scores'!G15*0.25+'Import Dependence'!G45*0.25+'Export Dependence'!G45*0.25 -> 0.034117459 | H45: ='Import HHI Hierarchy Scores'!H15*0.25+'Export HHI Hierarchy Scores'!H15*0.25+'Import Dependence'!H45*0.25+'Export Dependence'!H45*0.25 -> 0.0068879551 | I45: ='Import HHI Hierarchy Scores'!I15*0.25+'Export HHI Hierarchy Scores'!I15*0.25+'Import Dependence'!I45*0.25+'Export Dependence'!I45*0.25 -> 0.014896985 | ... AN45: ='Import HHI Hierarchy Scores'!AN15*0.25+'Export HHI Hierarchy Scores'!AN15*0.25+'Import Dependence'!AN45*0.25+'Export Dependence'!AN45*0.25 -> 0.12045
A46: 2005 | B46: ='Import HHI Hierarchy Scores'!B16*0.25+'Export HHI Hierarchy Scores'!B16*0.25+'Import Dependence'!B46*0.25+'Export Dependence'!B46*0.25 -> 0.064175 | C46: ='Import HHI Hierarchy Scores'!C16*0.25+'Export HHI Hierarchy Scores'!C16*0.25+'Import Dependence'!C46*0.25+'Export Dependence'!C46*0.25 -> 0.13535996 | D46: ='Import HHI Hierarchy Scores'!D16*0.25+'Export HHI Hierarchy Scores'!D16*0.25+'Import Dependence'!D46*0.25+'Export Dependence'!D46*0.25 -> 0.04705 | E46: ='Import HHI Hierarchy Scores'!E16*0.25+'Export HHI Hierarchy Scores'!E16*0.25+'Import Dependence'!E46*0.25+'Export Dependence'!E46*0.25 -> 0.606525 | F46: ='Import HHI Hierarchy Scores'!F16*0.25+'Export HHI Hierarchy Scores'!F16*0.25+'Import Dependence'!F46*0.25+'Export Dependence'!F46*0.25 -> 0.0059532498 | G46: ='Import HHI Hierarchy Scores'!G16*0.25+'Export HHI Hierarchy Scores'!G16*0.25+'Import Dependence'!G46*0.25+'Export Dependence'!G46*0.25 -> 0.0095348511 | H46: ='Import HHI Hierarchy Scores'!H16*0.25+'Export HHI Hierarchy Scores'!H16*0.25+'Import Dependence'!H46*0.25+'Export Dependence'!H46*0.25 -> 0.0054821515 | I46: ='Import HHI Hierarchy Scores'!I16*0.25+'Export HHI Hierarchy Scores'!I16*0.25+'Import Dependence'!I46*0.25+'Export Dependence'!I46*0.25 -> 0.017117828 | ... AN46: ='Import HHI Hierarchy Scores'!AN16*0.25+'Export HHI Hierarchy Scores'!AN16*0.25+'Import Dependence'!AN46*0.25+'Export Dependence'!AN46*0.25 -> 0.12465
A47: 2006 | B47: ='Import HHI Hierarchy Scores'!B17*0.25+'Export HHI Hierarchy Scores'!B17*0.25+'Import Dependence'!B47*0.25+'Export Dependence'!B47*0.25 -> 0.061225 | C47: ='Import HHI Hierarchy Scores'!C17*0.25+'Export HHI Hierarchy Scores'!C17*0.25+'Import Dependence'!C47*0.25+'Export Dependence'!C47*0.25 -> 0.13576841 | D47: ='Import HHI Hierarchy Scores'!D17*0.25+'Export HHI Hierarchy Scores'!D17*0.25+'Import Dependence'!D47*0.25+'Export Dependence'!D47*0.25 -> 0.055675 | E47: ='Import HHI Hierarchy Scores'!E17*0.25+'Export HHI Hierarchy Scores'!E17*0.25+'Import Dependence'!E47*0.25+'Export Dependence'!E47*0.25 -> 0.600375 | F47: ='Import HHI Hierarchy Scores'!F17*0.25+'Export HHI Hierarchy Scores'!F17*0.25+'Import Dependence'!F47*0.25+'Export Dependence'!F47*0.25 -> 0.0066482004 | G47: ='Import HHI Hierarchy Scores'!G17*0.25+'Export HHI Hierarchy Scores'!G17*0.25+'Import Dependence'!G47*0.25+'Export Dependence'!G47*0.25 -> 0.010396858 | H47: ='Import HHI Hierarchy Scores'!H17*0.25+'Export HHI Hierarchy Scores'!H17*0.25+'Import Dependence'!H47*0.25+'Export Dependence'!H47*0.25 -> 0.0048936629 | I47: ='Import HHI Hierarchy Scores'!I17*0.25+'Export HHI Hierarchy Scores'!I17*0.25+'Import Dependence'!I47*0.25+'Export Dependence'!I47*0.25 -> 0.018138514 | ... AN47: ='Import HHI Hierarchy Scores'!AN17*0.25+'Export HHI Hierarchy Scores'!AN17*0.25+'Import Dependence'!AN47*0.25+'Export Dependence'!AN47*0.25 -> 0.1339
...

Sheet Economic Hierarchy Scores wo HH
A1: US | B1: Armenia | C1: Austria | D1: Azerbaijan | E1: Belarus | F1: Belgium | G1: Bulgaria | H1: Croatia | I1: Cyprus | J1: Czech | K1: Denmark | L1: Estonia | M1: Finland | N1: France | O1: Georgia | P1: Germany | Q1: Greece | R1: Hungary | S1: Ireland | T1: Italy | U1: Kazakhstan | V1: Kyrgyzstan | W1: latvia | X1: Lithuania | Y1: Luxembourg | Z1: Malta | AA1: Moldova | AB1: Netherlands | AC1: Poland | AD1: Portugal | AE1: Romania | AF1: Slovakia | AG1: Slovenia | AH1: Spain | AI1: Sweden | AJ1: Tajikistan | AK1: Turkmenistan | AL1: UK | AM1: Ukraine | AN1: Uzbekistan
A2: 1991
A3: 1992
A4: 1993
A5: 1994
A6: 1995
A7: 1996
A8: 1997
A9: 1998
A10: 1999
A11: 2000 | B11: ='Import Dependence'!B11*0.5+'Export Dependence'!B11*0.5 -> 0.1285 | C11: ='Import Dependence'!C11*0.5+'Export Dependence'!C11*0.5 -> 0.045370291 | D11: ='Import Dependence'!D11*0.5+'Export Dependence'!D11*0.5 -> 0.0889 | E11: ='Import Dependence'!E11*0.5+'Export Dependence'!E11*0.5 -> 0.01535 | F11: ='Import Dependence'!F11*0.5+'Export Dependence'!F11*0.5 -> 0.057165748 | G11: ='Import Dependence'!G11*0.5+'Export Dependence'!G11*0.5 -> 0.030896716 | H11: ='Import Dependence'!H11*0.5+'Export Dependence'!H11*0.5 -> 0.014098801 | I11: ='Import Dependence'!I11*0.5+'Export Dependence'!I11*0.5 -> 0.082033571 | ... AN11: ='Import Dependence'!AN11*0.5+'Export Dependence'!AN11*0.5 -> 0.04965
A12: 2001 | B12: ='Import Dependence'!B12*0.5+'Export Dependence'!B12*0.5 -> 0.13495 | C12: ='Import Dependence'!C12*0.5+'Export Dependence'!C12*0.5 -> 0.044935621 | D12: ='Import Dependence'!D12*0.5+'Export Dependence'!D12*0.5 -> 0.0709 | E12: ='Import Dependence'!E12*0.5+'Export Dependence'!E12*0.5 -> 0.0146 | F12: ='Import Dependence'!F12*0.5+'Export Dependence'!F12*0.5 -> 0.062877704 | G12: ='Import Dependence'!G12*0.5+'Export Dependence'!G12*0.5 -> 0.027792238 | H12: ='Import Dependence'!H12*0.5+'Export Dependence'!H12*0.5 -> 0.014235818 | I12: ='Import Dependence'!I12*0.5+'Export Dependence'!I12*0.5 -> 0.090553959 | ... AN12: ='Import Dependence'!AN12*0.5+'Export Dependence'!AN12*0.5 -> 0.046
A13: 2002 | B13: ='Import Dependence'!B13*0.5+'Export Dependence'!B13*0.5 -> 0.10935 | C13: ='Import Dependence'!C13*0.5+'Export Dependence'!C13*0.5 -> 0.042413024 | D13: ='Import Dependence'!D13*0.5+'Export Dependence'!D13*0.5 -> 0.0377 | E13: ='Import Dependence'!E13*0.5+'Export Dependence'!E13*0.5 -> 0.01245 | F13: ='Import Dependence'!F13*0.5+'Export Dependence'!F13*0.5 -> 0.056469486 | G13: ='Import Dependence'!G13*0.5+'Export Dependence'!G13*0.5 -> 0.028200612 | H13: ='Import Dependence'!H13*0.5+'Export Dependence'!H13*0.5 -> 0.014269378 | I13: ='Import Dependence'!I13*0.5+'Export Dependence'!I13*0.5 -> 0.071293637 | ... AN13: ='Import Dependence'!AN13*0.5+'Export Dependence'!AN13*0.5 -> 0.05995
A14: 2003 | B14: ='Import Dependence'!B14*0.5+'Export Dependence'!B14*0.5 -> 0.09515 | C14: ='Import Dependence'!C14*0.5+'Export Dependence'!C14*0.5 -> 0.035646878 | D14: ='Import Dependence'!D14*0.5+'Export Dependence'!D14*0.5 -> 0.0383 | E14: ='Import Dependence'!E14*0.5+'Export Dependence'!E14*0.5 -> 0.02045 | F14: ='Import Dependence'!F14*0.5+'Export Dependence'!F14*0.5 -> 0.052112063 | G14: ='Import Dependence'!G14*0.5+'Export Dependence'!G14*0.5 -> 0.027077484 | H14: ='Import Dependence'!H14*0.5+'Export Dependence'!H14*0.5 -> 0.012240775 | I14: ='Import Dependence'!I14*0.5+'Export Dependence'!I14*0.5 -> 0.06826946 | ... AN14: ='Import Dependence'!AN14*0.5+'Export Dependence'!AN14*0.5 -> 0.07205
A15: 2004 | B15: ='Import Dependence'!B15*0.5+'Export Dependence'!B15*0.5 -> 0.08695 | C15: ='Import Dependence'!C15*0.5+'Export Dependence'!C15*0.5 -> 0.039487715 | D15: ='Import Dependence'!D15*0.5+'Export Dependence'!D15*0.5 -> 0.026 | E15: ='Import Dependence'!E15*0.5+'Export Dependence'!E15*0.5 -> 0.01325 | F15: ='Import Dependence'!F15*0.5+'Export Dependence'!F15*0.5 -> 0.051118069 | G15: ='Import Dependence'!G15*0.5+'Export Dependence'!G15*0.5 -> 0.019688068 | H15: ='Import Dependence'!H15*0.5+'Export Dependence'!H15*0.5 -> 0.01139018 | I15: ='Import Dependence'!I15*0.5+'Export Dependence'!I15*0.5 -> 0.056513963 | ... AN15: ='Import Dependence'!AN15*0.5+'Export Dependence'!AN15*0.5 -> 0.0499
A16: 2005 | B16: ='Import Dependence'!B16*0.5+'Export Dependence'!B16*0.5 -> 0.06045 | C16: ='Import Dependence'!C16*0.5+'Export Dependence'!C16*0.5 -> 0.040295013 | D16: ='Import Dependence'!D16*0.5+'Export Dependence'!D16*0.5 -> 0.0206 | E16: ='Import Dependence'!E16*0.5+'Export Dependence'!E16*0.5 -> 0.01505 | F16: ='Import Dependence'!F16*0.5+'Export Dependence'!F16*0.5 -> 0.042285391 | G16: ='Import Dependence'!G16*0.5+'Export Dependence'!G16*0.5 -> 0.022106915 | H16: ='Import Dependence'!H16*0.5+'Export Dependence'!H16*0.5 -> 0.013323406 | I16: ='Import Dependence'!I16*0.5+'Export Dependence'!I16*0.5 -> 0.05184474 | ... AN16: ='Import Dependence'!AN16*0.5+'Export Dependence'!AN16*0.5 -> 0.02015
A17: 2006 | B17: ='Import Dependence'!B17*0.5+'Export Dependence'!B17*0.5 -> 0.05255 | C17: ='Import Dependence'!C17*0.5+'Export Dependence'!C17*0.5 -> 0.040247808 | D17: ='Import Dependence'!D17*0.5+'Export Dependence'!D17*0.5 -> 0.04035 | E17: ='Import Dependence'!E17*0.5+'Export Dependence'!E17*0.5 -> 0.0192 | F17: ='Import Dependence'!F17*0.5+'Export Dependence'!F17*0.5 -> 0.041842292 | G17: ='Import Dependence'!G17*0.5+'Export Dependence'!G17*0.5 -> 0.015771678 | H17: ='Import Dependence'!H17*0.5+'Export Dependence'!H17*0.5 -> 0.011499544 | I17: ='Import Dependence'!I17*0.5+'Export Dependence'!I17*0.5 -> 0.050747178 | ... AN17: ='Import Dependence'!AN17*0.5+'Export Dependence'!AN17*0.5 -> 0.0202
A18: 2007 | B18: ='Import Dependence'!B18*0.5+'Export Dependence'!B18*0.5 -> 0.03995 | C18: ='Import Dependence'!C18*0.5+'Export Dependence'!C18*0.5 -> 0.035665484 | D18: ='Import Dependence'!D18*0.5+'Export Dependence'!D18*0.5 -> 0.0553 | E18: ='Import Dependence'!E18*0.5+'Export Dependence'!E18*0.5 -> 0.01365 | F18: ='Import Dependence'!F18*0.5+'Export Dependence'!F18*0.5 -> 0.039451722 | G18: ='Import Dependence'!G18*0.5+'Export Dependence'!G18*0.5 -> 0.0085412282 | H18: ='Import Dependence'!H18*0.5+'Export Dependence'!H18*0.5 -> 0.0096659292 | I18: ='Import Dependence'!I18*0.5+'Export Dependence'!I18*0.5 -> 0.043951587 | ... AN18: ='Import Dependence'!AN18*0.5+'Export Dependence'!AN18*0.5 -> 0.0176
A19: 2008 | B19: ='Import Dependence'!B19*0.5+'Export Dependence'!B19*0.5 -> 0.04575 | C19: ='Import Dependence'!C19*0.5+'Export Dependence'!C19*0.5 -> 0.030415785 | D19: ='Import Dependence'!D19*0.5+'Export Dependence'!D19*0.5 -> 0.0854 | E19: ='Import Dependence'!E19*0.5+'Export Dependence'!E19*0.5 -> 0.00795 | F19: ='Import Dependence'!F19*0.5+'Export Dependence'!F19*0.5 -> 0.035538896 | G19: ='Import Dependence'!G19*0.5+'Export Dependence'!G19*0.5 -> 0.0088276637 | H19: ='Import Dependence'!H19*0.5+'Export Dependence'!H19*0.5 -> 0.0088556996 | I19: ='Import Dependence'!I19*0.5+'Export Dependence'!I19*0.5 -> 0.04469741 | ... AN19: ='Import Dependence'!AN19*0.5+'Export Dependence'!AN19*0.5 -> 0.03415
A20: 2009 | B20: ='Import Dependence'!B20*0.5+'Export Dependence'!B20*0.5 -> 0.0643 | C20: ='Import Dependence'!C20*0.5+'Export Dependence'!C20*0.5 -> 0.028071305 | D20: ='Import Dependence'!D20*0.5+'Export Dependence'!D20*0.5 -> 0.06835 | E20: ='Import Dependence'!E20*0.5+'Export Dependence'!E20*0.5 -> 0.00765 | F20: ='Import Dependence'!F20*0.5+'Export Dependence'!F20*0.5 -> 0.037351559 | G20: ='Import Dependence'!G20*0.5+'Export Dependence'!G20*0.5 -> 0.011462036 | H20: ='Import Dependence'!H20*0.5+'Export Dependence'!H20*0.5 -> 0.0080023578 | I20: ='Import Dependence'!I20*0.5+'Export Dependence'!I20*0.5 -> 0.041371158 | ... AN20: ='Import Dependence'!AN20*0.5+'Export Dependence'!AN20*0.5 -> 0.01185
A21: 2010 | B21: ='Import Dependence'!B21*0.5+'Export Dependence'!B21*0.5 -> 0.05975 | C21: ='Import Dependence'!C21*0.5+'Export Dependence'!C21*0.5 -> 0.030030178 | D21: ='Import Dependence'!D21*0.5+'Export Dependence'!D21*0.5 -> 0.0454 | E21: ='Import Dependence'!E21*0.5+'Export Dependence'!E21*0.5 -> 0.008 | F21: ='Import Dependence'!F21*0.5+'Export Dependence'!F21*0.5 -> 0.035686561 | G21: ='Import Dependence'!G21*0.5+'Export Dependence'!G21*0.5 -> 0.0095976028 | H21: ='Import Dependence'!H21*0.5+'Export Dependence'!H21*0.5 -> 0.0087393732 | I21: ='Import Dependence'!I21*0.5+'Export Dependence'!I21*0.5 -> 0.040852136 | ... AN21: ='Import Dependence'!AN21*0.5+'Export Dependence'!AN21*0.5 -> 0.00945
A22: 2011 | B22: ='Import Dependence'!B22*0.5+'Export Dependence'!B22*0.5 -> 0.05445 | C22: ='Import Dependence'!C22*0.5+'Export Dependence'!C22*0.5 -> 0.032990748 | D22: ='Import Dependence'!D22*0.5+'Export Dependence'!D22*0.5 -> 0.06055 | E22: ='Import Dependence'!E22*0.5+'Export Dependence'!E22*0.5 -> 0.00765 | F22: ='Import Dependence'!F22*0.5+'Export Dependence'!F22*0.5 -> 0.03524267 | G22: ='Import Dependence'!G22*0.5+'Export Dependence'!G22*0.5 -> 0.011012969 | H22: ='Import Dependence'!H22*0.5+'Export Dependence'!H22*0.5 -> 0.0096995718 | I22: ='Import Dependence'!I22*0.5+'Export Dependence'!I22*0.5 -> 0.046157957 | ... AN22: ='Import Dependence'!AN22*0.5+'Export Dependence'!AN22*0.5 -> 0.007
... A28: 2017 | B28: ='Import Dependence'!B28*0.5+'Export Dependence'!B28*0.5 -> 0.02805 | C28: ='Import Dependence'!C28*0.5+'Export Dependence'!C28*0.5 -> 0.04390954 | D28: ='Import Dependence'!D28*0.5+'Export Dependence'!D28*0.5 -> 0.02025 | E28: ='Import Dependence'!E28*0.5+'Export Dependence'!E28*0.5 -> 0.0095 | F28: ='Import Dependence'!F28*0.5+'Export Dependence'!F28*0.5 -> 0.042696162 | G28: ='Import Dependence'!G28*0.5+'Export Dependence'!G28*0.5 -> 0.011469693 | H28: ='Import Dependence'!H28*0.5+'Export Dependence'!H28*0.5 -> 0.010292152 | I28: ='Import Dependence'!I28*0.5+'Export Dependence'!I28*0.5 -> 0.048735406 | ... AN28: ='Import Dependence'!AN28*0.5+'Export Dependence'!AN28*0.5 -> 0.0023
A31: Russia | B31: Armenia | C31: Austria | D31: Azerbaijan | E31: Belarus | F31: Belgium | G31: Bulgaria | H31: Croatia | I31: Cyprus | J31: Czech | K31: Denmark | L31: Estonia | M31: Finland | N31: France | O31: Georgia | P31: Germany | Q31: Greece | R31: Hungary | S31: Ireland | T31: Italy | U31: Kazakhstan | V31: Kyrgyzstan | W31: latvia | X31: Lithuania | Y31: Luxembourg | Z31: Malta | AA31: Moldova | AB31: Netherlands | AC31: Poland | AD31: Portugal | AE31: Romania | AF31: Slovakia | AG31: Slovenia | AH31: Spain | AI31: Sweden | AJ31: Tajikistan | AK31: Turkmenistan | AL31: UK | AM31: Ukraine | AN31: Uzbekistan
A32: 1991
A33: 1992
A34: 1993
A35: 1994
A36: 1995
A37: 1996
A38: 1997
A39: 1998
A40: 1999
A41: 2000 | B41: ='Import Dependence'!B41*0.5+'Export Dependence'!B41*0.5 -> 0.13785 | C41: ='Import Dependence'!C41*0.5+'Export Dependence'!C41*0.5 -> 0.012073341 | D41: ='Import Dependence'!D41*0.5+'Export Dependence'!D41*0.5 -> 0.0949 | E41: ='Import Dependence'!E41*0.5+'Export Dependence'!E41*0.5 -> 0.5674 | F41: ='Import Dependence'!F41*0.5+'Export Dependence'!F41*0.5 -> 0.0065126473 | G41: ='Import Dependence'!G41*0.5+'Export Dependence'!G41*0.5 -> 0.12804277 | H41: ='Import Dependence'!H41*0.5+'Export Dependence'!H41*0.5 -> 0.030180365 | I41: ='Import Dependence'!I41*0.5+'Export Dependence'!I41*0.5 -> 0.040966439 | ... AN41: ='Import Dependence'!AN41*0.5+'Export Dependence'!AN41*0.5 -> 0.24295
A42: 2001 | B42: ='Import Dependence'!B42*0.5+'Export Dependence'!B42*0.5 -> 0.1412 | C42: ='Import Dependence'!C42*0.5+'Export Dependence'!C42*0.5 -> 0.012745393 | D42: ='Import Dependence'!D42*0.5+'Export Dependence'!D42*0.5 -> 0.062 | E42: ='Import Dependence'!E42*0.5+'Export Dependence'!E42*0.5 -> 0.5704 | F42: ='Import Dependence'!F42*0.5+'Export Dependence'!F42*0.5 -> 0.0076014116 | G42: ='Import Dependence'!G42*0.5+'Export Dependence'!G42*0.5 -> 0.10877266 | H42: ='Import Dependence'!H42*0.5+'Export Dependence'!H42*0.5 -> 0.02800253 | I42: ='Import Dependence'!I42*0.5+'Export Dependence'!I42*0.5 -> 0.037309942 | ... AN42: ='Import Dependence'!AN42*0.5+'Export Dependence'!AN42*0.5 -> 0.24055
A43: 2002 | B43: ='Import Dependence'!B43*0.5+'Export Dependence'!B43*0.5 -> 0.14775 | C43: ='Import Dependence'!C43*0.5+'Export Dependence'!C43*0.5 -> 0.011976659 | D43: ='Import Dependence'!D43*0.5+'Export Dependence'!D43*0.5 -> 0.08575 | E43: ='Import Dependence'!E43*0.5+'Export Dependence'!E43*0.5 -> 0.55155 | F43: ='Import Dependence'!F43*0.5+'Export Dependence'!F43*0.5 -> 0.0071659055 | G43: ='Import Dependence'!G43*0.5+'Export Dependence'!G43*0.5 -> 0.076086752 | H43: ='Import Dependence'!H43*0.5+'Export Dependence'!H43*0.5 -> 0.027063165 | I43: ='Import Dependence'!I43*0.5+'Export Dependence'!I43*0.5 -> 0.035804854 | ... AN43: ='Import Dependence'!AN43*0.5+'Export Dependence'!AN43*0.5 -> 0.23495
A44: 2003 | B44: ='Import Dependence'!B44*0.5+'Export Dependence'!B44*0.5 -> 0.13885 | C44: ='Import Dependence'!C44*0.5+'Export Dependence'!C44*0.5 -> 0.014618808 | D44: ='Import Dependence'!D44*0.5+'Export Dependence'!D44*0.5 -> 0.0911 | E44: ='Import Dependence'!E44*0.5+'Export Dependence'!E44*0.5 -> 0.51285 | F44: ='Import Dependence'!F44*0.5+'Export Dependence'!F44*0.5 -> 0.0083257109 | G44: ='Import Dependence'!G44*0.5+'Export Dependence'!G44*0.5 -> 0.066003199 | H44: ='Import Dependence'!H44*0.5+'Export Dependence'!H44*0.5 -> 0.022044686 | I44: ='Import Dependence'!I44*0.5+'Export Dependence'!I44*0.5 -> 0.036807142 | ... AN44: ='Import Dependence'!AN44*0.5+'Export Dependence'!AN44*0.5 -> 0.22375
A45: 2004 | B45: ='Import Dependence'!B45*0.5+'Export Dependence'!B45*0.5 -> 0.1181 | C45: ='Import Dependence'!C45*0.5+'Export Dependence'!C45*0.5 -> 0.015183831 | D45: ='Import Dependence'!D45*0.5+'Export Dependence'!D45*0.5 -> 0.0952 | E45: ='Import Dependence'!E45*0.5+'Export Dependence'!E45*0.5 -> 0.55705 | F45: ='Import Dependence'!F45*0.5+'Export Dependence'!F45*0.5 -> 0.010168493 | G45: ='Import Dependence'!G45*0.5+'Export Dependence'!G45*0.5 -> 0.068234919 | H45: ='Import Dependence'!H45*0.5+'Export Dependence'!H45*0.5 -> 0.01377591 | I45: ='Import Dependence'!I45*0.5+'Export Dependence'!I45*0.5 -> 0.029793971 | ... AN45: ='Import Dependence'!AN45*0.5+'Export Dependence'!AN45*0.5 -> 0.2409
A46: 2005 | B46: ='Import Dependence'!B46*0.5+'Export Dependence'!B46*0.5 -> 0.12835 | C46: ='Import Dependence'!C46*0.5+'Export Dependence'!C46*0.5 -> 0.020719913 | D46: ='Import Dependence'!D46*0.5+'Export Dependence'!D46*0.5 -> 0.0941 | E46: ='Import Dependence'!E46*0.5+'Export Dependence'!E46*0.5 -> 0.46305 | F46: ='Import Dependence'!F46*0.5+'Export Dependence'!F46*0.5 -> 0.0119065 | G46: ='Import Dependence'!G46*0.5+'Export Dependence'!G46*0.5 -> 0.019069702 | H46: ='Import Dependence'!H46*0.5+'Export Dependence'!H46*0.5 -> 0.010964303 | I46: ='Import Dependence'!I46*0.5+'Export Dependence'!I46*0.5 -> 0.034235656 | ... AN46: ='Import Dependence'!AN46*0.5+'Export Dependence'!AN46*0.5 -> 0.2493
A47: 2006 | B47: ='Import Dependence'!B47*0.5+'Export Dependence'!B47*0.5 -> 0.12245 | C47: ='Import Dependence'!C47*0.5+'Export Dependence'!C47*0.5 -> 0.021536819 | D47: ='Import Dependence'!D47*0.5+'Export Dependence'!D47*0.5 -> 0.11135 | E47: ='Import Dependence'!E47*0.5+'Export Dependence'!E47*0.5 -> 0.45075 | F47: ='Import Dependence'!F47*0.5+'Export Dependence'!F47*0.5 -> 0.013296401 | G47: ='Import Dependence'!G47*0.5+'Export Dependence'!G47*0.5 -> 0.020793717 | H47: ='Import Dependence'!H47*0.5+'Export Dependence'!H47*0.5 -> 0.0097873258 | I47: ='Import Dependence'!I47*0.5+'Export Dependence'!I47*0.5 -> 0.036277027 | ... AN47: ='Import Dependence'!AN47*0.5+'Export Dependence'!AN47*0.5 -> 0.2678
...

Sheet Import HHI Hierarchy Scores
B1: Armenia | C1: Austria | D1: Azerbaijan | E1: Belarus | F1: Belgium | G1: Bulgaria | H1: Croatia | I1: Cyprus | J1: Czech | K1: Denmark | L1: Estonia | M1: Finland | N1: France | O1: Georgia | P1: Germany | Q1: Greece | R1: Hungary | S1: Ireland | T1: Italy | U1: Kazakhstan | V1: Kyrgyzstan | W1: latvia | X1: Lithuania | Y1: Luxembourg | Z1: Malta | AA1: Moldova | AB1: Netherlands | AC1: Poland | AD1: Portugal | AE1: Romania | AF1: Slovakia | AG1: Slovenia | AH1: Spain | AI1: Sweden | AJ1: Tajikistan | AK1: Turkmenistan | AL1: UK | AM1: Ukraine | AN1: Uzbekistan
A2: 1991 | B2: 0 | C2: 0 | D2: 0 | E2: 0 | F2: 0 | G2: 0 | H2: 0 | I2: 0 | J2: 0 | K2: 0 | L2: 0 | M2: 0 | N2: 0 | O2: 0 | P2: 0 | Q2: 0 | R2: 0 | S2: 0.5 | T2: 0 | U2: 0 | V2: 0 | W2: 0 | X2: 0 | Y2: 0 | Z2: 0 | AA2: 0 | AB2: 0 | AC2: 0 | AD2: 0 | AE2: 0 | AF2: 0 | AG2: 0 | AH2: 0 | AI2: 0 | AJ2: 0 | AK2: 0 | AL2: 0 | AM2: 0 | AN2: 0
A3: 1992 | B3: 0 | C3: 0 | D3: 0 | E3: 0 | F3: 0 | G3: 0 | H3: 0 | I3: 0 | J3: 0 | K3: 0 | L3: 0 | M3: 0 | N3: 0 | O3: 0 | P3: 0 | Q3: 0 | R3: 0 | S3: 1 | T3: 0 | U3: 0 | V3: 0 | W3: 0 | X3: 0 | Y3: 0 | Z3: 0 | AA3: 0 | AB3: 0 | AC3: 0 | AD3: 0 | AE3: 0 | AF3: 0 | AG3: 0 | AH3: 0 | AI3: 0 | AJ3: 0 | AK3: 0 | AL3: 0 | AM3: 0 | AN3: 0
A4: 1993 | B4: 0 | C4: 0 | D4: 0 | E4: 0 | F4: 0 | G4: 0 | H4: 0 | I4: 0 | J4: 0 | K4: 0 | L4: 0 | M4: 0 | N4: 0 | O4: 0 | P4: 0 | Q4: 0 | R4: 0 | S4: 0.5 | T4: 0 | U4: 0 | V4: 0 | W4: 0 | X4: 0 | Y4: 0 | Z4: 0 | AA4: 0 | AB4: 0 | AC4: 0 | AD4: 0 | AE4: 0 | AF4: 0 | AG4: 0 | AH4: 0 | AI4: 0 | AJ4: 0 | AK4: 0 | AL4: 0 | AM4: 0 | AN4: 0
A5: 1994 | B5: 0 | C5: 0 | D5: 0 | E5: 0 | F5: 0 | G5: 0 | H5: 0 | I5: 0 | J5: 0 | K5: 0 | L5: 0 | M5: 0 | N5: 0 | O5: 0 | P5: 0 | Q5: 0 | R5: 0 | S5: 0.5 | T5: 0 | U5: 0 | V5: 0 | W5: 0 | X5: 0 | Y5: 0 | Z5: 0 | AA5: 0 | AB5: 0 | AC5: 0 | AD5: 0 | AE5: 0 | AF5: 0 | AG5: 0 | AH5: 0 | AI5: 0 | AJ5: 0 | AK5: 0 | AL5: 0 | AM5: 0 | AN5: 0
A6: 1995 | B6: 0.5 | C6: 0.5 | D6: 0.5 | E6: 0 | F6: 0 | G6: 0 | H6: 0 | I6: 0 | J6: 0 | K6: 0 | L6: 0 | M6: 0 | N6: 0 | O6: 0 | P6: 0 | Q6: 0 | R6: 0 | S6: 0.5 | T6: 0 | U6: 0 | V6: 0 | W6: 0 | X6: 0 | Y6: 0 | Z6: 0 | AA6: 0 | AB6: 0 | AC6: 0 | AD6: 0 | AE6: 0 | AF6: 0 | AG6: 0 | AH6: 0 | AI6: 0 | AJ6: 0 | AK6: 0 | AL6: 0 | AM6: 0 | AN6: 0
A7: 1996 | B7: 0 | C7: 0.5 | D7: 0 | E7: 0 | F7: 0 | G7: 0 | H7: 0 | I7: 0 | J7: 0 | K7: 0 | L7: 0 | M7: 0 | N7: 0 | O7: 0 | P7: 0 | Q7: 0 | R7: 0 | S7: 0.5 | T7: 0 | U7: 1 | V7: 0 | W7: 0 | X7: 0 | Y7: 0 | Z7: 0 | AA7: 0 | AB7: 0 | AC7: 0 | AD7: 0 | AE7: 0 | AF7: 0 | AG7: 0 | AH7: 0 | AI7: 0 | AJ7: 1 | AK7: 0.5 | AL7: 0 | AM7: 1 | AN7: 0
A8: 1997 | B8: 0 | C8: 0.5 | D8: 0 | E8: 0.5 | F8: 0 | G8: 0 | H8: 0 | I8: 0 | J8: 0 | K8: 0 | L8: 0 | M8: 0 | N8: 0 | O8: 0 | P8: 0 | Q8: 0 | R8: 0 | S8: 0.5 | T8: 0 | U8: 1 | V8: 0.5 | W8: 0 | X8: 0 | Y8: 0 | Z8: 0 | AA8: 0 | AB8: 0 | AC8: 0 | AD8: 0 | AE8: 0 | AF8: 0 | AG8: 0 | AH8: 0 | AI8: 0 | AJ8: 0.5 | AK8: 0 | AL8: 0 | AM8: 0.5 | AN8: 0
A9: 1998 | B9: 0 | C9: 0.5 | D9: 0 | E9: 1 | F9: 0 | G9: 0 | H9: 0 | I9: 0 | J9: 0 | K9: 0 | L9: 0 | M9: 0 | N9: 0 | O9: 0 | P9: 0 | Q9: 0 | R9: 0 | S9: 0.5 | T9: 0 | U9: 0.5 | V9: 0.5 | W9: 0 | X9: 0 | Y9: 0 | Z9: 0 | AA9: 0 | AB9: 0 | AC9: 0 | AD9: 0 | AE9: 0 | AF9: 0 | AG9: 0 | AH9: 0 | AI9: 0 | AJ9: 0 | AK9: 0 | AL9: 0 | AM9: 0.5 | AN9: 0
A10: 1999 | B10: 0 | C10: 0.5 | D10: 0 | E10: 1 | F10: 0 | G10: 0 | H10: 0 | I10: 0 | J10: 0 | K10: 0 | L10: 0 | M10: 0 | N10: 0 | O10: 0 | P10: 0 | Q10: 0 | R10: 0 | S10: 0.5 | T10: 0 | U10: 0.5 | V10: 0 | W10: 0 | X10: 0 | Y10: 0.5 | Z10: 0 | AA10: 0 | AB10: 0 | AC10: 0 | AD10: 0 | AE10: 0 | AF10: 0 | AG10: 0 | AH10: 0 | AI10: 0 | AJ10: 0.5 | AK10: 0 | AL10: 0 | AM10: 0.5 | AN10: 0
A11: 2000 | B11: 0 | C11: 0.5 | D11: 0 | E11: 1 | F11: 0 | G11: 0 | H11: 0 | I11: 0 | J11: 0 | K11: 0 | L11: 0 | M11: 0 | N11: 0 | O11: 0 | P11: 0 | Q11: 0 | R11: 0 | S11: 0.5 | T11: 0 | U11: 0.5 | V11: 0 | W11: 0 | X11: 0 | Y11: 0.5 | Z11: 0 | AA11: 0 | AB11: 0 | AC11: 0 | AD11: 0 | AE11: 0 | AF11: 0 | AG11: 0 | AH11: 0 | AI11: 0 | AJ11: 0.5 | AK11: 0 | AL11: 0 | AM11: 0.5 | AN11: 0
A12: 2001 | B12: 0 | C12: 0.5 | D12: 0 | E12: 1 | F12: 0 | G12: 0 | H12: 0 | I12: 0 | J12: 0 | K12: 0 | L12: 0 | M12: 0 | N12: 0 | O12: 0 | P12: 0 | Q12: 0 | R12: 0 | S12: 0.5 | T12: 0 | U12: 0.5 | V12: 0 | W12: 0 | X12: 0 | Y12: 0.5 | Z12: 0 | AA12: 0 | AB12: 0 | AC12: 0 | AD12: 0 | AE12: 0 | AF12: 0 | AG12: 0 | AH12: 0 | AI12: 0 | AJ12: 0 | AK12: 0 | AL12: 0 | AM12: 0 | AN12: 0
A13: 2002 | B13: 0 | C13: 0.5 | D13: 0 | E13: 1 | F13: 0 | G13: 0 | H13: 0 | I13: 0 | J13: 0 | K13: 0 | L13: 0 | M13: 0 | N13: 0 | O13: 0 | P13: 0 | Q13: 0 | R13: 0 | S13: 0.5 | T13: 0 | U13: 0.5 | V13: 0 | W13: 0 | X13: 0 | Y13: 0.5 | Z13: 0 | AA13: 0 | AB13: 0 | AC13: 0 | AD13: 0 | AE13: 0 | AF13: 0 | AG13: 0 | AH13: 0 | AI13: 0 | AJ13: 0 | AK13: 0 | AL13: 0 | AM13: 0 | AN13: 0
... A28: 2017 | B28: 0 | C28: 0.5 | D28: 0 | E28: 1 | F28: 0 | G28: 0 | H28: 0 | I28: 0 | J28: 0 | K28: 0 | L28: 0 | M28: 0 | N28: 0 | O28: 0 | P28: 0 | Q28: 0 | R28: 0 | S28: 0.5 | T28: 0 | U28: 0.5 | V28: 1 | W28: 0 | X28: 0 | Y28: 0.5 | Z28: 0 | AA28: 0 | AB28: 0 | AC28: 0 | AD28: 0 | AE28: 0 | AF28: 0 | AG28: 0 | AH28: 0 | AI28: 0 | AJ28: 1 | AK28: 0 | AL28: 0 | AM28: 0 | AN28: 0

Sheet Export HHI Hierarchy Scores
B1: Armenia | C1: Austria | D1: Azerbaijan | E1: Belarus | F1: Belgium | G1: Bulgaria | H1: Croatia | I1: Cyprus | J1: Czech | K1: Denmark | L1: Estonia | M1: Finland | N1: France | O1: Georgia | P1: Germany | Q1: Greece | R1: Hungary | S1: Ireland | T1: Italy | U1: Kazakhstan | V1: Kyrgyzstan | W1: latvia | X1: Lithuania | Y1: Luxembourg | Z1: Malta | AA1: Moldova | AB1: Netherlands | AC1: Poland | AD1: Portugal | AE1: Romania | AF1: Slovakia | AG1: Slovenia | AH1: Spain | AI1: Sweden | AJ1: Tajikistan | AK1: Turkmenistan | AL1: UK | AM1: Ukraine | AN1: Uzbekistan
A2: 1991 | B2: 0 | C2: 0 | D2: 0 | E2: 0 | F2: 0 | G2: 0 | H2: 0 | I2: 0 | J2: 0 | K2: 0 | L2: 0 | M2: 0 | N2: 0 | O2: 0 | P2: 0 | Q2: 0 | R2: 0 | S2: 0 | T2: 0 | U2: 0 | V2: 0 | W2: 0 | X2: 0 | Y2: 0 | Z2: 0 | AA2: 0 | AB2: 0 | AC2: 0 | AD2: 0 | AE2: 0 | AF2: 0 | AG2: 0 | AH2: 0 | AI2: 0 | AJ2: 0 | AK2: 0 | AL2: 0 | AM2: 0 | AN2: 0
A3: 1992 | B3: 0 | C3: 0 | D3: 0 | E3: 0 | F3: 0 | G3: 0 | H3: 0 | I3: 0 | J3: 0 | K3: 0 | L3: 0 | M3: 0 | N3: 0 | O3: 0 | P3: 0 | Q3: 0 | R3: 0 | S3: 0 | T3: 0 | U3: 0 | V3: 0 | W3: 0 | X3: 0 | Y3: 0 | Z3: 0 | AA3: 0 | AB3: 0 | AC3: 0 | AD3: 0 | AE3: 0 | AF3: 0 | AG3: 0 | AH3: 0 | AI3: 0 | AJ3: 0 | AK3: 0 | AL3: 0 | AM3: 0 | AN3: 0
A4: 1993 | B4: 0 | C4: 0 | D4: 0 | E4: 0 | F4: 0 | G4: 0 | H4: 0 | I4: 0 | J4: 0 | K4: 0 | L4: 0 | M4: 0 | N4: 0 | O4: 0 | P4: 0 | Q4: 0 | R4: 0 | S4: 0 | T4: 0 | U4: 0 | V4: 0 | W4: 0 | X4: 0 | Y4: 0 | Z4: 0 | AA4: 0 | AB4: 0 | AC4: 0 | AD4: 0 | AE4: 0 | AF4: 0 | AG4: 0 | AH4: 0 | AI4: 0 | AJ4: 0 | AK4: 0 | AL4: 0 | AM4: 0 | AN4: 0
A5: 1994 | B5: 0 | C5: 0 | D5: 0 | E5: 0 | F5: 0 | G5: 0 | H5: 0 | I5: 0 | J5: 0 | K5: 0 | L5: 0 | M5: 0 | N5: 0 | O5: 0 | P5: 0 | Q5: 0 | R5: 0 | S5: 0 | T5: 0 | U5: 0 | V5: 0 | W5: 0 | X5: 0 | Y5: 0 | Z5: 0 | AA5: 0 | AB5: 0 | AC5: 0 | AD5: 0 | AE5: 0 | AF5: 0 | AG5: 0 | AH5: 0 | AI5: 0 | AJ5: 0 | AK5: 0 | AL5: 0 | AM5: 0 | AN5: 0
A6: 1995 | B6: 1 | C6: 0.5 | D6: 0 | E6: 0 | F6: 0 | G6: 0 | H6: 0 | I6: 0 | J6: 0 | K6: 0 | L6: 0 | M6: 0 | N6: 0 | O6: 1 | P6: 0 | Q6: 0 | R6: 0 | S6: 0 | T6: 0 | U6: 0 | V6: 0.5 | W6: 0 | X6: 0 | Y6: 0 | Z6: 0 | AA6: 0.5 | AB6: 0 | AC6: 0 | AD6: 0 | AE6: 0 | AF6: 0 | AG6: 0 | AH6: 0 | AI6: 0 | AJ6: 0 | AK6: 0 | AL6: 0 | AM6: 0 | AN6: 0
A7: 1996 | B7: 1 | C7: 0.5 | D7: 0.5 | E7: 0 | F7: 0 | G7: 0 | H7: 0 | I7: 0 | J7: 0 | K7: 0 | L7: 0 | M7: 0 | N7: 0 | O7: 0 | P7: 0 | Q7: 0 | R7: 0 | S7: 0 | T7: 0 | U7: 1 | V7: 0.5 | W7: 0 | X7: 0 | Y7: 0 | Z7: 0 | AA7: 1 | AB7: 0 | AC7: 0 | AD7: 0 | AE7: 0 | AF7: 0 | AG7: 0 | AH7: 0 | AI7: 0 | AJ7: 0 | AK7: 0.5 | AL7: 0 | AM7: 0 | AN7: 0
A8: 1997 | B8: 0.5 | C8: 0 | D8: 0 | E8: 0 | F8: 0 | G8: 0 | H8: 0 | I8: 0 | J8: 0 | K8: 0 | L8: 0 | M8: 0 | N8: 0 | O8: 0.5 | P8: 0 | Q8: 0 | R8: 0 | S8: 0 | T8: 0 | U8: 1 | V8: 1 | W8: 0 | X8: 0 | Y8: 0 | Z8: 0 | AA8: 1 | AB8: 0 | AC8: 0 | AD8: 0 | AE8: 0 | AF8: 0 | AG8: 0 | AH8: 0 | AI8: 0 | AJ8: 0.5 | AK8: 1 | AL8: 0 | AM8: 0 | AN8: 0
A9: 1998 | B9: 0.5 | C9: 0.5 | D9: 0 | E9: 1 | F9: 0 | G9: 0 | H9: 0 | I9: 0 | J9: 0 | K9: 0 | L9: 0 | M9: 0 | N9: 0 | O9: 0 | P9: 0 | Q9: 0 | R9: 0 | S9: 0 | T9: 0 | U9: 0.5 | V9: 1 | W9: 0 | X9: 0 | Y9: 0 | Z9: 0 | AA9: 0.5 | AB9: 0 | AC9: 0 | AD9: 0 | AE9: 0 | AF9: 0 | AG9: 0 | AH9: 0 | AI9: 0 | AJ9: 0 | AK9: 0 | AL9: 0 | AM9: 0 | AN9: 0
A10: 1999 | B10: 0 | C10: 0 | D10: 0 | E10: 1 | F10: 0 | G10: 0 | H10: 0 | I10: 0 | J10: 0.5 | K10: 0 | L10: 0 | M10: 0 | N10: 0 | O10: 0 | P10: 0 | Q10: 0 | R10: 0.5 | S10: 0 | T10: 0 | U10: 0 | V10: 1 | W10: 0 | X10: 0 | Y10: 0 | Z10: 0 | AA10: 0.5 | AB10: 0 | AC10: 0 | AD10: 0 | AE10: 0 | AF10: 0 | AG10: 0 | AH10: 0 | AI10: 0 | AJ10: 0.5 | AK10: 1 | AL10: 0 | AM10: 0 | AN10: 0
A11: 2000 | B11: 0 | C11: 0 | D11: 0 | E11: 1 | F11: 0 | G11: 0 | H11: 0 | I11: 0 | J11: 0.5 | K11: 0 | L11: 0.5 | M11: 0 | N11: 0 | O11: 0 | P11: 0 | Q11: 0 | R11: 0.5 | S11: 0 | T11: 0 | U11: 0 | V11: 0.5 | W11: 0 | X11: 0 | Y11: 0 | Z11: 0 | AA11: 0.5 | AB11: 0 | AC11: 0 | AD11: 0 | AE11: 0 | AF11: 0 | AG11: 0 | AH11: 0 | AI11: 0 | AJ11: 1 | AK11: 1 | AL11: 0 | AM11: 0 | AN11: 0
A12: 2001 | B12: 0 | C12: 0 | D12: 0.5 | E12: 1 | F12: 0 | G12: 0 | H12: 0 | I12: 0 | J12: 0.5 | K12: 0 | L12: 0.5 | M12: 0 | N12: 0 | O12: 0 | P12: 0 | Q12: 0 | R12: 0.5 | S12: 0 | T12: 0 | U12: 0 | V12: 0.5 | W12: 0 | X12: 0 | Y12: 0 | Z12: 0 | AA12: 0.5 | AB12: 0 | AC12: 0 | AD12: 0 | AE12: 0 | AF12: 0 | AG12: 0 | AH12: 0 | AI12: 0 | AJ12: 0.5 | AK12: 1 | AL12: 0 | AM12: 0 | AN12: 0
A13: 2002 | B13: 0 | C13: 0 | D13: 0 | E13: 0.5 | F13: 0 | G13: 0 | H13: 0 | I13: 0 | J13: 0.5 | K13: 0 | L13: 0 | M13: 0 | N13: 0 | O13: 0 | P13: 0 | Q13: 0 | R13: 0.5 | S13: 0 | T13: 0 | U13: 0 | V13: 0 | W13: 0 | X13: 0 | Y13: 0 | Z13: 0 | AA13: 0 | AB13: 0 | AC13: 0 | AD13: 0 | AE13: 0 | AF13: 0 | AG13: 0 | AH13: 0 | AI13: 0 | AJ13: 0 | AK13: 1 | AL13: 0 | AM13: 0 | AN13: 0
... A28: 2017 | B28: 0 | C28: 0 | D28: 0 | E28: 0.5 | F28: 0 | G28: 0 | H28: 0 | I28: 0 | J28: 0 | K28: 0 | L28: 0 | M28: 0 | N28: 0 | O28: 0 | P28: 0 | Q28: 0 | R28: 0 | S28: 0 | T28: 0 | U28: 0 | V28: 0 | W28: 0 | X28: 0 | Y28: 0 | Z28: 0 | AA28: 0 | AB28: 0 | AC28: 0 | AD28: 0 | AE28: 0 | AF28: 0 | AG28: 0 | AH28: 0 | AI28: 0 | AJ28: 0.5 | AK28: 1 | AL28: 0 | AM28: 0 | AN28: 1

Sheet Import Dependence
A1: US | B1: Armenia | C1: Austria | D1: Azerbaijan | E1: Belarus | F1: Belgium | G1: Bulgaria | H1: Croatia | I1: Cyprus | J1: Czech | K1: Denmark | L1: Estonia | M1: Finland | N1: France | O1: Georgia | P1: Germany | Q1: Greece | R1: Hungary | S1: Ireland | T1: Italy | U1: Kazakhstan | V1: Kyrgyzstan | W1: latvia | X1: Lithuania | Y1: Luxembourg | Z1: Malta | AA1: Moldova | AB1: Netherlands | AC1: Poland | AD1: Portugal | AE1: Romania | AF1: Slovakia | AG1: Slovenia | AH1: Spain | AI1: Sweden | AJ1: Tajikistan | AK1: Turkmenistan | AL1: UK | AM1: Ukraine | AN1: Uzbekistan
A2: 1991
A3: 1992
A4: 1993
A5: 1994
A6: 1995 | B6: 0.316 | D6: 0.0703 | E6: 0.0146 | O6: 0.1852 | U6: 0.0175 | V6: 0.0598 | AA6: 0.0181 | AJ6: 0.1121 | AK6: 0.0973 | AM6: 0.0231 | AN6: 0.0134
A7: 1996 | B7: 0.1396 | D7: 0.0313 | E7: 0.0111 | O7: 0.0755 | U7: 0.0112 | V7: 0.0486 | AA7: 0.0308 | AJ7: 0.0532 | AK7: 0.1803 | AM7: 0.0355 | AN7: 0.0801
A8: 1997 | B8: 0.1443 | D8: 0.0357 | E8: 0.0055 | O8: 0.0784 | U8: 0.0171 | V8: 0.0471 | AA8: 0.0088 | AJ8: 0.0564 | AK8: 0.1005 | AM8: 0.0369 | AN8: 0.0538
A9: 1998 | B9: 0.0749 | D9: 0.0554 | E9: 0.0156 | O9: 0.0906 | U9: 0.0103 | V9: 0.0269 | AA9: 0.0321 | AJ9: 0.0341 | AK9: 0.0206 | AM9: 0.0401 | AN9: 0.047
A10: 1999 | B10: 0.1291 | D10: 0.0763 | E10: 0.0223 | O10: 0.1228 | U10: 0.0088 | V10: 0.025 | AA10: 0.0318 | AJ10: 0.0416 | AK10: 0.0122 | AM10: 0.0351 | AN10: 0.149
A11: 2000 | B11: 0.1238 | C11: 0.040798753 | D11: 0.1675 | E11: 0.014 | F11: 0.074918067 | G11: 0.029251967 | I11: 0.060687857 | J11: 0.040690534 | K11: 0.042597606 | L11: 0.021922147 | M11: 0.048215826 | N11: 0.072710257 | O11: 0.1049 | P11: 0.0725365 | Q11: 0.032294508 | R11: 0.038135515 | S11: 0.16111696 | T11: 0.052288506 | U11: 0.0519 | V11: 0.0847 | W11: 0.019867088 | X11: 0.024587013 | Y11: 0.034318016 | Z11: 0.10629303 | AA11: 0.0515 | AB11: 0.10168298 | AC11: 0.044639452 | AD11: 0.029571952 | AE11: 0.03017852 | AF11: 0.020131996 | AG11: 0.029680827 | AH11: 0.043805394 | AI11: 0.070423361 | AJ11: 0.033 | AK11: 0.0826 | AL11: 0.13139164 | AM11: 0.0252 | AN11: 0.0821
A12: 2001 | B12: 0.1029 | C12: 0.038428231 | D12: 0.1282 | E12: 0.0151 | F12: 0.069903123 | G12: 0.026215727 | I12: 0.074847879 | J12: 0.038708962 | K12: 0.04690905 | L12: 0.022918238 | M12: 0.041975697 | N12: 0.073511448 | O12: 0.1143 | P12: 0.070044242 | Q12: 0.03193103 | R12: 0.042286244 | S12: 0.14981917 | T12: 0.048876614 | U12: 0.0539 | V12: 0.0551 | W12: 0.018432445 | X12: 0.0314234 | Y12: 0.051875952 | Z12: 0.12347745 | AA12: 0.0289 | AB12: 0.099035683 | AC12: 0.033965163 | AD12: 0.036313865 | AE12: 0.031724869 | AF12: 0.019078233 | AG12: 0.02940386 | AH12: 0.038673972 | AI12: 0.058940907 | AJ12: 0.0669 | AK12: 0.2318 | AL12: 0.13297978 | AM12: 0.0264 | AN12: 0.0636
A13: 2002 | B13: 0.1185 | C13: 0.035179914 | D13: 0.0491 | E13: 0.0113 | F13: 0.065870058 | G13: 0.021694515 | I13: 0.03777107 | J13: 0.031979015 | K13: 0.037491203 | L13: 0.031088236 | M13: 0.036753994 | N13: 0.06807234 | O13: 0.1064 | P13: 0.062906358 | Q13: 0.038794853 | R13: 0.036989377 | S13: 0.15795178 | T13: 0.048033699 | U13: 0.0679 | V13: 0.0778 | W13: 0.015666481 | X13: 0.028771495 | Y13: 0.040038538 | Z13: 0.099592886 | AA13: 0.0386 | AB13: 0.090428949 | AC13: 0.033045777 | AD13: 0.020804175 | AE13: 0.030243926 | AF13: 0.021116499 | AG13: 0.028903804 | AH13: 0.034399171 | AI13: 0.052831182 | AJ13: 0.0359 | AK13: 0.0461 | AL13: 0.11451564 | AM13: 0.029 | AN13: 0.0663
