Workbook

Sheet Sheet1
A1: Hierarchy Models
A2: All Equal
A3: Security
A4: Economic
A5: Social
A6: Diplomatic
A8: Hierarchy Category Scores
A9: Security
A10: Economic w/ HHI
A11: Economic w/o HHI
A12: Social
A13: Diplomatic
... A32: Head of State Meetings Data and Hierarchy Score Calculation

Sheet All Equal Model
A1: US
B2: Albania | C2: Armenia | D2: Austria | E2: Azerbaijan | F2: Belarus | G2: Belgium | H2: Bosnia-Herzegovina | I2: Bulgaria | J2: Croatia | K2: Cyprus | L2: Czech | M2: Denmark | N2: Estonia | O2: Finland | P2: France | Q2: Georgia | R2: Germany | S2: Greece | T2: Hungary | U2: Iceland | V2: Ireland | W2: Italy | X2: Kazakhstan | Y2: Kyrgyzstan | Z2: latvia | AA2: Lithuania | AB2: Luxembourg | AC2: Macedonia | AD2: Malta | AE2: Moldova | AF2: Montenegro | AG2: Netherlands | AH2: Norway | AI2: Poland | AJ2: Portugal | AK2: Romania | AL2: Serbia | AM2: Slovakia | AN2: Slovenia | AO2: Spain | AP2: Sweden | AQ2: Switzerland | AR2: Tajikistan | AS2: Turkey | AT2: Turkmenistan | AU2: UK | AV2: Ukraine | AW2: Uzbekistan
A3: 1991 | B3: ='Security Hierarchy'!B3*(1/4)+'Economic Hierarchy'!B3*(1/4)+'Diplomatic Hiearachy'!B3*(1/4)+'Informational Hierarchy'!B33*(1/4) -> #DIV/0! | C3: ='Security Hierarchy'!C3*(1/4)+'Economic Hierarchy'!C3*(1/4)+'Diplomatic Hiearachy'!C3*(1/4)+'Informational Hierarchy'!C33*(1/4) -> #DIV/0! | D3: ='Security Hierarchy'!D3*(1/4)+'Economic Hierarchy'!D3*(1/4)+'Diplomatic Hiearachy'!D3*(1/4)+'Informational Hierarchy'!D33*(1/4) -> #DIV/0! | E3: ='Security Hierarchy'!E3*(1/4)+'Economic Hierarchy'!E3*(1/4)+'Diplomatic Hiearachy'!E3*(1/4)+'Informational Hierarchy'!E33*(1/4) -> #DIV/0! | F3: ='Security Hierarchy'!F3*(1/4)+'Economic Hierarchy'!F3*(1/4)+'Diplomatic Hiearachy'!F3*(1/4)+'Informational Hierarchy'!F33*(1/4) -> #DIV/0! | G3: ='Security Hierarchy'!G3*(1/4)+'Economic Hierarchy'!G3*(1/4)+'Diplomatic Hiearachy'!G3*(1/4)+'Informational Hierarchy'!G33*(1/4) -> #DIV/0! | H3: ='Security Hierarchy'!H3*(1/4)+'Economic Hierarchy'!H3*(1/4)+'Diplomatic Hiearachy'!H3*(1/4)+'Informational Hierarchy'!H33*(1/4) -> #DIV/0! | I3: ='Security Hierarchy'!I3*(1/4)+'Economic Hierarchy'!I3*(1/4)+'Diplomatic Hiearachy'!I3*(1/4)+'Informational Hierarchy'!I33*(1/4) -> #DIV/0! | ... AW3: ='Security Hierarchy'!AW3*(1/4)+'Economic Hierarchy'!AW3*(1/4)+'Diplomatic Hiearachy'!AW3*(1/4)+'Informational Hierarchy'!AW33*(1/4) -> #DIV/0!
A4: 1992 | B4: ='Security Hierarchy'!B4*(1/4)+'Economic Hierarchy'!B4*(1/4)+'Diplomatic Hiearachy'!B4*(1/4)+'Informational Hierarchy'!B34*(1/4) -> #DIV/0! | C4: ='Security Hierarchy'!C4*(1/4)+'Economic Hierarchy'!C4*(1/4)+'Diplomatic Hiearachy'!C4*(1/4)+'Informational Hierarchy'!C34*(1/4) -> #DIV/0! | D4: ='Security Hierarchy'!D4*(1/4)+'Economic Hierarchy'!D4*(1/4)+'Diplomatic Hiearachy'!D4*(1/4)+'Informational Hierarchy'!D34*(1/4) -> #DIV/0! | E4: ='Security Hierarchy'!E4*(1/4)+'Economic Hierarchy'!E4*(1/4)+'Diplomatic Hiearachy'!E4*(1/4)+'Informational Hierarchy'!E34*(1/4) -> #DIV/0! | F4: ='Security Hierarchy'!F4*(1/4)+'Economic Hierarchy'!F4*(1/4)+'Diplomatic Hiearachy'!F4*(1/4)+'Informational Hierarchy'!F34*(1/4) -> #DIV/0! | G4: ='Security Hierarchy'!G4*(1/4)+'Economic Hierarchy'!G4*(1/4)+'Diplomatic Hiearachy'!G4*(1/4)+'Informational Hierarchy'!G34*(1/4) -> #DIV/0! | H4: ='Security Hierarchy'!H4*(1/4)+'Economic Hierarchy'!H4*(1/4)+'Diplomatic Hiearachy'!H4*(1/4)+'Informational Hierarchy'!H34*(1/4) -> #DIV/0! | I4: ='Security Hierarchy'!I4*(1/4)+'Economic Hierarchy'!I4*(1/4)+'Diplomatic Hiearachy'!I4*(1/4)+'Informational Hierarchy'!I34*(1/4) -> #DIV/0! | ... AW4: ='Security Hierarchy'!AW4*(1/4)+'Economic Hierarchy'!AW4*(1/4)+'Diplomatic Hiearachy'!AW4*(1/4)+'Informational Hierarchy'!AW34*(1/4) -> #DIV/0!
A5: 1993 | B5: ='Security Hierarchy'!B5*(1/4)+'Economic Hierarchy'!B5*(1/4)+'Diplomatic Hiearachy'!B5*(1/4)+'Informational Hierarchy'!B35*(1/4) -> #DIV/0! | C5: ='Security Hierarchy'!C5*(1/4)+'Economic Hierarchy'!C5*(1/4)+'Diplomatic Hiearachy'!C5*(1/4)+'Informational Hierarchy'!C35*(1/4) -> #DIV/0! | D5: ='Security Hierarchy'!D5*(1/4)+'Economic Hierarchy'!D5*(1/4)+'Diplomatic Hiearachy'!D5*(1/4)+'Informational Hierarchy'!D35*(1/4) -> #DIV/0! | E5: ='Security Hierarchy'!E5*(1/4)+'Economic Hierarchy'!E5*(1/4)+'Diplomatic Hiearachy'!E5*(1/4)+'Informational Hierarchy'!E35*(1/4) -> #DIV/0! | F5: ='Security Hierarchy'!F5*(1/4)+'Economic Hierarchy'!F5*(1/4)+'Diplomatic Hiearachy'!F5*(1/4)+'Informational Hierarchy'!F35*(1/4) -> #DIV/0! | G5: ='Security Hierarchy'!G5*(1/4)+'Economic Hierarchy'!G5*(1/4)+'Diplomatic Hiearachy'!G5*(1/4)+'Informational Hierarchy'!G35*(1/4) -> #DIV/0! | H5: ='Security Hierarchy'!H5*(1/4)+'Economic Hierarchy'!H5*(1/4)+'Diplomatic Hiearachy'!H5*(1/4)+'Informational Hierarchy'!H35*(1/4) -> #DIV/0! | I5: ='Security Hierarchy'!I5*(1/4)+'Economic Hierarchy'!I5*(1/4)+'Diplomatic Hiearachy'!I5*(1/4)+'Informational Hierarchy'!I35*(1/4) -> #DIV/0! | ... AW5: ='Security Hierarchy'!AW5*(1/4)+'Economic Hierarchy'!AW5*(1/4)+'Diplomatic Hiearachy'!AW5*(1/4)+'Informational Hierarchy'!AW35*(1/4) -> #DIV/0!
A6: 1994 | B6: ='Security Hierarchy'!B6*(1/4)+'Economic Hierarchy'!B6*(1/4)+'Diplomatic Hiearachy'!B6*(1/4)+'Informational Hierarchy'!B36*(1/4) -> #DIV/0! | C6: ='Security Hierarchy'!C6*(1/4)+'Economic Hierarchy'!C6*(1/4)+'Diplomatic Hiearachy'!C6*(1/4)+'Informational Hierarchy'!C36*(1/4) -> #DIV/0! | D6: ='Security Hierarchy'!D6*(1/4)+'Economic Hierarchy'!D6*(1/4)+'Diplomatic Hiearachy'!D6*(1/4)+'Informational Hierarchy'!D36*(1/4) -> #DIV/0! | E6: ='Security Hierarchy'!E6*(1/4)+'Economic Hierarchy'!E6*(1/4)+'Diplomatic Hiearachy'!E6*(1/4)+'Informational Hierarchy'!E36*(1/4) -> #DIV/0! | F6: ='Security Hierarchy'!F6*(1/4)+'Economic Hierarchy'!F6*(1/4)+'Diplomatic Hiearachy'!F6*(1/4)+'Informational Hierarchy'!F36*(1/4) -> #DIV/0! | G6: ='Security Hierarchy'!G6*(1/4)+'Economic Hierarchy'!G6*(1/4)+'Diplomatic Hiearachy'!G6*(1/4)+'Informational Hierarchy'!G36*(1/4) -> #DIV/0! | H6: ='Security Hierarchy'!H6*(1/4)+'Economic Hierarchy'!H6*(1/4)+'Diplomatic Hiearachy'!H6*(1/4)+'Informational Hierarchy'!H36*(1/4) -> #DIV/0! | I6: ='Security Hierarchy'!I6*(1/4)+'Economic Hierarchy'!I6*(1/4)+'Diplomatic Hiearachy'!I6*(1/4)+'Informational Hierarchy'!I36*(1/4) -> #DIV/0! | ... AW6: ='Security Hierarchy'!AW6*(1/4)+'Economic Hierarchy'!AW6*(1/4)+'Diplomatic Hiearachy'!AW6*(1/4)+'Informational Hierarchy'!AW36*(1/4) -> #DIV/0!
A7: 1995 | B7: ='Security Hierarchy'!B7*(1/4)+'Economic Hierarchy'!B7*(1/4)+'Diplomatic Hiearachy'!B7*(1/4)+'Informational Hierarchy'!B37*(1/4) -> #DIV/0! | C7: ='Security Hierarchy'!C7*(1/4)+'Economic Hierarchy'!C7*(1/4)+'Diplomatic Hiearachy'!C7*(1/4)+'Informational Hierarchy'!C37*(1/4) -> #DIV/0! | D7: ='Security Hierarchy'!D7*(1/4)+'Economic Hierarchy'!D7*(1/4)+'Diplomatic Hiearachy'!D7*(1/4)+'Informational Hierarchy'!D37*(1/4) -> #DIV/0! | E7: ='Security Hierarchy'!E7*(1/4)+'Economic Hierarchy'!E7*(1/4)+'Diplomatic Hiearachy'!E7*(1/4)+'Informational Hierarchy'!E37*(1/4) -> #DIV/0! | F7: ='Security Hierarchy'!F7*(1/4)+'Economic Hierarchy'!F7*(1/4)+'Diplomatic Hiearachy'!F7*(1/4)+'Informational Hierarchy'!F37*(1/4) -> #DIV/0! | G7: ='Security Hierarchy'!G7*(1/4)+'Economic Hierarchy'!G7*(1/4)+'Diplomatic Hiearachy'!G7*(1/4)+'Informational Hierarchy'!G37*(1/4) -> #DIV/0! | H7: ='Security Hierarchy'!H7*(1/4)+'Economic Hierarchy'!H7*(1/4)+'Diplomatic Hiearachy'!H7*(1/4)+'Informational Hierarchy'!H37*(1/4) -> #DIV/0! | I7: ='Security Hierarchy'!I7*(1/4)+'Economic Hierarchy'!I7*(1/4)+'Diplomatic Hiearachy'!I7*(1/4)+'Informational Hierarchy'!I37*(1/4) -> #DIV/0! | ... AW7: ='Security Hierarchy'!AW7*(1/4)+'Economic Hierarchy'!AW7*(1/4)+'Diplomatic Hiearachy'!AW7*(1/4)+'Informational Hierarchy'!AW37*(1/4) -> #DIV/0!
A8: 1996 | B8: ='Security Hierarchy'!B8*(1/4)+'Economic Hierarchy'!B8*(1/4)+'Diplomatic Hiearachy'!B8*(1/4)+'Informational Hierarchy'!B38*(1/4) -> #DIV/0! | C8: ='Security Hierarchy'!C8*(1/4)+'Economic Hierarchy'!C8*(1/4)+'Diplomatic Hiearachy'!C8*(1/4)+'Informational Hierarchy'!C38*(1/4) -> #DIV/0! | D8: ='Security Hierarchy'!D8*(1/4)+'Economic Hierarchy'!D8*(1/4)+'Diplomatic Hiearachy'!D8*(1/4)+'Informational Hierarchy'!D38*(1/4) -> #DIV/0! | E8: ='Security Hierarchy'!E8*(1/4)+'Economic Hierarchy'!E8*(1/4)+'Diplomatic Hiearachy'!E8*(1/4)+'Informational Hierarchy'!E38*(1/4) -> #DIV/0! | F8: ='Security Hierarchy'!F8*(1/4)+'Economic Hierarchy'!F8*(1/4)+'Diplomatic Hiearachy'!F8*(1/4)+'Informational Hierarchy'!F38*(1/4) -> #DIV/0! | G8: ='Security Hierarchy'!G8*(1/4)+'Economic Hierarchy'!G8*(1/4)+'Diplomatic Hiearachy'!G8*(1/4)+'Informational Hierarchy'!G38*(1/4) -> #DIV/0! | H8: ='Security Hierarchy'!H8*(1/4)+'Economic Hierarchy'!H8*(1/4)+'Diplomatic Hiearachy'!H8*(1/4)+'Informational Hierarchy'!H38*(1/4) -> #DIV/0! | I8: ='Security Hierarchy'!I8*(1/4)+'Economic Hierarchy'!I8*(1/4)+'Diplomatic Hiearachy'!I8*(1/4)+'Informational Hierarchy'!I38*(1/4) -> #DIV/0! | ... AW8: ='Security Hierarchy'!AW8*(1/4)+'Economic Hierarchy'!AW8*(1/4)+'Diplomatic Hiearachy'!AW8*(1/4)+'Informational Hierarchy'!AW38*(1/4) -> #DIV/0!
A9: 1997 | B9: ='Security Hierarchy'!B9*(1/4)+'Economic Hierarchy'!B9*(1/4)+'Diplomatic Hiearachy'!B9*(1/4)+'Informational Hierarchy'!B39*(1/4) -> #DIV/0! | C9: ='Security Hierarchy'!C9*(1/4)+'Economic Hierarchy'!C9*(1/4)+'Diplomatic Hiearachy'!C9*(1/4)+'Informational Hierarchy'!C39*(1/4) -> #DIV/0! | D9: ='Security Hierarchy'!D9*(1/4)+'Economic Hierarchy'!D9*(1/4)+'Diplomatic Hiearachy'!D9*(1/4)+'Informational Hierarchy'!D39*(1/4) -> #DIV/0! | E9: ='Security Hierarchy'!E9*(1/4)+'Economic Hierarchy'!E9*(1/4)+'Diplomatic Hiearachy'!E9*(1/4)+'Informational Hierarchy'!E39*(1/4) -> #DIV/0! | F9: ='Security Hierarchy'!F9*(1/4)+'Economic Hierarchy'!F9*(1/4)+'Diplomatic Hiearachy'!F9*(1/4)+'Informational Hierarchy'!F39*(1/4) -> #DIV/0! | G9: ='Security Hierarchy'!G9*(1/4)+'Economic Hierarchy'!G9*(1/4)+'Diplomatic Hiearachy'!G9*(1/4)+'Informational Hierarchy'!G39*(1/4) -> #DIV/0! | H9: ='Security Hierarchy'!H9*(1/4)+'Economic Hierarchy'!H9*(1/4)+'Diplomatic Hiearachy'!H9*(1/4)+'Informational Hierarchy'!H39*(1/4) -> #DIV/0! | I9: ='Security Hierarchy'!I9*(1/4)+'Economic Hierarchy'!I9*(1/4)+'Diplomatic Hiearachy'!I9*(1/4)+'Informational Hierarchy'!I39*(1/4) -> #DIV/0! | ... AW9: ='Security Hierarchy'!AW9*(1/4)+'Economic Hierarchy'!AW9*(1/4)+'Diplomatic Hiearachy'!AW9*(1/4)+'Informational Hierarchy'!AW39*(1/4) -> #DIV/0!
A10: 1998 | B10: ='Security Hierarchy'!B10*(1/4)+'Economic Hierarchy'!B10*(1/4)+'Diplomatic Hiearachy'!B10*(1/4)+'Informational Hierarchy'!B40*(1/4) -> #DIV/0! | C10: ='Security Hierarchy'!C10*(1/4)+'Economic Hierarchy'!C10*(1/4)+'Diplomatic Hiearachy'!C10*(1/4)+'Informational Hierarchy'!C40*(1/4) -> #DIV/0! | D10: ='Security Hierarchy'!D10*(1/4)+'Economic Hierarchy'!D10*(1/4)+'Diplomatic Hiearachy'!D10*(1/4)+'Informational Hierarchy'!D40*(1/4) -> #DIV/0! | E10: ='Security Hierarchy'!E10*(1/4)+'Economic Hierarchy'!E10*(1/4)+'Diplomatic Hiearachy'!E10*(1/4)+'Informational Hierarchy'!E40*(1/4) -> #DIV/0! | F10: ='Security Hierarchy'!F10*(1/4)+'Economic Hierarchy'!F10*(1/4)+'Diplomatic Hiearachy'!F10*(1/4)+'Informational Hierarchy'!F40*(1/4) -> #DIV/0! | G10: ='Security Hierarchy'!G10*(1/4)+'Economic Hierarchy'!G10*(1/4)+'Diplomatic Hiearachy'!G10*(1/4)+'Informational Hierarchy'!G40*(1/4) -> #DIV/0! | H10: ='Security Hierarchy'!H10*(1/4)+'Economic Hierarchy'!H10*(1/4)+'Diplomatic Hiearachy'!H10*(1/4)+'Informational Hierarchy'!H40*(1/4) -> #DIV/0! | I10: ='Security Hierarchy'!I10*(1/4)+'Economic Hierarchy'!I10*(1/4)+'Diplomatic Hiearachy'!I10*(1/4)+'Informational Hierarchy'!I40*(1/4) -> #DIV/0! | ... AW10: ='Security Hierarchy'!AW10*(1/4)+'Economic Hierarchy'!AW10*(1/4)+'Diplomatic Hiearachy'!AW10*(1/4)+'Informational Hierarchy'!AW40*(1/4) -> #DIV/0!
A11: 1999 | B11: ='Security Hierarchy'!B11*(1/4)+'Economic Hierarchy'!B11*(1/4)+'Diplomatic Hiearachy'!B11*(1/4)+'Informational Hierarchy'!B41*(1/4) -> #DIV/0! | C11: ='Security Hierarchy'!C11*(1/4)+'Economic Hierarchy'!C11*(1/4)+'Diplomatic Hiearachy'!C11*(1/4)+'Informational Hierarchy'!C41*(1/4) -> #DIV/0! | D11: ='Security Hierarchy'!D11*(1/4)+'Economic Hierarchy'!D11*(1/4)+'Diplomatic Hiearachy'!D11*(1/4)+'Informational Hierarchy'!D41*(1/4) -> #DIV/0! | E11: ='Security Hierarchy'!E11*(1/4)+'Economic Hierarchy'!E11*(1/4)+'Diplomatic Hiearachy'!E11*(1/4)+'Informational Hierarchy'!E41*(1/4) -> #DIV/0! | F11: ='Security Hierarchy'!F11*(1/4)+'Economic Hierarchy'!F11*(1/4)+'Diplomatic Hiearachy'!F11*(1/4)+'Informational Hierarchy'!F41*(1/4) -> #DIV/0! | G11: ='Security Hierarchy'!G11*(1/4)+'Economic Hierarchy'!G11*(1/4)+'Diplomatic Hiearachy'!G11*(1/4)+'Informational Hierarchy'!G41*(1/4) -> #DIV/0! | H11: ='Security Hierarchy'!H11*(1/4)+'Economic Hierarchy'!H11*(1/4)+'Diplomatic Hiearachy'!H11*(1/4)+'Informational Hierarchy'!H41*(1/4) -> #DIV/0! | I11: ='Security Hierarchy'!I11*(1/4)+'Economic Hierarchy'!I11*(1/4)+'Diplomatic Hiearachy'!I11*(1/4)+'Informational Hierarchy'!I41*(1/4) -> #DIV/0! | ... AW11: ='Security Hierarchy'!AW11*(1/4)+'Economic Hierarchy'!AW11*(1/4)+'Diplomatic Hiearachy'!AW11*(1/4)+'Informational Hierarchy'!AW41*(1/4) -> #DIV/0!
A12: 2000 | B12: ='Security Hierarchy'!B12*(1/4)+'Economic Hierarchy'!B12*(1/4)+'Diplomatic Hiearachy'!B12*(1/4)+'Informational Hierarchy'!B42*(1/4) -> 0.18166069 | C12: ='Security Hierarchy'!C12*(1/4)+'Economic Hierarchy'!C12*(1/4)+'Diplomatic Hiearachy'!C12*(1/4)+'Informational Hierarchy'!C42*(1/4) -> 0.21696088 | D12: ='Security Hierarchy'!D12*(1/4)+'Economic Hierarchy'!D12*(1/4)+'Diplomatic Hiearachy'!D12*(1/4)+'Informational Hierarchy'!D42*(1/4) -> 0.20844805 | E12: ='Security Hierarchy'!E12*(1/4)+'Economic Hierarchy'!E12*(1/4)+'Diplomatic Hiearachy'!E12*(1/4)+'Informational Hierarchy'!E42*(1/4) -> 0.2647619 | F12: ='Security Hierarchy'!F12*(1/4)+'Economic Hierarchy'!F12*(1/4)+'Diplomatic Hiearachy'!F12*(1/4)+'Informational Hierarchy'!F42*(1/4) -> 0.1169339 | G12: ='Security Hierarchy'!G12*(1/4)+'Economic Hierarchy'!G12*(1/4)+'Diplomatic Hiearachy'!G12*(1/4)+'Informational Hierarchy'!G42*(1/4) -> 0.36905296 | H12: ='Security Hierarchy'!H12*(1/4)+'Economic Hierarchy'!H12*(1/4)+'Diplomatic Hiearachy'!H12*(1/4)+'Informational Hierarchy'!H42*(1/4) -> 0.15734893 | I12: ='Security Hierarchy'!I12*(1/4)+'Economic Hierarchy'!I12*(1/4)+'Diplomatic Hiearachy'!I12*(1/4)+'Informational Hierarchy'!I42*(1/4) -> 0.12945653 | ... AW12: ='Security Hierarchy'!AW12*(1/4)+'Economic Hierarchy'!AW12*(1/4)+'Diplomatic Hiearachy'!AW12*(1/4)+'Informational Hierarchy'!AW42*(1/4) -> 0.20759915
A13: 2001 | B13: ='Security Hierarchy'!B13*(1/4)+'Economic Hierarchy'!B13*(1/4)+'Diplomatic Hiearachy'!B13*(1/4)+'Informational Hierarchy'!B43*(1/4) -> 0.16462676 | C13: ='Security Hierarchy'!C13*(1/4)+'Economic Hierarchy'!C13*(1/4)+'Diplomatic Hiearachy'!C13*(1/4)+'Informational Hierarchy'!C43*(1/4) -> 0.21702772 | D13: ='Security Hierarchy'!D13*(1/4)+'Economic Hierarchy'!D13*(1/4)+'Diplomatic Hiearachy'!D13*(1/4)+'Informational Hierarchy'!D43*(1/4) -> 0.18292854 | E13: ='Security Hierarchy'!E13*(1/4)+'Economic Hierarchy'!E13*(1/4)+'Diplomatic Hiearachy'!E13*(1/4)+'Informational Hierarchy'!E43*(1/4) -> 0.24080587 | F13: ='Security Hierarchy'!F13*(1/4)+'Economic Hierarchy'!F13*(1/4)+'Diplomatic Hiearachy'!F13*(1/4)+'Informational Hierarchy'!F43*(1/4) -> 0.10565853 | G13: ='Security Hierarchy'!G13*(1/4)+'Economic Hierarchy'!G13*(1/4)+'Diplomatic Hiearachy'!G13*(1/4)+'Informational Hierarchy'!G43*(1/4) -> 0.4913736 | H13: ='Security Hierarchy'!H13*(1/4)+'Economic Hierarchy'!H13*(1/4)+'Diplomatic Hiearachy'!H13*(1/4)+'Informational Hierarchy'!H43*(1/4) -> 0.15092172 | I13: ='Security Hierarchy'!I13*(1/4)+'Economic Hierarchy'!I13*(1/4)+'Diplomatic Hiearachy'!I13*(1/4)+'Informational Hierarchy'!I43*(1/4) -> 0.12429636 | ... AW13: ='Security Hierarchy'!AW13*(1/4)+'Economic Hierarchy'!AW13*(1/4)+'Diplomatic Hiearachy'!AW13*(1/4)+'Informational Hierarchy'!AW43*(1/4) -> 0.14587583
A14: 2002 | B14: ='Security Hierarchy'!B14*(1/4)+'Economic Hierarchy'!B14*(1/4)+'Diplomatic Hiearachy'!B14*(1/4)+'Informational Hierarchy'!B44*(1/4) -> 0.13459776 | C14: ='Security Hierarchy'!C14*(1/4)+'Economic Hierarchy'!C14*(1/4)+'Diplomatic Hiearachy'!C14*(1/4)+'Informational Hierarchy'!C44*(1/4) -> 0.1362807 | D14: ='Security Hierarchy'!D14*(1/4)+'Economic Hierarchy'!D14*(1/4)+'Diplomatic Hiearachy'!D14*(1/4)+'Informational Hierarchy'!D44*(1/4) -> 0.14067705 | E14: ='Security Hierarchy'!E14*(1/4)+'Economic Hierarchy'!E14*(1/4)+'Diplomatic Hiearachy'!E14*(1/4)+'Informational Hierarchy'!E44*(1/4) -> 0.20426557 | F14: ='Security Hierarchy'!F14*(1/4)+'Economic Hierarchy'!F14*(1/4)+'Diplomatic Hiearachy'!F14*(1/4)+'Informational Hierarchy'!F44*(1/4) -> 0.17876439 | G14: ='Security Hierarchy'!G14*(1/4)+'Economic Hierarchy'!G14*(1/4)+'Diplomatic Hiearachy'!G14*(1/4)+'Informational Hierarchy'!G44*(1/4) -> 0.35940761 | H14: ='Security Hierarchy'!H14*(1/4)+'Economic Hierarchy'!H14*(1/4)+'Diplomatic Hiearachy'!H14*(1/4)+'Informational Hierarchy'!H44*(1/4) -> 0.15637636 | I14: ='Security Hierarchy'!I14*(1/4)+'Economic Hierarchy'!I14*(1/4)+'Diplomatic Hiearachy'!I14*(1/4)+'Informational Hierarchy'!I44*(1/4) -> 0.21156557 | ... AW14: ='Security Hierarchy'!AW14*(1/4)+'Economic Hierarchy'!AW14*(1/4)+'Diplomatic Hiearachy'!AW14*(1/4)+'Informational Hierarchy'!AW44*(1/4) -> 0.29799496
... A29: 2017 | B29: ='Security Hierarchy'!B29*(1/4)+'Economic Hierarchy'!B29*(1/4)+'Diplomatic Hiearachy'!B29*(1/4)+'Informational Hierarchy'!B59*(1/4) -> 0.40963062 | C29: ='Security Hierarchy'!C29*(1/4)+'Economic Hierarchy'!C29*(1/4)+'Diplomatic Hiearachy'!C29*(1/4)+'Informational Hierarchy'!C59*(1/4) -> 0.16239768 | D29: ='Security Hierarchy'!D29*(1/4)+'Economic Hierarchy'!D29*(1/4)+'Diplomatic Hiearachy'!D29*(1/4)+'Informational Hierarchy'!D59*(1/4) -> 0.11059639 | E29: ='Security Hierarchy'!E29*(1/4)+'Economic Hierarchy'!E29*(1/4)+'Diplomatic Hiearachy'!E29*(1/4)+'Informational Hierarchy'!E59*(1/4) -> 0.20889593 | F29: ='Security Hierarchy'!F29*(1/4)+'Economic Hierarchy'!F29*(1/4)+'Diplomatic Hiearachy'!F29*(1/4)+'Informational Hierarchy'!F59*(1/4) -> 0.19447233 | G29: ='Security Hierarchy'!G29*(1/4)+'Economic Hierarchy'!G29*(1/4)+'Diplomatic Hiearachy'!G29*(1/4)+'Informational Hierarchy'!G59*(1/4) -> 0.35562658 | H29: ='Security Hierarchy'!H29*(1/4)+'Economic Hierarchy'!H29*(1/4)+'Diplomatic Hiearachy'!H29*(1/4)+'Informational Hierarchy'!H59*(1/4) -> 0.166168 | I29: ='Security Hierarchy'!I29*(1/4)+'Economic Hierarchy'!I29*(1/4)+'Diplomatic Hiearachy'!I29*(1/4)+'Informational Hierarchy'!I59*(1/4) -> 0.42953906 | ... AW29: ='Security Hierarchy'!AW29*(1/4)+'Economic Hierarchy'!AW29*(1/4)+'Diplomatic Hiearachy'!AW29*(1/4)+'Informational Hierarchy'!AW59*(1/4) -> 0.2953018
A31: Russia
B32: Albania | C32: Armenia | D32: Austria | E32: Azerbaijan | F32: Belarus | G32: Belgium | H32: Bosnia-Herzegovina | I32: Bulgaria | J32: Croatia | K32: Cyprus | L32: Czech | M32: Denmark | N32: Estonia | O32: Finland | P32: France | Q32: Georgia | R32: Germany | S32: Greece | T32: Hungary | U32: Iceland | V32: Ireland | W32: Italy | X32: Kazakhstan | Y32: Kyrgyzstan | Z32: latvia | AA32: Lithuania | AB32: Luxembourg | AC32: Macedonia | AD32: Malta | AE32: Moldova | AF32: Montenegro | AG32: Netherlands | AH32: Norway | AI32: Poland | AJ32: Portugal | AK32: Romania | AL32: Serbia | AM32: Slovakia | AN32: Slovenia | AO32: Spain | AP32: Sweden | AQ32: Switzerland | AR32: Tajikistan | AS32: Turkey | AT32: Turkmenistan | AU32: UK | AV32: Ukraine | AW32: Uzbekistan
A33: 1991 | B33: ='Security Hierarchy'!B33*(1/4)+'Economic Hierarchy'!B33*(1/4)+'Diplomatic Hiearachy'!B33*(1/4)+'Informational Hierarchy'!B33*(1/4) -> #DIV/0! | C33: ='Security Hierarchy'!C33*(1/4)+'Economic Hierarchy'!C33*(1/4)+'Diplomatic Hiearachy'!C33*(1/4)+'Informational Hierarchy'!C33*(1/4) -> #DIV/0! | D33: ='Security Hierarchy'!D33*(1/4)+'Economic Hierarchy'!D33*(1/4)+'Diplomatic Hiearachy'!D33*(1/4)+'Informational Hierarchy'!D33*(1/4) -> #DIV/0! | E33: ='Security Hierarchy'!E33*(1/4)+'Economic Hierarchy'!E33*(1/4)+'Diplomatic Hiearachy'!E33*(1/4)+'Informational Hierarchy'!E33*(1/4) -> #DIV/0! | F33: ='Security Hierarchy'!F33*(1/4)+'Economic Hierarchy'!F33*(1/4)+'Diplomatic Hiearachy'!F33*(1/4)+'Informational Hierarchy'!F33*(1/4) -> #DIV/0! | G33: ='Security Hierarchy'!G33*(1/4)+'Economic Hierarchy'!G33*(1/4)+'Diplomatic Hiearachy'!G33*(1/4)+'Informational Hierarchy'!G33*(1/4) -> #DIV/0! | H33: ='Security Hierarchy'!H33*(1/4)+'Economic Hierarchy'!H33*(1/4)+'Diplomatic Hiearachy'!H33*(1/4)+'Informational Hierarchy'!H33*(1/4) -> #DIV/0! | I33: ='Security Hierarchy'!I33*(1/4)+'Economic Hierarchy'!I33*(1/4)+'Diplomatic Hiearachy'!I33*(1/4)+'Informational Hierarchy'!I33*(1/4) -> #DIV/0! | ... AW33: ='Security Hierarchy'!AW33*(1/4)+'Economic Hierarchy'!AW33*(1/4)+'Diplomatic Hiearachy'!AW33*(1/4)+'Informational Hierarchy'!AW33*(1/4) -> #DIV/0!
A34: 1992 | B34: ='Security Hierarchy'!B34*(1/4)+'Economic Hierarchy'!B34*(1/4)+'Diplomatic Hiearachy'!B34*(1/4)+'Informational Hierarchy'!B34*(1/4) -> #DIV/0! | C34: ='Security Hierarchy'!C34*(1/4)+'Economic Hierarchy'!C34*(1/4)+'Diplomatic Hiearachy'!C34*(1/4)+'Informational Hierarchy'!C34*(1/4) -> #DIV/0! | D34: ='Security Hierarchy'!D34*(1/4)+'Economic Hierarchy'!D34*(1/4)+'Diplomatic Hiearachy'!D34*(1/4)+'Informational Hierarchy'!D34*(1/4) -> #DIV/0! | E34: ='Security Hierarchy'!E34*(1/4)+'Economic Hierarchy'!E34*(1/4)+'Diplomatic Hiearachy'!E34*(1/4)+'Informational Hierarchy'!E34*(1/4) -> #DIV/0! | F34: ='Security Hierarchy'!F34*(1/4)+'Economic Hierarchy'!F34*(1/4)+'Diplomatic Hiearachy'!F34*(1/4)+'Informational Hierarchy'!F34*(1/4) -> #DIV/0! | G34: ='Security Hierarchy'!G34*(1/4)+'Economic Hierarchy'!G34*(1/4)+'Diplomatic Hiearachy'!G34*(1/4)+'Informational Hierarchy'!G34*(1/4) -> #DIV/0! | H34: ='Security Hierarchy'!H34*(1/4)+'Economic Hierarchy'!H34*(1/4)+'Diplomatic Hiearachy'!H34*(1/4)+'Informational Hierarchy'!H34*(1/4) -> #DIV/0! | I34: ='Security Hierarchy'!I34*(1/4)+'Economic Hierarchy'!I34*(1/4)+'Diplomatic Hiearachy'!I34*(1/4)+'Informational Hierarchy'!I34*(1/4) -> #DIV/0! | ... AW34: ='Security Hierarchy'!AW34*(1/4)+'Economic Hierarchy'!AW34*(1/4)+'Diplomatic Hiearachy'!AW34*(1/4)+'Informational Hierarchy'!AW34*(1/4) -> #DIV/0!
A35: 1993 | B35: ='Security Hierarchy'!B35*(1/4)+'Economic Hierarchy'!B35*(1/4)+'Diplomatic Hiearachy'!B35*(1/4)+'Informational Hierarchy'!B35*(1/4) -> #DIV/0! | C35: ='Security Hierarchy'!C35*(1/4)+'Economic Hierarchy'!C35*(1/4)+'Diplomatic Hiearachy'!C35*(1/4)+'Informational Hierarchy'!C35*(1/4) -> #DIV/0! | D35: ='Security Hierarchy'!D35*(1/4)+'Economic Hierarchy'!D35*(1/4)+'Diplomatic Hiearachy'!D35*(1/4)+'Informational Hierarchy'!D35*(1/4) -> #DIV/0! | E35: ='Security Hierarchy'!E35*(1/4)+'Economic Hierarchy'!E35*(1/4)+'Diplomatic Hiearachy'!E35*(1/4)+'Informational Hierarchy'!E35*(1/4) -> #DIV/0! | F35: ='Security Hierarchy'!F35*(1/4)+'Economic Hierarchy'!F35*(1/4)+'Diplomatic Hiearachy'!F35*(1/4)+'Informational Hierarchy'!F35*(1/4) -> #DIV/0! | G35: ='Security Hierarchy'!G35*(1/4)+'Economic Hierarchy'!G35*(1/4)+'Diplomatic Hiearachy'!G35*(1/4)+'Informational Hierarchy'!G35*(1/4) -> #DIV/0! | H35: ='Security Hierarchy'!H35*(1/4)+'Economic Hierarchy'!H35*(1/4)+'Diplomatic Hiearachy'!H35*(1/4)+'Informational Hierarchy'!H35*(1/4) -> #DIV/0! | I35: ='Security Hierarchy'!I35*(1/4)+'Economic Hierarchy'!I35*(1/4)+'Diplomatic Hiearachy'!I35*(1/4)+'Informational Hierarchy'!I35*(1/4) -> #DIV/0! | ... AW35: ='Security Hierarchy'!AW35*(1/4)+'Economic Hierarchy'!AW35*(1/4)+'Diplomatic Hiearachy'!AW35*(1/4)+'Informational Hierarchy'!AW35*(1/4) -> #DIV/0!
A36: 1994 | B36: ='Security Hierarchy'!B36*(1/4)+'Economic Hierarchy'!B36*(1/4)+'Diplomatic Hiearachy'!B36*(1/4)+'Informational Hierarchy'!B36*(1/4) -> #DIV/0! | C36: ='Security Hierarchy'!C36*(1/4)+'Economic Hierarchy'!C36*(1/4)+'Diplomatic Hiearachy'!C36*(1/4)+'Informational Hierarchy'!C36*(1/4) -> #DIV/0! | D36: ='Security Hierarchy'!D36*(1/4)+'Economic Hierarchy'!D36*(1/4)+'Diplomatic Hiearachy'!D36*(1/4)+'Informational Hierarchy'!D36*(1/4) -> #DIV/0! | E36: ='Security Hierarchy'!E36*(1/4)+'Economic Hierarchy'!E36*(1/4)+'Diplomatic Hiearachy'!E36*(1/4)+'Informational Hierarchy'!E36*(1/4) -> #DIV/0! | F36: ='Security Hierarchy'!F36*(1/4)+'Economic Hierarchy'!F36*(1/4)+'Diplomatic Hiearachy'!F36*(1/4)+'Informational Hierarchy'!F36*(1/4) -> #DIV/0! | G36: ='Security Hierarchy'!G36*(1/4)+'Economic Hierarchy'!G36*(1/4)+'Diplomatic Hiearachy'!G36*(1/4)+'Informational Hierarchy'!G36*(1/4) -> #DIV/0! | H36: ='Security Hierarchy'!H36*(1/4)+'Economic Hierarchy'!H36*(1/4)+'Diplomatic Hiearachy'!H36*(1/4)+'Informational Hierarchy'!H36*(1/4) -> #DIV/0! | I36: ='Security Hierarchy'!I36*(1/4)+'Economic Hierarchy'!I36*(1/4)+'Diplomatic Hiearachy'!I36*(1/4)+'Informational Hierarchy'!I36*(1/4) -> #DIV/0! | ... AW36: ='Security Hierarchy'!AW36*(1/4)+'Economic Hierarchy'!AW36*(1/4)+'Diplomatic Hiearachy'!AW36*(1/4)+'Informational Hierarchy'!AW36*(1/4) -> #DIV/0!
A37: 1995 | B37: ='Security Hierarchy'!B37*(1/4)+'Economic Hierarchy'!B37*(1/4)+'Diplomatic Hiearachy'!B37*(1/4)+'Informational Hierarchy'!B37*(1/4) -> #DIV/0! | C37: ='Security Hierarchy'!C37*(1/4)+'Economic Hierarchy'!C37*(1/4)+'Diplomatic Hiearachy'!C37*(1/4)+'Informational Hierarchy'!C37*(1/4) -> #DIV/0! | D37: ='Security Hierarchy'!D37*(1/4)+'Economic Hierarchy'!D37*(1/4)+'Diplomatic Hiearachy'!D37*(1/4)+'Informational Hierarchy'!D37*(1/4) -> #DIV/0! | E37: ='Security Hierarchy'!E37*(1/4)+'Economic Hierarchy'!E37*(1/4)+'Diplomatic Hiearachy'!E37*(1/4)+'Informational Hierarchy'!E37*(1/4) -> #DIV/0! | F37: ='Security Hierarchy'!F37*(1/4)+'Economic Hierarchy'!F37*(1/4)+'Diplomatic Hiearachy'!F37*(1/4)+'Informational Hierarchy'!F37*(1/4) -> #DIV/0! | G37: ='Security Hierarchy'!G37*(1/4)+'Economic Hierarchy'!G37*(1/4)+'Diplomatic Hiearachy'!G37*(1/4)+'Informational Hierarchy'!G37*(1/4) -> #DIV/0! | H37: ='Security Hierarchy'!H37*(1/4)+'Economic Hierarchy'!H37*(1/4)+'Diplomatic Hiearachy'!H37*(1/4)+'Informational Hierarchy'!H37*(1/4) -> #DIV/0! | I37: ='Security Hierarchy'!I37*(1/4)+'Economic Hierarchy'!I37*(1/4)+'Diplomatic Hiearachy'!I37*(1/4)+'Informational Hierarchy'!I37*(1/4) -> #DIV/0! | ... AW37: ='Security Hierarchy'!AW37*(1/4)+'Economic Hierarchy'!AW37*(1/4)+'Diplomatic Hiearachy'!AW37*(1/4)+'Informational Hierarchy'!AW37*(1/4) -> #DIV/0!
A38: 1996 | B38: ='Security Hierarchy'!B38*(1/4)+'Economic Hierarchy'!B38*(1/4)+'Diplomatic Hiearachy'!B38*(1/4)+'Informational Hierarchy'!B38*(1/4) -> #DIV/0! | C38: ='Security Hierarchy'!C38*(1/4)+'Economic Hierarchy'!C38*(1/4)+'Diplomatic Hiearachy'!C38*(1/4)+'Informational Hierarchy'!C38*(1/4) -> #DIV/0! | D38: ='Security Hierarchy'!D38*(1/4)+'Economic Hierarchy'!D38*(1/4)+'Diplomatic Hiearachy'!D38*(1/4)+'Informational Hierarchy'!D38*(1/4) -> #DIV/0! | E38: ='Security Hierarchy'!E38*(1/4)+'Economic Hierarchy'!E38*(1/4)+'Diplomatic Hiearachy'!E38*(1/4)+'Informational Hierarchy'!E38*(1/4) -> #DIV/0! | F38: ='Security Hierarchy'!F38*(1/4)+'Economic Hierarchy'!F38*(1/4)+'Diplomatic Hiearachy'!F38*(1/4)+'Informational Hierarchy'!F38*(1/4) -> #DIV/0! | G38: ='Security Hierarchy'!G38*(1/4)+'Economic Hierarchy'!G38*(1/4)+'Diplomatic Hiearachy'!G38*(1/4)+'Informational Hierarchy'!G38*(1/4) -> #DIV/0! | H38: ='Security Hierarchy'!H38*(1/4)+'Economic Hierarchy'!H38*(1/4)+'Diplomatic Hiearachy'!H38*(1/4)+'Informational Hierarchy'!H38*(1/4) -> #DIV/0! | I38: ='Security Hierarchy'!I38*(1/4)+'Economic Hierarchy'!I38*(1/4)+'Diplomatic Hiearachy'!I38*(1/4)+'Informational Hierarchy'!I38*(1/4) -> #DIV/0! | ... AW38: ='Security Hierarchy'!AW38*(1/4)+'Economic Hierarchy'!AW38*(1/4)+'Diplomatic Hiearachy'!AW38*(1/4)+'Informational Hierarchy'!AW38*(1/4) -> #DIV/0!
A39: 1997 | B39: ='Security Hierarchy'!B39*(1/4)+'Economic Hierarchy'!B39*(1/4)+'Diplomatic Hiearachy'!B39*(1/4)+'Informational Hierarchy'!B39*(1/4) -> #DIV/0! | C39: ='Security Hierarchy'!C39*(1/4)+'Economic Hierarchy'!C39*(1/4)+'Diplomatic Hiearachy'!C39*(1/4)+'Informational Hierarchy'!C39*(1/4) -> #DIV/0! | D39: ='Security Hierarchy'!D39*(1/4)+'Economic Hierarchy'!D39*(1/4)+'Diplomatic Hiearachy'!D39*(1/4)+'Informational Hierarchy'!D39*(1/4) -> #DIV/0! | E39: ='Security Hierarchy'!E39*(1/4)+'Economic Hierarchy'!E39*(1/4)+'Diplomatic Hiearachy'!E39*(1/4)+'Informational Hierarchy'!E39*(1/4) -> #DIV/0! | F39: ='Security Hierarchy'!F39*(1/4)+'Economic Hierarchy'!F39*(1/4)+'Diplomatic Hiearachy'!F39*(1/4)+'Informational Hierarchy'!F39*(1/4) -> #DIV/0! | G39: ='Security Hierarchy'!G39*(1/4)+'Economic Hierarchy'!G39*(1/4)+'Diplomatic Hiearachy'!G39*(1/4)+'Informational Hierarchy'!G39*(1/4) -> #DIV/0! | H39: ='Security Hierarchy'!H39*(1/4)+'Economic Hierarchy'!H39*(1/4)+'Diplomatic Hiearachy'!H39*(1/4)+'Informational Hierarchy'!H39*(1/4) -> #DIV/0! | I39: ='Security Hierarchy'!I39*(1/4)+'Economic Hierarchy'!I39*(1/4)+'Diplomatic Hiearachy'!I39*(1/4)+'Informational Hierarchy'!I39*(1/4) -> #DIV/0! | ... AW39: ='Security Hierarchy'!AW39*(1/4)+'Economic Hierarchy'!AW39*(1/4)+'Diplomatic Hiearachy'!AW39*(1/4)+'Informational Hierarchy'!AW39*(1/4) -> #DIV/0!
A40: 1998 | B40: ='Security Hierarchy'!B40*(1/4)+'Economic Hierarchy'!B40*(1/4)+'Diplomatic Hiearachy'!B40*(1/4)+'Informational Hierarchy'!B40*(1/4) -> #DIV/0! | C40: ='Security Hierarchy'!C40*(1/4)+'Economic Hierarchy'!C40*(1/4)+'Diplomatic Hiearachy'!C40*(1/4)+'Informational Hierarchy'!C40*(1/4) -> #DIV/0! | D40: ='Security Hierarchy'!D40*(1/4)+'Economic Hierarchy'!D40*(1/4)+'Diplomatic Hiearachy'!D40*(1/4)+'Informational Hierarchy'!D40*(1/4) -> #DIV/0! | E40: ='Security Hierarchy'!E40*(1/4)+'Economic Hierarchy'!E40*(1/4)+'Diplomatic Hiearachy'!E40*(1/4)+'Informational Hierarchy'!E40*(1/4) -> #DIV/0! | F40: ='Security Hierarchy'!F40*(1/4)+'Economic Hierarchy'!F40*(1/4)+'Diplomatic Hiearachy'!F40*(1/4)+'Informational Hierarchy'!F40*(1/4) -> #DIV/0! | G40: ='Security Hierarchy'!G40*(1/4)+'Economic Hierarchy'!G40*(1/4)+'Diplomatic Hiearachy'!G40*(1/4)+'Informational Hierarchy'!G40*(1/4) -> #DIV/0! | H40: ='Security Hierarchy'!H40*(1/4)+'Economic Hierarchy'!H40*(1/4)+'Diplomatic Hiearachy'!H40*(1/4)+'Informational Hierarchy'!H40*(1/4) -> #DIV/0! | I40: ='Security Hierarchy'!I40*(1/4)+'Economic Hierarchy'!I40*(1/4)+'Diplomatic Hiearachy'!I40*(1/4)+'Informational Hierarchy'!I40*(1/4) -> #DIV/0! | ... AW40: ='Security Hierarchy'!AW40*(1/4)+'Economic Hierarchy'!AW40*(1/4)+'Diplomatic Hiearachy'!AW40*(1/4)+'Informational Hierarchy'!AW40*(1/4) -> #DIV/0!
A41: 1999 | B41: ='Security Hierarchy'!B41*(1/4)+'Economic Hierarchy'!B41*(1/4)+'Diplomatic Hiearachy'!B41*(1/4)+'Informational Hierarchy'!B41*(1/4) -> #DIV/0! | C41: ='Security Hierarchy'!C41*(1/4)+'Economic Hierarchy'!C41*(1/4)+'Diplomatic Hiearachy'!C41*(1/4)+'Informational Hierarchy'!C41*(1/4) -> #DIV/0! | D41: ='Security Hierarchy'!D41*(1/4)+'Economic Hierarchy'!D41*(1/4)+'Diplomatic Hiearachy'!D41*(1/4)+'Informational Hierarchy'!D41*(1/4) -> #DIV/0! | E41: ='Security Hierarchy'!E41*(1/4)+'Economic Hierarchy'!E41*(1/4)+'Diplomatic Hiearachy'!E41*(1/4)+'Informational Hierarchy'!E41*(1/4) -> #DIV/0! | F41: ='Security Hierarchy'!F41*(1/4)+'Economic Hierarchy'!F41*(1/4)+'Diplomatic Hiearachy'!F41*(1/4)+'Informational Hierarchy'!F41*(1/4) -> #DIV/0! | G41: ='Security Hierarchy'!G41*(1/4)+'Economic Hierarchy'!G41*(1/4)+'Diplomatic Hiearachy'!G41*(1/4)+'Informational Hierarchy'!G41*(1/4) -> #DIV/0! | H41: ='Security Hierarchy'!H41*(1/4)+'Economic Hierarchy'!H41*(1/4)+'Diplomatic Hiearachy'!H41*(1/4)+'Informational Hierarchy'!H41*(1/4) -> #DIV/0! | I41: ='Security Hierarchy'!I41*(1/4)+'Economic Hierarchy'!I41*(1/4)+'Diplomatic Hiearachy'!I41*(1/4)+'Informational Hierarchy'!I41*(1/4) -> #DIV/0! | ... AW41: ='Security Hierarchy'!AW41*(1/4)+'Economic Hierarchy'!AW41*(1/4)+'Diplomatic Hiearachy'!AW41*(1/4)+'Informational Hierarchy'!AW41*(1/4) -> #DIV/0!
A42: 2000 | B42: ='Security Hierarchy'!B42*(1/4)+'Economic Hierarchy'!B42*(1/4)+'Diplomatic Hiearachy'!B42*(1/4)+'Informational Hierarchy'!B42*(1/4) -> 0.15640841 | C42: ='Security Hierarchy'!C42*(1/4)+'Economic Hierarchy'!C42*(1/4)+'Diplomatic Hiearachy'!C42*(1/4)+'Informational Hierarchy'!C42*(1/4) -> 0.51061417 | D42: ='Security Hierarchy'!D42*(1/4)+'Economic Hierarchy'!D42*(1/4)+'Diplomatic Hiearachy'!D42*(1/4)+'Informational Hierarchy'!D42*(1/4) -> 0.14475101 | E42: ='Security Hierarchy'!E42*(1/4)+'Economic Hierarchy'!E42*(1/4)+'Diplomatic Hiearachy'!E42*(1/4)+'Informational Hierarchy'!E42*(1/4) -> 0.47167 | F42: ='Security Hierarchy'!F42*(1/4)+'Economic Hierarchy'!F42*(1/4)+'Diplomatic Hiearachy'!F42*(1/4)+'Informational Hierarchy'!F42*(1/4) -> 0.60787639 | G42: ='Security Hierarchy'!G42*(1/4)+'Economic Hierarchy'!G42*(1/4)+'Diplomatic Hiearachy'!G42*(1/4)+'Informational Hierarchy'!G42*(1/4) -> 0.19430833 | H42: ='Security Hierarchy'!H42*(1/4)+'Economic Hierarchy'!H42*(1/4)+'Diplomatic Hiearachy'!H42*(1/4)+'Informational Hierarchy'!H42*(1/4) -> 0.16081262 | I42: ='Security Hierarchy'!I42*(1/4)+'Economic Hierarchy'!I42*(1/4)+'Diplomatic Hiearachy'!I42*(1/4)+'Informational Hierarchy'!I42*(1/4) -> 0.18409591 | ... AW42: ='Security Hierarchy'!AW42*(1/4)+'Economic Hierarchy'!AW42*(1/4)+'Diplomatic Hiearachy'!AW42*(1/4)+'Informational Hierarchy'!AW42*(1/4) -> 0.4045728
A43: 2001 | B43: ='Security Hierarchy'!B43*(1/4)+'Economic Hierarchy'!B43*(1/4)+'Diplomatic Hiearachy'!B43*(1/4)+'Informational Hierarchy'!B43*(1/4) -> 0.15715963 | C43: ='Security Hierarchy'!C43*(1/4)+'Economic Hierarchy'!C43*(1/4)+'Diplomatic Hiearachy'!C43*(1/4)+'Informational Hierarchy'!C43*(1/4) -> 0.50725413 | D43: ='Security Hierarchy'!D43*(1/4)+'Economic Hierarchy'!D43*(1/4)+'Diplomatic Hiearachy'!D43*(1/4)+'Informational Hierarchy'!D43*(1/4) -> 0.20851552 | E43: ='Security Hierarchy'!E43*(1/4)+'Economic Hierarchy'!E43*(1/4)+'Diplomatic Hiearachy'!E43*(1/4)+'Informational Hierarchy'!E43*(1/4) -> 0.46231275 | F43: ='Security Hierarchy'!F43*(1/4)+'Economic Hierarchy'!F43*(1/4)+'Diplomatic Hiearachy'!F43*(1/4)+'Informational Hierarchy'!F43*(1/4) -> 0.61589733 | G43: ='Security Hierarchy'!G43*(1/4)+'Economic Hierarchy'!G43*(1/4)+'Diplomatic Hiearachy'!G43*(1/4)+'Informational Hierarchy'!G43*(1/4) -> 0.19567702 | H43: ='Security Hierarchy'!H43*(1/4)+'Economic Hierarchy'!H43*(1/4)+'Diplomatic Hiearachy'!H43*(1/4)+'Informational Hierarchy'!H43*(1/4) -> 0.14927172 | I43: ='Security Hierarchy'!I43*(1/4)+'Economic Hierarchy'!I43*(1/4)+'Diplomatic Hiearachy'!I43*(1/4)+'Informational Hierarchy'!I43*(1/4) -> 0.17540567 | ... AW43: ='Security Hierarchy'!AW43*(1/4)+'Economic Hierarchy'!AW43*(1/4)+'Diplomatic Hiearachy'!AW43*(1/4)+'Informational Hierarchy'!AW43*(1/4) -> 0.52784667
A44: 2002 | B44: ='Security Hierarchy'!B44*(1/4)+'Economic Hierarchy'!B44*(1/4)+'Diplomatic Hiearachy'!B44*(1/4)+'Informational Hierarchy'!B44*(1/4) -> 0.16651131 | C44: ='Security Hierarchy'!C44*(1/4)+'Economic Hierarchy'!C44*(1/4)+'Diplomatic Hiearachy'!C44*(1/4)+'Informational Hierarchy'!C44*(1/4) -> 0.49804417 | D44: ='Security Hierarchy'!D44*(1/4)+'Economic Hierarchy'!D44*(1/4)+'Diplomatic Hiearachy'!D44*(1/4)+'Informational Hierarchy'!D44*(1/4) -> 0.16785761 | E44: ='Security Hierarchy'!E44*(1/4)+'Economic Hierarchy'!E44*(1/4)+'Diplomatic Hiearachy'!E44*(1/4)+'Informational Hierarchy'!E44*(1/4) -> 0.50363102 | F44: ='Security Hierarchy'!F44*(1/4)+'Economic Hierarchy'!F44*(1/4)+'Diplomatic Hiearachy'!F44*(1/4)+'Informational Hierarchy'!F44*(1/4) -> 0.67480136 | G44: ='Security Hierarchy'!G44*(1/4)+'Economic Hierarchy'!G44*(1/4)+'Diplomatic Hiearachy'!G44*(1/4)+'Informational Hierarchy'!G44*(1/4) -> 0.21680269 | H44: ='Security Hierarchy'!H44*(1/4)+'Economic Hierarchy'!H44*(1/4)+'Diplomatic Hiearachy'!H44*(1/4)+'Informational Hierarchy'!H44*(1/4) -> 0.1883373 | I44: ='Security Hierarchy'!I44*(1/4)+'Economic Hierarchy'!I44*(1/4)+'Diplomatic Hiearachy'!I44*(1/4)+'Informational Hierarchy'!I44*(1/4) -> 0.26115023 | ... AW44: ='Security Hierarchy'!AW44*(1/4)+'Economic Hierarchy'!AW44*(1/4)+'Diplomatic Hiearachy'!AW44*(1/4)+'Informational Hierarchy'!AW44*(1/4) -> 0.44665567
... A59: 2017 | B59: ='Security Hierarchy'!B59*(1/4)+'Economic Hierarchy'!B59*(1/4)+'Diplomatic Hiearachy'!B59*(1/4)+'Informational Hierarchy'!B59*(1/4) -> 0.18939755 | C59: ='Security Hierarchy'!C59*(1/4)+'Economic Hierarchy'!C59*(1/4)+'Diplomatic Hiearachy'!C59*(1/4)+'Informational Hierarchy'!C59*(1/4) -> 0.64652822 | D59: ='Security Hierarchy'!D59*(1/4)+'Economic Hierarchy'!D59*(1/4)+'Diplomatic Hiearachy'!D59*(1/4)+'Informational Hierarchy'!D59*(1/4) -> 0.12775072 | E59: ='Security Hierarchy'!E59*(1/4)+'Economic Hierarchy'!E59*(1/4)+'Diplomatic Hiearachy'!E59*(1/4)+'Informational Hierarchy'!E59*(1/4) -> 0.47909017 | F59: ='Security Hierarchy'!F59*(1/4)+'Economic Hierarchy'!F59*(1/4)+'Diplomatic Hiearachy'!F59*(1/4)+'Informational Hierarchy'!F59*(1/4) -> 0.7602486 | G59: ='Security Hierarchy'!G59*(1/4)+'Economic Hierarchy'!G59*(1/4)+'Diplomatic Hiearachy'!G59*(1/4)+'Informational Hierarchy'!G59*(1/4) -> 0.12535807 | H59: ='Security Hierarchy'!H59*(1/4)+'Economic Hierarchy'!H59*(1/4)+'Diplomatic Hiearachy'!H59*(1/4)+'Informational Hierarchy'!H59*(1/4) -> 0.18576395 | I59: ='Security Hierarchy'!I59*(1/4)+'Economic Hierarchy'!I59*(1/4)+'Diplomatic Hiearachy'!I59*(1/4)+'Informational Hierarchy'!I59*(1/4) -> 0.22149156 | ... AW59: ='Security Hierarchy'!AW59*(1/4)+'Economic Hierarchy'!AW59*(1/4)+'Diplomatic Hiearachy'!AW59*(1/4)+'Informational Hierarchy'!AW59*(1/4) -> 0.43111657
A61: China
B62: Albania | C62: Armenia | D62: Austria | E62: Azerbaijan | F62: Belarus | G62: Belgium | H62: Bosnia-Herzegovina | I62: Bulgaria | J62: Croatia | K62: Cyprus | L62: Czech | M62: Denmark | N62: Estonia | O62: Finland | P62: France | Q62: Georgia | R62: Germany | S62: Greece | T62: Hungary | U62: Iceland | V62: Ireland | W62: Italy | X62: Kazakhstan | Y62: Kyrgyzstan | Z62: latvia | AA62: Lithuania | AB62: Luxembourg | AC62: Macedonia | AD62: Malta | AE62: Moldova | AF62: Montenegro | AG62: Netherlands | AH62: Norway | AI62: Poland | AJ62: Portugal | AK62: Romania | AL62: Serbia | AM62: Slovakia | AN62: Slovenia | AO62: Spain | AP62: Sweden | AQ62: Switzerland | AR62: Tajikistan | AS62: Turkey | AT62: Turkmenistan | AU62: UK | AV62: Ukraine | AW62: Uzbekistan
A63: 1991 | B63: ='Security Hierarchy'!B63*(1/4)+'Economic Hierarchy'!B63*(1/4)+'Diplomatic Hiearachy'!B63*(1/4)+'Informational Hierarchy'!B63*(1/4) -> #DIV/0! | C63: ='Security Hierarchy'!C63*(1/4)+'Economic Hierarchy'!C63*(1/4)+'Diplomatic Hiearachy'!C63*(1/4)+'Informational Hierarchy'!C63*(1/4) -> #DIV/0! | D63: ='Security Hierarchy'!D63*(1/4)+'Economic Hierarchy'!D63*(1/4)+'Diplomatic Hiearachy'!D63*(1/4)+'Informational Hierarchy'!D63*(1/4) -> #DIV/0! | E63: ='Security Hierarchy'!E63*(1/4)+'Economic Hierarchy'!E63*(1/4)+'Diplomatic Hiearachy'!E63*(1/4)+'Informational Hierarchy'!E63*(1/4) -> #DIV/0! | F63: ='Security Hierarchy'!F63*(1/4)+'Economic Hierarchy'!F63*(1/4)+'Diplomatic Hiearachy'!F63*(1/4)+'Informational Hierarchy'!F63*(1/4) -> #DIV/0! | G63: ='Security Hierarchy'!G63*(1/4)+'Economic Hierarchy'!G63*(1/4)+'Diplomatic Hiearachy'!G63*(1/4)+'Informational Hierarchy'!G63*(1/4) -> #DIV/0! | H63: ='Security Hierarchy'!H63*(1/4)+'Economic Hierarchy'!H63*(1/4)+'Diplomatic Hiearachy'!H63*(1/4)+'Informational Hierarchy'!H63*(1/4) -> #DIV/0! | I63: ='Security Hierarchy'!I63*(1/4)+'Economic Hierarchy'!I63*(1/4)+'Diplomatic Hiearachy'!I63*(1/4)+'Informational Hierarchy'!I63*(1/4) -> #DIV/0! | ... AW63: ='Security Hierarchy'!AW63*(1/4)+'Economic Hierarchy'!AW63*(1/4)+'Diplomatic Hiearachy'!AW63*(1/4)+'Informational Hierarchy'!AW63*(1/4) -> #DIV/0!
A64: 1992 | B64: ='Security Hierarchy'!B64*(1/4)+'Economic Hierarchy'!B64*(1/4)+'Diplomatic Hiearachy'!B64*(1/4)+'Informational Hierarchy'!B64*(1/4) -> #DIV/0! | C64: ='Security Hierarchy'!C64*(1/4)+'Economic Hierarchy'!C64*(1/4)+'Diplomatic Hiearachy'!C64*(1/4)+'Informational Hierarchy'!C64*(1/4) -> #DIV/0! | D64: ='Security Hierarchy'!D64*(1/4)+'Economic Hierarchy'!D64*(1/4)+'Diplomatic Hiearachy'!D64*(1/4)+'Informational Hierarchy'!D64*(1/4) -> #DIV/0! | E64: ='Security Hierarchy'!E64*(1/4)+'Economic Hierarchy'!E64*(1/4)+'Diplomatic Hiearachy'!E64*(1/4)+'Informational Hierarchy'!E64*(1/4) -> #DIV/0! | F64: ='Security Hierarchy'!F64*(1/4)+'Economic Hierarchy'!F64*(1/4)+'Diplomatic Hiearachy'!F64*(1/4)+'Informational Hierarchy'!F64*(1/4) -> #DIV/0! | G64: ='Security Hierarchy'!G64*(1/4)+'Economic Hierarchy'!G64*(1/4)+'Diplomatic Hiearachy'!G64*(1/4)+'Informational Hierarchy'!G64*(1/4) -> #DIV/0! | H64: ='Security Hierarchy'!H64*(1/4)+'Economic Hierarchy'!H64*(1/4)+'Diplomatic Hiearachy'!H64*(1/4)+'Informational Hierarchy'!H64*(1/4) -> #DIV/0! | I64: ='Security Hierarchy'!I64*(1/4)+'Economic Hierarchy'!I64*(1/4)+'Diplomatic Hiearachy'!I64*(1/4)+'Informational Hierarchy'!I64*(1/4) -> #DIV/0! | ... AW64: ='Security Hierarchy'!AW64*(1/4)+'Economic Hierarchy'!AW64*(1/4)+'Diplomatic Hiearachy'!AW64*(1/4)+'Informational Hierarchy'!AW64*(1/4) -> #DIV/0!
A65: 1993 | B65: ='Security Hierarchy'!B65*(1/4)+'Economic Hierarchy'!B65*(1/4)+'Diplomatic Hiearachy'!B65*(1/4)+'Informational Hierarchy'!B65*(1/4) -> #DIV/0! | C65: ='Security Hierarchy'!C65*(1/4)+'Economic Hierarchy'!C65*(1/4)+'Diplomatic Hiearachy'!C65*(1/4)+'Informational Hierarchy'!C65*(1/4) -> #DIV/0! | D65: ='Security Hierarchy'!D65*(1/4)+'Economic Hierarchy'!D65*(1/4)+'Diplomatic Hiearachy'!D65*(1/4)+'Informational Hierarchy'!D65*(1/4) -> #DIV/0! | E65: ='Security Hierarchy'!E65*(1/4)+'Economic Hierarchy'!E65*(1/4)+'Diplomatic Hiearachy'!E65*(1/4)+'Informational Hierarchy'!E65*(1/4) -> #DIV/0! | F65: ='Security Hierarchy'!F65*(1/4)+'Economic Hierarchy'!F65*(1/4)+'Diplomatic Hiearachy'!F65*(1/4)+'Informational Hierarchy'!F65*(1/4) -> #DIV/0! | G65: ='Security Hierarchy'!G65*(1/4)+'Economic Hierarchy'!G65*(1/4)+'Diplomatic Hiearachy'!G65*(1/4)+'Informational Hierarchy'!G65*(1/4) -> #DIV/0! | H65: ='Security Hierarchy'!H65*(1/4)+'Economic Hierarchy'!H65*(1/4)+'Diplomatic Hiearachy'!H65*(1/4)+'Informational Hierarchy'!H65*(1/4) -> #DIV/0! | I65: ='Security Hierarchy'!I65*(1/4)+'Economic Hierarchy'!I65*(1/4)+'Diplomatic Hiearachy'!I65*(1/4)+'Informational Hierarchy'!I65*(1/4) -> #DIV/0! | ... AW65: ='Security Hierarchy'!AW65*(1/4)+'Economic Hierarchy'!AW65*(1/4)+'Diplomatic Hiearachy'!AW65*(1/4)+'Informational Hierarchy'!AW65*(1/4) -> #DIV/0!
A66: 1994 | B66: ='Security Hierarchy'!B66*(1/4)+'Economic Hierarchy'!B66*(1/4)+'Diplomatic Hiearachy'!B66*(1/4)+'Informational Hierarchy'!B66*(1/4) -> #DIV/0! | C66: ='Security Hierarchy'!C66*(1/4)+'Economic Hierarchy'!C66*(1/4)+'Diplomatic Hiearachy'!C66*(1/4)+'Informational Hierarchy'!C66*(1/4) -> #DIV/0! | D66: ='Security Hierarchy'!D66*(1/4)+'Economic Hierarchy'!D66*(1/4)+'Diplomatic Hiearachy'!D66*(1/4)+'Informational Hierarchy'!D66*(1/4) -> #DIV/0! | E66: ='Security Hierarchy'!E66*(1/4)+'Economic Hierarchy'!E66*(1/4)+'Diplomatic Hiearachy'!E66*(1/4)+'Informational Hierarchy'!E66*(1/4) -> #DIV/0! | F66: ='Security Hierarchy'!F66*(1/4)+'Economic Hierarchy'!F66*(1/4)+'Diplomatic Hiearachy'!F66*(1/4)+'Informational Hierarchy'!F66*(1/4) -> #DIV/0! | G66: ='Security Hierarchy'!G66*(1/4)+'Economic Hierarchy'!G66*(1/4)+'Diplomatic Hiearachy'!G66*(1/4)+'Informational Hierarchy'!G66*(1/4) -> #DIV/0! | H66: ='Security Hierarchy'!H66*(1/4)+'Economic Hierarchy'!H66*(1/4)+'Diplomatic Hiearachy'!H66*(1/4)+'Informational Hierarchy'!H66*(1/4) -> #DIV/0! | I66: ='Security Hierarchy'!I66*(1/4)+'Economic Hierarchy'!I66*(1/4)+'Diplomatic Hiearachy'!I66*(1/4)+'Informational Hierarchy'!I66*(1/4) -> #DIV/0! | ... AW66: ='Security Hierarchy'!AW66*(1/4)+'Economic Hierarchy'!AW66*(1/4)+'Diplomatic Hiearachy'!AW66*(1/4)+'Informational Hierarchy'!AW66*(1/4) -> #DIV/0!
A67: 1995 | B67: ='Security Hierarchy'!B67*(1/4)+'Economic Hierarchy'!B67*(1/4)+'Diplomatic Hiearachy'!B67*(1/4)+'Informational Hierarchy'!B67*(1/4) -> #DIV/0! | C67: ='Security Hierarchy'!C67*(1/4)+'Economic Hierarchy'!C67*(1/4)+'Diplomatic Hiearachy'!C67*(1/4)+'Informational Hierarchy'!C67*(1/4) -> #DIV/0! | D67: ='Security Hierarchy'!D67*(1/4)+'Economic Hierarchy'!D67*(1/4)+'Diplomatic Hiearachy'!D67*(1/4)+'Informational Hierarchy'!D67*(1/4) -> #DIV/0! | E67: ='Security Hierarchy'!E67*(1/4)+'Economic Hierarchy'!E67*(1/4)+'Diplomatic Hiearachy'!E67*(1/4)+'Informational Hierarchy'!E67*(1/4) -> #DIV/0! | F67: ='Security Hierarchy'!F67*(1/4)+'Economic Hierarchy'!F67*(1/4)+'Diplomatic Hiearachy'!F67*(1/4)+'Informational Hierarchy'!F67*(1/4) -> #DIV/0! | G67: ='Security Hierarchy'!G67*(1/4)+'Economic Hierarchy'!G67*(1/4)+'Diplomatic Hiearachy'!G67*(1/4)+'Informational Hierarchy'!G67*(1/4) -> #DIV/0! | H67: ='Security Hierarchy'!H67*(1/4)+'Economic Hierarchy'!H67*(1/4)+'Diplomatic Hiearachy'!H67*(1/4)+'Informational Hierarchy'!H67*(1/4) -> #DIV/0! | I67: ='Security Hierarchy'!I67*(1/4)+'Economic Hierarchy'!I67*(1/4)+'Diplomatic Hiearachy'!I67*(1/4)+'Informational Hierarchy'!I67*(1/4) -> #DIV/0! | ... AW67: ='Security Hierarchy'!AW67*(1/4)+'Economic Hierarchy'!AW67*(1/4)+'Diplomatic Hiearachy'!AW67*(1/4)+'Informational Hierarchy'!AW67*(1/4) -> #DIV/0!
A68: 1996 | B68: ='Security Hierarchy'!B68*(1/4)+'Economic Hierarchy'!B68*(1/4)+'Diplomatic Hiearachy'!B68*(1/4)+'Informational Hierarchy'!B68*(1/4) -> #DIV/0! | C68: ='Security Hierarchy'!C68*(1/4)+'Economic Hierarchy'!C68*(1/4)+'Diplomatic Hiearachy'!C68*(1/4)+'Informational Hierarchy'!C68*(1/4) -> #DIV/0! | D68: ='Security Hierarchy'!D68*(1/4)+'Economic Hierarchy'!D68*(1/4)+'Diplomatic Hiearachy'!D68*(1/4)+'Informational Hierarchy'!D68*(1/4) -> #DIV/0! | E68: ='Security Hierarchy'!E68*(1/4)+'Economic Hierarchy'!E68*(1/4)+'Diplomatic Hiearachy'!E68*(1/4)+'Informational Hierarchy'!E68*(1/4) -> #DIV/0! | F68: ='Security Hierarchy'!F68*(1/4)+'Economic Hierarchy'!F68*(1/4)+'Diplomatic Hiearachy'!F68*(1/4)+'Informational Hierarchy'!F68*(1/4) -> #DIV/0! | G68: ='Security Hierarchy'!G68*(1/4)+'Economic Hierarchy'!G68*(1/4)+'Diplomatic Hiearachy'!G68*(1/4)+'Informational Hierarchy'!G68*(1/4) -> #DIV/0! | H68: ='Security Hierarchy'!H68*(1/4)+'Economic Hierarchy'!H68*(1/4)+'Diplomatic Hiearachy'!H68*(1/4)+'Informational Hierarchy'!H68*(1/4) -> #DIV/0! | I68: ='Security Hierarchy'!I68*(1/4)+'Economic Hierarchy'!I68*(1/4)+'Diplomatic Hiearachy'!I68*(1/4)+'Informational Hierarchy'!I68*(1/4) -> #DIV/0! | ... AW68: ='Security Hierarchy'!AW68*(1/4)+'Economic Hierarchy'!AW68*(1/4)+'Diplomatic Hiearachy'!AW68*(1/4)+'Informational Hierarchy'!AW68*(1/4) -> #DIV/0!
A69: 1997 | B69: ='Security Hierarchy'!B69*(1/4)+'Economic Hierarchy'!B69*(1/4)+'Diplomatic Hiearachy'!B69*(1/4)+'Informational Hierarchy'!B69*(1/4) -> #DIV/0! | C69: ='Security Hierarchy'!C69*(1/4)+'Economic Hierarchy'!C69*(1/4)+'Diplomatic Hiearachy'!C69*(1/4)+'Informational Hierarchy'!C69*(1/4) -> #DIV/0! | D69: ='Security Hierarchy'!D69*(1/4)+'Economic Hierarchy'!D69*(1/4)+'Diplomatic Hiearachy'!D69*(1/4)+'Informational Hierarchy'!D69*(1/4) -> #DIV/0! | E69: ='Security Hierarchy'!E69*(1/4)+'Economic Hierarchy'!E69*(1/4)+'Diplomatic Hiearachy'!E69*(1/4)+'Informational Hierarchy'!E69*(1/4) -> #DIV/0! | F69: ='Security Hierarchy'!F69*(1/4)+'Economic Hierarchy'!F69*(1/4)+'Diplomatic Hiearachy'!F69*(1/4)+'Informational Hierarchy'!F69*(1/4) -> #DIV/0! | G69: ='Security Hierarchy'!G69*(1/4)+'Economic Hierarchy'!G69*(1/4)+'Diplomatic Hiearachy'!G69*(1/4)+'Informational Hierarchy'!G69*(1/4) -> #DIV/0! | H69: ='Security Hierarchy'!H69*(1/4)+'Economic Hierarchy'!H69*(1/4)+'Diplomatic Hiearachy'!H69*(1/4)+'Informational Hierarchy'!H69*(1/4) -> #DIV/0! | I69: ='Security Hierarchy'!I69*(1/4)+'Economic Hierarchy'!I69*(1/4)+'Diplomatic Hiearachy'!I69*(1/4)+'Informational Hierarchy'!I69*(1/4) -> #DIV/0! | ... AW69: ='Security Hierarchy'!AW69*(1/4)+'Economic Hierarchy'!AW69*(1/4)+'Diplomatic Hiearachy'!AW69*(1/4)+'Informational Hierarchy'!AW69*(1/4) -> #DIV/0!
A70: 1998 | B70: ='Security Hierarchy'!B70*(1/4)+'Economic Hierarchy'!B70*(1/4)+'Diplomatic Hiearachy'!B70*(1/4)+'Informational Hierarchy'!B70*(1/4) -> #DIV/0! | C70: ='Security Hierarchy'!C70*(1/4)+'Economic Hierarchy'!C70*(1/4)+'Diplomatic Hiearachy'!C70*(1/4)+'Informational Hierarchy'!C70*(1/4) -> #DIV/0! | D70: ='Security Hierarchy'!D70*(1/4)+'Economic Hierarchy'!D70*(1/4)+'Diplomatic Hiearachy'!D70*(1/4)+'Informational Hierarchy'!D70*(1/4) -> #DIV/0! | E70: ='Security Hierarchy'!E70*(1/4)+'Economic Hierarchy'!E70*(1/4)+'Diplomatic Hiearachy'!E70*(1/4)+'Informational Hierarchy'!E70*(1/4) -> #DIV/0! | F70: ='Security Hierarchy'!F70*(1/4)+'Economic Hierarchy'!F70*(1/4)+'Diplomatic Hiearachy'!F70*(1/4)+'Informational Hierarchy'!F70*(1/4) -> #DIV/0! | G70: ='Security Hierarchy'!G70*(1/4)+'Economic Hierarchy'!G70*(1/4)+'Diplomatic Hiearachy'!G70*(1/4)+'Informational Hierarchy'!G70*(1/4) -> #DIV/0! | H70: ='Security Hierarchy'!H70*(1/4)+'Economic Hierarchy'!H70*(1/4)+'Diplomatic Hiearachy'!H70*(1/4)+'Informational Hierarchy'!H70*(1/4) -> #DIV/0! | I70: ='Security Hierarchy'!I70*(1/4)+'Economic Hierarchy'!I70*(1/4)+'Diplomatic Hiearachy'!I70*(1/4)+'Informational Hierarchy'!I70*(1/4) -> #DIV/0! | ... AW70: ='Security Hierarchy'!AW70*(1/4)+'Economic Hierarchy'!AW70*(1/4)+'Diplomatic Hiearachy'!AW70*(1/4)+'Informational Hierarchy'!AW70*(1/4) -> #DIV/0!
...

Sheet Security Model
A1: US
B2: Albania | C2: Armenia | D2: Austria | E2: Azerbaijan | F2: Belarus | G2: Belgium | H2: Bosnia-Herzegovina | I2: Bulgaria | J2: Croatia | K2: Cyprus | L2: Czech | M2: Denmark | N2: Estonia | O2: Finland | P2: France | Q2: Georgia | R2: Germany | S2: Greece | T2: Hungary | U2: Iceland | V2: Ireland | W2: Italy | X2: Kazakhstan | Y2: Kyrgyzstan | Z2: latvia | AA2: Lithuania | AB2: Luxembourg | AC2: Macedonia | AD2: Malta | AE2: Moldova | AF2: Montenegro | AG2: Netherlands | AH2: Norway | AI2: Poland | AJ2: Portugal | AK2: Romania | AL2: Serbia | AM2: Slovakia | AN2: Slovenia | AO2: Spain | AP2: Sweden | AQ2: Switzerland | AR2: Tajikistan | AS2: Turkey | AT2: Turkmenistan | AU2: UK | AV2: Ukraine | AW2: Uzbekistan
A3: 1991 | B3: ='Security Hierarchy'!B3*(1/2)+'Economic Hierarchy'!B3*(1/6)+'Diplomatic Hiearachy'!B3*(1/6)+'Informational Hierarchy'!B33*(1/6) -> #DIV/0! | C3: ='Security Hierarchy'!C3*(1/2)+'Economic Hierarchy'!C3*(1/6)+'Diplomatic Hiearachy'!C3*(1/6)+'Informational Hierarchy'!C33*(1/6) -> #DIV/0! | D3: ='Security Hierarchy'!D3*(1/2)+'Economic Hierarchy'!D3*(1/6)+'Diplomatic Hiearachy'!D3*(1/6)+'Informational Hierarchy'!D33*(1/6) -> #DIV/0! | E3: ='Security Hierarchy'!E3*(1/2)+'Economic Hierarchy'!E3*(1/6)+'Diplomatic Hiearachy'!E3*(1/6)+'Informational Hierarchy'!E33*(1/6) -> #DIV/0! | F3: ='Security Hierarchy'!F3*(1/2)+'Economic Hierarchy'!F3*(1/6)+'Diplomatic Hiearachy'!F3*(1/6)+'Informational Hierarchy'!F33*(1/6) -> #DIV/0! | G3: ='Security Hierarchy'!G3*(1/2)+'Economic Hierarchy'!G3*(1/6)+'Diplomatic Hiearachy'!G3*(1/6)+'Informational Hierarchy'!G33*(1/6) -> #DIV/0! | H3: ='Security Hierarchy'!H3*(1/2)+'Economic Hierarchy'!H3*(1/6)+'Diplomatic Hiearachy'!H3*(1/6)+'Informational Hierarchy'!H33*(1/6) -> #DIV/0! | I3: ='Security Hierarchy'!I3*(1/2)+'Economic Hierarchy'!I3*(1/6)+'Diplomatic Hiearachy'!I3*(1/6)+'Informational Hierarchy'!I33*(1/6) -> #DIV/0! | ... AW3: ='Security Hierarchy'!AW3*(1/2)+'Economic Hierarchy'!AW3*(1/6)+'Diplomatic Hiearachy'!AW3*(1/6)+'Informational Hierarchy'!AW33*(1/6) -> #DIV/0!
A4: 1992 | B4: ='Security Hierarchy'!B4*(1/2)+'Economic Hierarchy'!B4*(1/6)+'Diplomatic Hiearachy'!B4*(1/6)+'Informational Hierarchy'!B34*(1/6) -> #DIV/0! | C4: ='Security Hierarchy'!C4*(1/2)+'Economic Hierarchy'!C4*(1/6)+'Diplomatic Hiearachy'!C4*(1/6)+'Informational Hierarchy'!C34*(1/6) -> #DIV/0! | D4: ='Security Hierarchy'!D4*(1/2)+'Economic Hierarchy'!D4*(1/6)+'Diplomatic Hiearachy'!D4*(1/6)+'Informational Hierarchy'!D34*(1/6) -> #DIV/0! | E4: ='Security Hierarchy'!E4*(1/2)+'Economic Hierarchy'!E4*(1/6)+'Diplomatic Hiearachy'!E4*(1/6)+'Informational Hierarchy'!E34*(1/6) -> #DIV/0! | F4: ='Security Hierarchy'!F4*(1/2)+'Economic Hierarchy'!F4*(1/6)+'Diplomatic Hiearachy'!F4*(1/6)+'Informational Hierarchy'!F34*(1/6) -> #DIV/0! | G4: ='Security Hierarchy'!G4*(1/2)+'Economic Hierarchy'!G4*(1/6)+'Diplomatic Hiearachy'!G4*(1/6)+'Informational Hierarchy'!G34*(1/6) -> #DIV/0! | H4: ='Security Hierarchy'!H4*(1/2)+'Economic Hierarchy'!H4*(1/6)+'Diplomatic Hiearachy'!H4*(1/6)+'Informational Hierarchy'!H34*(1/6) -> #DIV/0! | I4: ='Security Hierarchy'!I4*(1/2)+'Economic Hierarchy'!I4*(1/6)+'Diplomatic Hiearachy'!I4*(1/6)+'Informational Hierarchy'!I34*(1/6) -> #DIV/0! | ... AW4: ='Security Hierarchy'!AW4*(1/2)+'Economic Hierarchy'!AW4*(1/6)+'Diplomatic Hiearachy'!AW4*(1/6)+'Informational Hierarchy'!AW34*(1/6) -> #DIV/0!
A5: 1993 | B5: ='Security Hierarchy'!B5*(1/2)+'Economic Hierarchy'!B5*(1/6)+'Diplomatic Hiearachy'!B5*(1/6)+'Informational Hierarchy'!B35*(1/6) -> #DIV/0! | C5: ='Security Hierarchy'!C5*(1/2)+'Economic Hierarchy'!C5*(1/6)+'Diplomatic Hiearachy'!C5*(1/6)+'Informational Hierarchy'!C35*(1/6) -> #DIV/0! | D5: ='Security Hierarchy'!D5*(1/2)+'Economic Hierarchy'!D5*(1/6)+'Diplomatic Hiearachy'!D5*(1/6)+'Informational Hierarchy'!D35*(1/6) -> #DIV/0! | E5: ='Security Hierarchy'!E5*(1/2)+'Economic Hierarchy'!E5*(1/6)+'Diplomatic Hiearachy'!E5*(1/6)+'Informational Hierarchy'!E35*(1/6) -> #DIV/0! | F5: ='Security Hierarchy'!F5*(1/2)+'Economic Hierarchy'!F5*(1/6)+'Diplomatic Hiearachy'!F5*(1/6)+'Informational Hierarchy'!F35*(1/6) -> #DIV/0! | G5: ='Security Hierarchy'!G5*(1/2)+'Economic Hierarchy'!G5*(1/6)+'Diplomatic Hiearachy'!G5*(1/6)+'Informational Hierarchy'!G35*(1/6) -> #DIV/0! | H5: ='Security Hierarchy'!H5*(1/2)+'Economic Hierarchy'!H5*(1/6)+'Diplomatic Hiearachy'!H5*(1/6)+'Informational Hierarchy'!H35*(1/6) -> #DIV/0! | I5: ='Security Hierarchy'!I5*(1/2)+'Economic Hierarchy'!I5*(1/6)+'Diplomatic Hiearachy'!I5*(1/6)+'Informational Hierarchy'!I35*(1/6) -> #DIV/0! | ... AW5: ='Security Hierarchy'!AW5*(1/2)+'Economic Hierarchy'!AW5*(1/6)+'Diplomatic Hiearachy'!AW5*(1/6)+'Informational Hierarchy'!AW35*(1/6) -> #DIV/0!
A6: 1994 | B6: ='Security Hierarchy'!B6*(1/2)+'Economic Hierarchy'!B6*(1/6)+'Diplomatic Hiearachy'!B6*(1/6)+'Informational Hierarchy'!B36*(1/6) -> #DIV/0! | C6: ='Security Hierarchy'!C6*(1/2)+'Economic Hierarchy'!C6*(1/6)+'Diplomatic Hiearachy'!C6*(1/6)+'Informational Hierarchy'!C36*(1/6) -> #DIV/0! | D6: ='Security Hierarchy'!D6*(1/2)+'Economic Hierarchy'!D6*(1/6)+'Diplomatic Hiearachy'!D6*(1/6)+'Informational Hierarchy'!D36*(1/6) -> #DIV/0! | E6: ='Security Hierarchy'!E6*(1/2)+'Economic Hierarchy'!E6*(1/6)+'Diplomatic Hiearachy'!E6*(1/6)+'Informational Hierarchy'!E36*(1/6) -> #DIV/0! | F6: ='Security Hierarchy'!F6*(1/2)+'Economic Hierarchy'!F6*(1/6)+'Diplomatic Hiearachy'!F6*(1/6)+'Informational Hierarchy'!F36*(1/6) -> #DIV/0! | G6: ='Security Hierarchy'!G6*(1/2)+'Economic Hierarchy'!G6*(1/6)+'Diplomatic Hiearachy'!G6*(1/6)+'Informational Hierarchy'!G36*(1/6) -> #DIV/0! | H6: ='Security Hierarchy'!H6*(1/2)+'Economic Hierarchy'!H6*(1/6)+'Diplomatic Hiearachy'!H6*(1/6)+'Informational Hierarchy'!H36*(1/6) -> #DIV/0! | I6: ='Security Hierarchy'!I6*(1/2)+'Economic Hierarchy'!I6*(1/6)+'Diplomatic Hiearachy'!I6*(1/6)+'Informational Hierarchy'!I36*(1/6) -> #DIV/0! | ... AW6: ='Security Hierarchy'!AW6*(1/2)+'Economic Hierarchy'!AW6*(1/6)+'Diplomatic Hiearachy'!AW6*(1/6)+'Informational Hierarchy'!AW36*(1/6) -> #DIV/0!
A7: 1995 | B7: ='Security Hierarchy'!B7*(1/2)+'Economic Hierarchy'!B7*(1/6)+'Diplomatic Hiearachy'!B7*(1/6)+'Informational Hierarchy'!B37*(1/6) -> #DIV/0! | C7: ='Security Hierarchy'!C7*(1/2)+'Economic Hierarchy'!C7*(1/6)+'Diplomatic Hiearachy'!C7*(1/6)+'Informational Hierarchy'!C37*(1/6) -> #DIV/0! | D7: ='Security Hierarchy'!D7*(1/2)+'Economic Hierarchy'!D7*(1/6)+'Diplomatic Hiearachy'!D7*(1/6)+'Informational Hierarchy'!D37*(1/6) -> #DIV/0! | E7: ='Security Hierarchy'!E7*(1/2)+'Economic Hierarchy'!E7*(1/6)+'Diplomatic Hiearachy'!E7*(1/6)+'Informational Hierarchy'!E37*(1/6) -> #DIV/0! | F7: ='Security Hierarchy'!F7*(1/2)+'Economic Hierarchy'!F7*(1/6)+'Diplomatic Hiearachy'!F7*(1/6)+'Informational Hierarchy'!F37*(1/6) -> #DIV/0! | G7: ='Security Hierarchy'!G7*(1/2)+'Economic Hierarchy'!G7*(1/6)+'Diplomatic Hiearachy'!G7*(1/6)+'Informational Hierarchy'!G37*(1/6) -> #DIV/0! | H7: ='Security Hierarchy'!H7*(1/2)+'Economic Hierarchy'!H7*(1/6)+'Diplomatic Hiearachy'!H7*(1/6)+'Informational Hierarchy'!H37*(1/6) -> #DIV/0! | I7: ='Security Hierarchy'!I7*(1/2)+'Economic Hierarchy'!I7*(1/6)+'Diplomatic Hiearachy'!I7*(1/6)+'Informational Hierarchy'!I37*(1/6) -> #DIV/0! | ... AW7: ='Security Hierarchy'!AW7*(1/2)+'Economic Hierarchy'!AW7*(1/6)+'Diplomatic Hiearachy'!AW7*(1/6)+'Informational Hierarchy'!AW37*(1/6) -> #DIV/0!
A8: 1996 | B8: ='Security Hierarchy'!B8*(1/2)+'Economic Hierarchy'!B8*(1/6)+'Diplomatic Hiearachy'!B8*(1/6)+'Informational Hierarchy'!B38*(1/6) -> #DIV/0! | C8: ='Security Hierarchy'!C8*(1/2)+'Economic Hierarchy'!C8*(1/6)+'Diplomatic Hiearachy'!C8*(1/6)+'Informational Hierarchy'!C38*(1/6) -> #DIV/0! | D8: ='Security Hierarchy'!D8*(1/2)+'Economic Hierarchy'!D8*(1/6)+'Diplomatic Hiearachy'!D8*(1/6)+'Informational Hierarchy'!D38*(1/6) -> #DIV/0! | E8: ='Security Hierarchy'!E8*(1/2)+'Economic Hierarchy'!E8*(1/6)+'Diplomatic Hiearachy'!E8*(1/6)+'Informational Hierarchy'!E38*(1/6) -> #DIV/0! | F8: ='Security Hierarchy'!F8*(1/2)+'Economic Hierarchy'!F8*(1/6)+'Diplomatic Hiearachy'!F8*(1/6)+'Informational Hierarchy'!F38*(1/6) -> #DIV/0! | G8: ='Security Hierarchy'!G8*(1/2)+'Economic Hierarchy'!G8*(1/6)+'Diplomatic Hiearachy'!G8*(1/6)+'Informational Hierarchy'!G38*(1/6) -> #DIV/0! | H8: ='Security Hierarchy'!H8*(1/2)+'Economic Hierarchy'!H8*(1/6)+'Diplomatic Hiearachy'!H8*(1/6)+'Informational Hierarchy'!H38*(1/6) -> #DIV/0! | I8: ='Security Hierarchy'!I8*(1/2)+'Economic Hierarchy'!I8*(1/6)+'Diplomatic Hiearachy'!I8*(1/6)+'Informational Hierarchy'!I38*(1/6) -> #DIV/0! | ... AW8: ='Security Hierarchy'!AW8*(1/2)+'Economic Hierarchy'!AW8*(1/6)+'Diplomatic Hiearachy'!AW8*(1/6)+'Informational Hierarchy'!AW38*(1/6) -> #DIV/0!
A9: 1997 | B9: ='Security Hierarchy'!B9*(1/2)+'Economic Hierarchy'!B9*(1/6)+'Diplomatic Hiearachy'!B9*(1/6)+'Informational Hierarchy'!B39*(1/6) -> #DIV/0! | C9: ='Security Hierarchy'!C9*(1/2)+'Economic Hierarchy'!C9*(1/6)+'Diplomatic Hiearachy'!C9*(1/6)+'Informational Hierarchy'!C39*(1/6) -> #DIV/0! | D9: ='Security Hierarchy'!D9*(1/2)+'Economic Hierarchy'!D9*(1/6)+'Diplomatic Hiearachy'!D9*(1/6)+'Informational Hierarchy'!D39*(1/6) -> #DIV/0! | E9: ='Security Hierarchy'!E9*(1/2)+'Economic Hierarchy'!E9*(1/6)+'Diplomatic Hiearachy'!E9*(1/6)+'Informational Hierarchy'!E39*(1/6) -> #DIV/0! | F9: ='Security Hierarchy'!F9*(1/2)+'Economic Hierarchy'!F9*(1/6)+'Diplomatic Hiearachy'!F9*(1/6)+'Informational Hierarchy'!F39*(1/6) -> #DIV/0! | G9: ='Security Hierarchy'!G9*(1/2)+'Economic Hierarchy'!G9*(1/6)+'Diplomatic Hiearachy'!G9*(1/6)+'Informational Hierarchy'!G39*(1/6) -> #DIV/0! | H9: ='Security Hierarchy'!H9*(1/2)+'Economic Hierarchy'!H9*(1/6)+'Diplomatic Hiearachy'!H9*(1/6)+'Informational Hierarchy'!H39*(1/6) -> #DIV/0! | I9: ='Security Hierarchy'!I9*(1/2)+'Economic Hierarchy'!I9*(1/6)+'Diplomatic Hiearachy'!I9*(1/6)+'Informational Hierarchy'!I39*(1/6) -> #DIV/0! | ... AW9: ='Security Hierarchy'!AW9*(1/2)+'Economic Hierarchy'!AW9*(1/6)+'Diplomatic Hiearachy'!AW9*(1/6)+'Informational Hierarchy'!AW39*(1/6) -> #DIV/0!
