Workbook

Sheet All Equal Model
A1: US | B1: Armenia | C1: Austria | D1: Azerbaijan | E1: Belarus | F1: Belgium | G1: Bulgaria | H1: Croatia | I1: Cyprus | J1: Czech | K1: Denmark | L1: Estonia | M1: Finland | N1: France | O1: Georgia | P1: Germany | Q1: Greece | R1: Hungary | S1: Ireland | T1: Italy | U1: Kazakhstan | V1: Kyrgyzstan | W1: latvia | X1: Lithuania | Y1: Luxembourg | Z1: Malta | AA1: Moldova | AB1: Netherlands | AC1: Poland | AD1: Portugal | AE1: Romania | AF1: Slovakia | AG1: Slovenia | AH1: Spain | AI1: Sweden | AJ1: Tajikistan | AK1: Turkmenistan | AL1: UK | AM1: Ukraine | AN1: Uzbekistan
A2: 1991 | B2: ='Economic Hierarchy NO HHI'!B2*0.25+'Security Hierarchy'!B2*0.25+'Political Hierarchy'!B2*0.25+'PublicSocial Hierarchy'!B2*0.25 -> 0 | C2: ='Economic Hierarchy NO HHI'!C2*0.25+'Security Hierarchy'!C2*0.25+'Political Hierarchy'!C2*0.25+'PublicSocial Hierarchy'!C2*0.25 -> 0 | D2: ='Economic Hierarchy NO HHI'!D2*0.25+'Security Hierarchy'!D2*0.25+'Political Hierarchy'!D2*0.25+'PublicSocial Hierarchy'!D2*0.25 -> 0 | E2: ='Economic Hierarchy NO HHI'!E2*0.25+'Security Hierarchy'!E2*0.25+'Political Hierarchy'!E2*0.25+'PublicSocial Hierarchy'!E2*0.25 -> 0 | F2: ='Economic Hierarchy NO HHI'!F2*0.25+'Security Hierarchy'!F2*0.25+'Political Hierarchy'!F2*0.25+'PublicSocial Hierarchy'!F2*0.25 -> 0.16666667 | G2: ='Economic Hierarchy NO HHI'!G2*0.25+'Security Hierarchy'!G2*0.25+'Political Hierarchy'!G2*0.25+'PublicSocial Hierarchy'!G2*0.25 -> 0 | H2: ='Economic Hierarchy NO HHI'!H2*0.25+'Security Hierarchy'!H2*0.25+'Political Hierarchy'!H2*0.25+'PublicSocial Hierarchy'!H2*0.25 -> 0 | I2: ='Economic Hierarchy NO HHI'!I2*0.25+'Security Hierarchy'!I2*0.25+'Political Hierarchy'!I2*0.25+'PublicSocial Hierarchy'!I2*0.25 -> 0 | ... AN2: ='Economic Hierarchy NO HHI'!AN2*0.25+'Security Hierarchy'!AN2*0.25+'Political Hierarchy'!AN2*0.25+'PublicSocial Hierarchy'!AN2*0.25 -> 0
A3: 1992 | B3: ='Economic Hierarchy NO HHI'!B3*0.25+'Security Hierarchy'!B3*0.25+'Political Hierarchy'!B3*0.25+'PublicSocial Hierarchy'!B3*0.25 -> 0 | C3: ='Economic Hierarchy NO HHI'!C3*0.25+'Security Hierarchy'!C3*0.25+'Political Hierarchy'!C3*0.25+'PublicSocial Hierarchy'!C3*0.25 -> 0.083333333 | D3: ='Economic Hierarchy NO HHI'!D3*0.25+'Security Hierarchy'!D3*0.25+'Political Hierarchy'!D3*0.25+'PublicSocial Hierarchy'!D3*0.25 -> 0 | E3: ='Economic Hierarchy NO HHI'!E3*0.25+'Security Hierarchy'!E3*0.25+'Political Hierarchy'!E3*0.25+'PublicSocial Hierarchy'!E3*0.25 -> 0 | F3: ='Economic Hierarchy NO HHI'!F3*0.25+'Security Hierarchy'!F3*0.25+'Political Hierarchy'!F3*0.25+'PublicSocial Hierarchy'!F3*0.25 -> 0.16666667 | G3: ='Economic Hierarchy NO HHI'!G3*0.25+'Security Hierarchy'!G3*0.25+'Political Hierarchy'!G3*0.25+'PublicSocial Hierarchy'!G3*0.25 -> 0 | H3: ='Economic Hierarchy NO HHI'!H3*0.25+'Security Hierarchy'!H3*0.25+'Political Hierarchy'!H3*0.25+'PublicSocial Hierarchy'!H3*0.25 -> 0 | I3: ='Economic Hierarchy NO HHI'!I3*0.25+'Security Hierarchy'!I3*0.25+'Political Hierarchy'!I3*0.25+'PublicSocial Hierarchy'!I3*0.25 -> 0 | ... AN3: ='Economic Hierarchy NO HHI'!AN3*0.25+'Security Hierarchy'!AN3*0.25+'Political Hierarchy'!AN3*0.25+'PublicSocial Hierarchy'!AN3*0.25 -> 0
A4: 1993 | B4: ='Economic Hierarchy NO HHI'!B4*0.25+'Security Hierarchy'!B4*0.25+'Political Hierarchy'!B4*0.25+'PublicSocial Hierarchy'!B4*0.25 -> 0 | C4: ='Economic Hierarchy NO HHI'!C4*0.25+'Security Hierarchy'!C4*0.25+'Political Hierarchy'!C4*0.25+'PublicSocial Hierarchy'!C4*0.25 -> 0 | D4: ='Economic Hierarchy NO HHI'!D4*0.25+'Security Hierarchy'!D4*0.25+'Political Hierarchy'!D4*0.25+'PublicSocial Hierarchy'!D4*0.25 -> 0 | E4: ='Economic Hierarchy NO HHI'!E4*0.25+'Security Hierarchy'!E4*0.25+'Political Hierarchy'!E4*0.25+'PublicSocial Hierarchy'!E4*0.25 -> 0 | F4: ='Economic Hierarchy NO HHI'!F4*0.25+'Security Hierarchy'!F4*0.25+'Political Hierarchy'!F4*0.25+'PublicSocial Hierarchy'!F4*0.25 -> 0.25 | G4: ='Economic Hierarchy NO HHI'!G4*0.25+'Security Hierarchy'!G4*0.25+'Political Hierarchy'!G4*0.25+'PublicSocial Hierarchy'!G4*0.25 -> 0 | H4: ='Economic Hierarchy NO HHI'!H4*0.25+'Security Hierarchy'!H4*0.25+'Political Hierarchy'!H4*0.25+'PublicSocial Hierarchy'!H4*0.25 -> 0 | I4: ='Economic Hierarchy NO HHI'!I4*0.25+'Security Hierarchy'!I4*0.25+'Political Hierarchy'!I4*0.25+'PublicSocial Hierarchy'!I4*0.25 -> 0 | ... AN4: ='Economic Hierarchy NO HHI'!AN4*0.25+'Security Hierarchy'!AN4*0.25+'Political Hierarchy'!AN4*0.25+'PublicSocial Hierarchy'!AN4*0.25 -> 0
A5: 1994 | B5: ='Economic Hierarchy NO HHI'!B5*0.25+'Security Hierarchy'!B5*0.25+'Political Hierarchy'!B5*0.25+'PublicSocial Hierarchy'!B5*0.25 -> 0 | C5: ='Economic Hierarchy NO HHI'!C5*0.25+'Security Hierarchy'!C5*0.25+'Political Hierarchy'!C5*0.25+'PublicSocial Hierarchy'!C5*0.25 -> 0 | D5: ='Economic Hierarchy NO HHI'!D5*0.25+'Security Hierarchy'!D5*0.25+'Political Hierarchy'!D5*0.25+'PublicSocial Hierarchy'!D5*0.25 -> 0 | E5: ='Economic Hierarchy NO HHI'!E5*0.25+'Security Hierarchy'!E5*0.25+'Political Hierarchy'!E5*0.25+'PublicSocial Hierarchy'!E5*0.25 -> 0 | F5: ='Economic Hierarchy NO HHI'!F5*0.25+'Security Hierarchy'!F5*0.25+'Political Hierarchy'!F5*0.25+'PublicSocial Hierarchy'!F5*0.25 -> 0.16666667 | G5: ='Economic Hierarchy NO HHI'!G5*0.25+'Security Hierarchy'!G5*0.25+'Political Hierarchy'!G5*0.25+'PublicSocial Hierarchy'!G5*0.25 -> 0 | H5: ='Economic Hierarchy NO HHI'!H5*0.25+'Security Hierarchy'!H5*0.25+'Political Hierarchy'!H5*0.25+'PublicSocial Hierarchy'!H5*0.25 -> 0 | I5: ='Economic Hierarchy NO HHI'!I5*0.25+'Security Hierarchy'!I5*0.25+'Political Hierarchy'!I5*0.25+'PublicSocial Hierarchy'!I5*0.25 -> 0 | ... AN5: ='Economic Hierarchy NO HHI'!AN5*0.25+'Security Hierarchy'!AN5*0.25+'Political Hierarchy'!AN5*0.25+'PublicSocial Hierarchy'!AN5*0.25 -> 0
A6: 1995 | B6: ='Economic Hierarchy NO HHI'!B6*0.25+'Security Hierarchy'!B6*0.25+'Political Hierarchy'!B6*0.25+'PublicSocial Hierarchy'!B6*0.25 -> 0 | C6: ='Economic Hierarchy NO HHI'!C6*0.25+'Security Hierarchy'!C6*0.25+'Political Hierarchy'!C6*0.25+'PublicSocial Hierarchy'!C6*0.25 -> 0.083333333 | D6: ='Economic Hierarchy NO HHI'!D6*0.25+'Security Hierarchy'!D6*0.25+'Political Hierarchy'!D6*0.25+'PublicSocial Hierarchy'!D6*0.25 -> 0 | E6: ='Economic Hierarchy NO HHI'!E6*0.25+'Security Hierarchy'!E6*0.25+'Political Hierarchy'!E6*0.25+'PublicSocial Hierarchy'!E6*0.25 -> 0 | F6: ='Economic Hierarchy NO HHI'!F6*0.25+'Security Hierarchy'!F6*0.25+'Political Hierarchy'!F6*0.25+'PublicSocial Hierarchy'!F6*0.25 -> 0.25 | G6: ='Economic Hierarchy NO HHI'!G6*0.25+'Security Hierarchy'!G6*0.25+'Political Hierarchy'!G6*0.25+'PublicSocial Hierarchy'!G6*0.25 -> 0 | H6: ='Economic Hierarchy NO HHI'!H6*0.25+'Security Hierarchy'!H6*0.25+'Political Hierarchy'!H6*0.25+'PublicSocial Hierarchy'!H6*0.25 -> 0 | I6: ='Economic Hierarchy NO HHI'!I6*0.25+'Security Hierarchy'!I6*0.25+'Political Hierarchy'!I6*0.25+'PublicSocial Hierarchy'!I6*0.25 -> 0 | ... AN6: ='Economic Hierarchy NO HHI'!AN6*0.25+'Security Hierarchy'!AN6*0.25+'Political Hierarchy'!AN6*0.25+'PublicSocial Hierarchy'!AN6*0.25 -> 0
A7: 1996 | B7: ='Economic Hierarchy NO HHI'!B7*0.25+'Security Hierarchy'!B7*0.25+'Political Hierarchy'!B7*0.25+'PublicSocial Hierarchy'!B7*0.25 -> 0 | C7: ='Economic Hierarchy NO HHI'!C7*0.25+'Security Hierarchy'!C7*0.25+'Political Hierarchy'!C7*0.25+'PublicSocial Hierarchy'!C7*0.25 -> 0 | D7: ='Economic Hierarchy NO HHI'!D7*0.25+'Security Hierarchy'!D7*0.25+'Political Hierarchy'!D7*0.25+'PublicSocial Hierarchy'!D7*0.25 -> 0 | E7: ='Economic Hierarchy NO HHI'!E7*0.25+'Security Hierarchy'!E7*0.25+'Political Hierarchy'!E7*0.25+'PublicSocial Hierarchy'!E7*0.25 -> 0 | F7: ='Economic Hierarchy NO HHI'!F7*0.25+'Security Hierarchy'!F7*0.25+'Political Hierarchy'!F7*0.25+'PublicSocial Hierarchy'!F7*0.25 -> 0.16666667 | G7: ='Economic Hierarchy NO HHI'!G7*0.25+'Security Hierarchy'!G7*0.25+'Political Hierarchy'!G7*0.25+'PublicSocial Hierarchy'!G7*0.25 -> 0 | H7: ='Economic Hierarchy NO HHI'!H7*0.25+'Security Hierarchy'!H7*0.25+'Political Hierarchy'!H7*0.25+'PublicSocial Hierarchy'!H7*0.25 -> 0.083333333 | I7: ='Economic Hierarchy NO HHI'!I7*0.25+'Security Hierarchy'!I7*0.25+'Political Hierarchy'!I7*0.25+'PublicSocial Hierarchy'!I7*0.25 -> 0 | ... AN7: ='Economic Hierarchy NO HHI'!AN7*0.25+'Security Hierarchy'!AN7*0.25+'Political Hierarchy'!AN7*0.25+'PublicSocial Hierarchy'!AN7*0.25 -> 0
A8: 1997 | B8: ='Economic Hierarchy NO HHI'!B8*0.25+'Security Hierarchy'!B8*0.25+'Political Hierarchy'!B8*0.25+'PublicSocial Hierarchy'!B8*0.25 -> 0 | C8: ='Economic Hierarchy NO HHI'!C8*0.25+'Security Hierarchy'!C8*0.25+'Political Hierarchy'!C8*0.25+'PublicSocial Hierarchy'!C8*0.25 -> 0 | D8: ='Economic Hierarchy NO HHI'!D8*0.25+'Security Hierarchy'!D8*0.25+'Political Hierarchy'!D8*0.25+'PublicSocial Hierarchy'!D8*0.25 -> 0 | E8: ='Economic Hierarchy NO HHI'!E8*0.25+'Security Hierarchy'!E8*0.25+'Political Hierarchy'!E8*0.25+'PublicSocial Hierarchy'!E8*0.25 -> 0 | F8: ='Economic Hierarchy NO HHI'!F8*0.25+'Security Hierarchy'!F8*0.25+'Political Hierarchy'!F8*0.25+'PublicSocial Hierarchy'!F8*0.25 -> 0.25 | G8: ='Economic Hierarchy NO HHI'!G8*0.25+'Security Hierarchy'!G8*0.25+'Political Hierarchy'!G8*0.25+'PublicSocial Hierarchy'!G8*0.25 -> 0 | H8: ='Economic Hierarchy NO HHI'!H8*0.25+'Security Hierarchy'!H8*0.25+'Political Hierarchy'!H8*0.25+'PublicSocial Hierarchy'!H8*0.25 -> 0 | I8: ='Economic Hierarchy NO HHI'!I8*0.25+'Security Hierarchy'!I8*0.25+'Political Hierarchy'!I8*0.25+'PublicSocial Hierarchy'!I8*0.25 -> 0 | ... AN8: ='Economic Hierarchy NO HHI'!AN8*0.25+'Security Hierarchy'!AN8*0.25+'Political Hierarchy'!AN8*0.25+'PublicSocial Hierarchy'!AN8*0.25 -> 0
A9: 1998 | B9: ='Economic Hierarchy NO HHI'!B9*0.25+'Security Hierarchy'!B9*0.25+'Political Hierarchy'!B9*0.25+'PublicSocial Hierarchy'!B9*0.25 -> 0 | C9: ='Economic Hierarchy NO HHI'!C9*0.25+'Security Hierarchy'!C9*0.25+'Political Hierarchy'!C9*0.25+'PublicSocial Hierarchy'!C9*0.25 -> 0 | D9: ='Economic Hierarchy NO HHI'!D9*0.25+'Security Hierarchy'!D9*0.25+'Political Hierarchy'!D9*0.25+'PublicSocial Hierarchy'!D9*0.25 -> 0 | E9: ='Economic Hierarchy NO HHI'!E9*0.25+'Security Hierarchy'!E9*0.25+'Political Hierarchy'!E9*0.25+'PublicSocial Hierarchy'!E9*0.25 -> 0 | F9: ='Economic Hierarchy NO HHI'!F9*0.25+'Security Hierarchy'!F9*0.25+'Political Hierarchy'!F9*0.25+'PublicSocial Hierarchy'!F9*0.25 -> 0.16666667 | G9: ='Economic Hierarchy NO HHI'!G9*0.25+'Security Hierarchy'!G9*0.25+'Political Hierarchy'!G9*0.25+'PublicSocial Hierarchy'!G9*0.25 -> 0 | H9: ='Economic Hierarchy NO HHI'!H9*0.25+'Security Hierarchy'!H9*0.25+'Political Hierarchy'!H9*0.25+'PublicSocial Hierarchy'!H9*0.25 -> 0 | I9: ='Economic Hierarchy NO HHI'!I9*0.25+'Security Hierarchy'!I9*0.25+'Political Hierarchy'!I9*0.25+'PublicSocial Hierarchy'!I9*0.25 -> 0 | ... AN9: ='Economic Hierarchy NO HHI'!AN9*0.25+'Security Hierarchy'!AN9*0.25+'Political Hierarchy'!AN9*0.25+'PublicSocial Hierarchy'!AN9*0.25 -> 0
A10: 1999 | B10: ='Economic Hierarchy NO HHI'!B10*0.25+'Security Hierarchy'!B10*0.25+'Political Hierarchy'!B10*0.25+'PublicSocial Hierarchy'!B10*0.25 -> 0 | C10: ='Economic Hierarchy NO HHI'!C10*0.25+'Security Hierarchy'!C10*0.25+'Political Hierarchy'!C10*0.25+'PublicSocial Hierarchy'!C10*0.25 -> 0 | D10: ='Economic Hierarchy NO HHI'!D10*0.25+'Security Hierarchy'!D10*0.25+'Political Hierarchy'!D10*0.25+'PublicSocial Hierarchy'!D10*0.25 -> 0 | E10: ='Economic Hierarchy NO HHI'!E10*0.25+'Security Hierarchy'!E10*0.25+'Political Hierarchy'!E10*0.25+'PublicSocial Hierarchy'!E10*0.25 -> 0 | F10: ='Economic Hierarchy NO HHI'!F10*0.25+'Security Hierarchy'!F10*0.25+'Political Hierarchy'!F10*0.25+'PublicSocial Hierarchy'!F10*0.25 -> 0.25 | G10: ='Economic Hierarchy NO HHI'!G10*0.25+'Security Hierarchy'!G10*0.25+'Political Hierarchy'!G10*0.25+'PublicSocial Hierarchy'!G10*0.25 -> 0.083333333 | H10: ='Economic Hierarchy NO HHI'!H10*0.25+'Security Hierarchy'!H10*0.25+'Political Hierarchy'!H10*0.25+'PublicSocial Hierarchy'!H10*0.25 -> 0.083333333 | I10: ='Economic Hierarchy NO HHI'!I10*0.25+'Security Hierarchy'!I10*0.25+'Political Hierarchy'!I10*0.25+'PublicSocial Hierarchy'!I10*0.25 -> 0 | ... AN10: ='Economic Hierarchy NO HHI'!AN10*0.25+'Security Hierarchy'!AN10*0.25+'Political Hierarchy'!AN10*0.25+'PublicSocial Hierarchy'!AN10*0.25 -> 0
A11: 2000 | B11: ='Economic Hierarchy NO HHI'!B11*0.25+'Security Hierarchy'!B11*0.25+'Political Hierarchy'!B11*0.25+'PublicSocial Hierarchy'!B11*0.25 -> 0.032125 | C11: ='Economic Hierarchy NO HHI'!C11*0.25+'Security Hierarchy'!C11*0.25+'Political Hierarchy'!C11*0.25+'PublicSocial Hierarchy'!C11*0.25 -> 0.094675906 | D11: ='Economic Hierarchy NO HHI'!D11*0.25+'Security Hierarchy'!D11*0.25+'Political Hierarchy'!D11*0.25+'PublicSocial Hierarchy'!D11*0.25 -> 0.022225 | E11: ='Economic Hierarchy NO HHI'!E11*0.25+'Security Hierarchy'!E11*0.25+'Political Hierarchy'!E11*0.25+'PublicSocial Hierarchy'!E11*0.25 -> 0.0038375 | F11: ='Economic Hierarchy NO HHI'!F11*0.25+'Security Hierarchy'!F11*0.25+'Political Hierarchy'!F11*0.25+'PublicSocial Hierarchy'!F11*0.25 -> 0.26429144 | G11: ='Economic Hierarchy NO HHI'!G11*0.25+'Security Hierarchy'!G11*0.25+'Political Hierarchy'!G11*0.25+'PublicSocial Hierarchy'!G11*0.25 -> 0.007724179 | H11: ='Economic Hierarchy NO HHI'!H11*0.25+'Security Hierarchy'!H11*0.25+'Political Hierarchy'!H11*0.25+'PublicSocial Hierarchy'!H11*0.25 -> 0.0035247002 | I11: ='Economic Hierarchy NO HHI'!I11*0.25+'Security Hierarchy'!I11*0.25+'Political Hierarchy'!I11*0.25+'PublicSocial Hierarchy'!I11*0.25 -> 0.020508393 | ... AN11: ='Economic Hierarchy NO HHI'!AN11*0.25+'Security Hierarchy'!AN11*0.25+'Political Hierarchy'!AN11*0.25+'PublicSocial Hierarchy'!AN11*0.25 -> 0.0124125
A12: 2001 | B12: ='Economic Hierarchy NO HHI'!B12*0.25+'Security Hierarchy'!B12*0.25+'Political Hierarchy'!B12*0.25+'PublicSocial Hierarchy'!B12*0.25 -> 0.0337375 | C12: ='Economic Hierarchy NO HHI'!C12*0.25+'Security Hierarchy'!C12*0.25+'Political Hierarchy'!C12*0.25+'PublicSocial Hierarchy'!C12*0.25 -> 0.011233905 | D12: ='Economic Hierarchy NO HHI'!D12*0.25+'Security Hierarchy'!D12*0.25+'Political Hierarchy'!D12*0.25+'PublicSocial Hierarchy'!D12*0.25 -> 0.017725 | E12: ='Economic Hierarchy NO HHI'!E12*0.25+'Security Hierarchy'!E12*0.25+'Political Hierarchy'!E12*0.25+'PublicSocial Hierarchy'!E12*0.25 -> 0.00365 | F12: ='Economic Hierarchy NO HHI'!F12*0.25+'Security Hierarchy'!F12*0.25+'Political Hierarchy'!F12*0.25+'PublicSocial Hierarchy'!F12*0.25 -> 0.26571943 | G12: ='Economic Hierarchy NO HHI'!G12*0.25+'Security Hierarchy'!G12*0.25+'Political Hierarchy'!G12*0.25+'PublicSocial Hierarchy'!G12*0.25 -> 0.0069480596 | H12: ='Economic Hierarchy NO HHI'!H12*0.25+'Security Hierarchy'!H12*0.25+'Political Hierarchy'!H12*0.25+'PublicSocial Hierarchy'!H12*0.25 -> 0.0035589545 | I12: ='Economic Hierarchy NO HHI'!I12*0.25+'Security Hierarchy'!I12*0.25+'Political Hierarchy'!I12*0.25+'PublicSocial Hierarchy'!I12*0.25 -> 0.02263849 | ... AN12: ='Economic Hierarchy NO HHI'!AN12*0.25+'Security Hierarchy'!AN12*0.25+'Political Hierarchy'!AN12*0.25+'PublicSocial Hierarchy'!AN12*0.25 -> 0.0115
A13: 2002 | B13: ='Economic Hierarchy NO HHI'!B13*0.25+'Security Hierarchy'!B13*0.25+'Political Hierarchy'!B13*0.25+'PublicSocial Hierarchy'!B13*0.25 -> #VALUE! | C13: ='Economic Hierarchy NO HHI'!C13*0.25+'Security Hierarchy'!C13*0.25+'Political Hierarchy'!C13*0.25+'PublicSocial Hierarchy'!C13*0.25 -> 0.24803342 | D13: ='Economic Hierarchy NO HHI'!D13*0.25+'Security Hierarchy'!D13*0.25+'Political Hierarchy'!D13*0.25+'PublicSocial Hierarchy'!D13*0.25 -> 0.14210656 | E13: ='Economic Hierarchy NO HHI'!E13*0.25+'Security Hierarchy'!E13*0.25+'Political Hierarchy'!E13*0.25+'PublicSocial Hierarchy'!E13*0.25 -> 0.10367116 | F13: ='Economic Hierarchy NO HHI'!F13*0.25+'Security Hierarchy'!F13*0.25+'Political Hierarchy'!F13*0.25+'PublicSocial Hierarchy'!F13*0.25 -> 0.4238008 | G13: ='Economic Hierarchy NO HHI'!G13*0.25+'Security Hierarchy'!G13*0.25+'Political Hierarchy'!G13*0.25+'PublicSocial Hierarchy'!G13*0.25 -> 0.22772054 | H13: ='Economic Hierarchy NO HHI'!H13*0.25+'Security Hierarchy'!H13*0.25+'Political Hierarchy'!H13*0.25+'PublicSocial Hierarchy'!H13*0.25 -> 0.23122098 | I13: ='Economic Hierarchy NO HHI'!I13*0.25+'Security Hierarchy'!I13*0.25+'Political Hierarchy'!I13*0.25+'PublicSocial Hierarchy'!I13*0.25 -> #VALUE! | ... AN13: ='Economic Hierarchy NO HHI'!AN13*0.25+'Security Hierarchy'!AN13*0.25+'Political Hierarchy'!AN13*0.25+'PublicSocial Hierarchy'!AN13*0.25 -> 0.12113275
... A28: 2017 | B28: ='Economic Hierarchy NO HHI'!B28*0.25+'Security Hierarchy'!B28*0.25+'Political Hierarchy'!B28*0.25+'PublicSocial Hierarchy'!B28*0.25 -> 0.20673317 | C28: ='Economic Hierarchy NO HHI'!C28*0.25+'Security Hierarchy'!C28*0.25+'Political Hierarchy'!C28*0.25+'PublicSocial Hierarchy'!C28*0.25 -> 0.21628465 | D28: ='Economic Hierarchy NO HHI'!D28*0.25+'Security Hierarchy'!D28*0.25+'Political Hierarchy'!D28*0.25+'PublicSocial Hierarchy'!D28*0.25 -> 0.088861383 | E28: ='Economic Hierarchy NO HHI'!E28*0.25+'Security Hierarchy'!E28*0.25+'Political Hierarchy'!E28*0.25+'PublicSocial Hierarchy'!E28*0.25 -> 0.098743715 | F28: ='Economic Hierarchy NO HHI'!F28*0.25+'Security Hierarchy'!F28*0.25+'Political Hierarchy'!F28*0.25+'PublicSocial Hierarchy'!F28*0.25 -> 0.37985467 | G28: ='Economic Hierarchy NO HHI'!G28*0.25+'Security Hierarchy'!G28*0.25+'Political Hierarchy'!G28*0.25+'PublicSocial Hierarchy'!G28*0.25 -> 0.32735532 | H28: ='Economic Hierarchy NO HHI'!H28*0.25+'Security Hierarchy'!H28*0.25+'Political Hierarchy'!H28*0.25+'PublicSocial Hierarchy'!H28*0.25 -> 0.29261028 | I28: ='Economic Hierarchy NO HHI'!I28*0.25+'Security Hierarchy'!I28*0.25+'Political Hierarchy'!I28*0.25+'PublicSocial Hierarchy'!I28*0.25 -> 0.24402743 | ... AN28: ='Economic Hierarchy NO HHI'!AN28*0.25+'Security Hierarchy'!AN28*0.25+'Political Hierarchy'!AN28*0.25+'PublicSocial Hierarchy'!AN28*0.25 -> 0.15793068
A31: Russia | B31: Armenia | C31: Austria | D31: Azerbaijan | E31: Belarus | F31: Belgium | G31: Bulgaria | H31: Croatia | I31: Cyprus | J31: Czech | K31: Denmark | L31: Estonia | M31: Finland | N31: France | O31: Georgia | P31: Germany | Q31: Greece | R31: Hungary | S31: Ireland | T31: Italy | U31: Kazakhstan | V31: Kyrgyzstan | W31: latvia | X31: Lithuania | Y31: Luxembourg | Z31: Malta | AA31: Moldova | AB31: Netherlands | AC31: Poland | AD31: Portugal | AE31: Romania | AF31: Slovakia | AG31: Slovenia | AH31: Spain | AI31: Sweden | AJ31: Tajikistan | AK31: Turkmenistan | AL31: UK | AM31: Ukraine | AN31: Uzbekistan
A32: 1991 | B32: ='Economic Hierarchy NO HHI'!B32*0.25+'Security Hierarchy'!B33*0.25+'Political Hierarchy'!B33*0.25+'PublicSocial Hierarchy'!B33*0.25 -> 0.083333333 | C32: ='Economic Hierarchy NO HHI'!C32*0.25+'Security Hierarchy'!C33*0.25+'Political Hierarchy'!C33*0.25+'PublicSocial Hierarchy'!C33*0.25 -> 0 | D32: ='Economic Hierarchy NO HHI'!D32*0.25+'Security Hierarchy'!D33*0.25+'Political Hierarchy'!D33*0.25+'PublicSocial Hierarchy'!D33*0.25 -> 0.083333333 | E32: ='Economic Hierarchy NO HHI'!E32*0.25+'Security Hierarchy'!E33*0.25+'Political Hierarchy'!E33*0.25+'PublicSocial Hierarchy'!E33*0.25 -> 0.083333333 | F32: ='Economic Hierarchy NO HHI'!F32*0.25+'Security Hierarchy'!F33*0.25+'Political Hierarchy'!F33*0.25+'PublicSocial Hierarchy'!F33*0.25 -> 0 | G32: ='Economic Hierarchy NO HHI'!G32*0.25+'Security Hierarchy'!G33*0.25+'Political Hierarchy'!G33*0.25+'PublicSocial Hierarchy'!G33*0.25 -> 0 | H32: ='Economic Hierarchy NO HHI'!H32*0.25+'Security Hierarchy'!H33*0.25+'Political Hierarchy'!H33*0.25+'PublicSocial Hierarchy'!H33*0.25 -> 0 | I32: ='Economic Hierarchy NO HHI'!I32*0.25+'Security Hierarchy'!I33*0.25+'Political Hierarchy'!I33*0.25+'PublicSocial Hierarchy'!I33*0.25 -> 0 | ... AN32: ='Economic Hierarchy NO HHI'!AN32*0.25+'Security Hierarchy'!AN33*0.25+'Political Hierarchy'!AN33*0.25+'PublicSocial Hierarchy'!AN33*0.25 -> 0
A33: 1992 | B33: ='Economic Hierarchy NO HHI'!B33*0.25+'Security Hierarchy'!B34*0.25+'Political Hierarchy'!B34*0.25+'PublicSocial Hierarchy'!B34*0.25 -> 0.083333333 | C33: ='Economic Hierarchy NO HHI'!C33*0.25+'Security Hierarchy'!C34*0.25+'Political Hierarchy'!C34*0.25+'PublicSocial Hierarchy'!C34*0.25 -> 0 | D33: ='Economic Hierarchy NO HHI'!D33*0.25+'Security Hierarchy'!D34*0.25+'Political Hierarchy'!D34*0.25+'PublicSocial Hierarchy'!D34*0.25 -> 0.083333333 | E33: ='Economic Hierarchy NO HHI'!E33*0.25+'Security Hierarchy'!E34*0.25+'Political Hierarchy'!E34*0.25+'PublicSocial Hierarchy'!E34*0.25 -> 0.083333333 | F33: ='Economic Hierarchy NO HHI'!F33*0.25+'Security Hierarchy'!F34*0.25+'Political Hierarchy'!F34*0.25+'PublicSocial Hierarchy'!F34*0.25 -> 0 | G33: ='Economic Hierarchy NO HHI'!G33*0.25+'Security Hierarchy'!G34*0.25+'Political Hierarchy'!G34*0.25+'PublicSocial Hierarchy'!G34*0.25 -> 0.083333333 | H33: ='Economic Hierarchy NO HHI'!H33*0.25+'Security Hierarchy'!H34*0.25+'Political Hierarchy'!H34*0.25+'PublicSocial Hierarchy'!H34*0.25 -> 0.083333333 | I33: ='Economic Hierarchy NO HHI'!I33*0.25+'Security Hierarchy'!I34*0.25+'Political Hierarchy'!I34*0.25+'PublicSocial Hierarchy'!I34*0.25 -> 0 | ... AN33: ='Economic Hierarchy NO HHI'!AN33*0.25+'Security Hierarchy'!AN34*0.25+'Political Hierarchy'!AN34*0.25+'PublicSocial Hierarchy'!AN34*0.25 -> 0
A34: 1993 | B34: ='Economic Hierarchy NO HHI'!B34*0.25+'Security Hierarchy'!B35*0.25+'Political Hierarchy'!B35*0.25+'PublicSocial Hierarchy'!B35*0.25 -> 0.16666667 | C34: ='Economic Hierarchy NO HHI'!C34*0.25+'Security Hierarchy'!C35*0.25+'Political Hierarchy'!C35*0.25+'PublicSocial Hierarchy'!C35*0.25 -> 0 | D34: ='Economic Hierarchy NO HHI'!D34*0.25+'Security Hierarchy'!D35*0.25+'Political Hierarchy'!D35*0.25+'PublicSocial Hierarchy'!D35*0.25 -> 0.083333333 | E34: ='Economic Hierarchy NO HHI'!E34*0.25+'Security Hierarchy'!E35*0.25+'Political Hierarchy'!E35*0.25+'PublicSocial Hierarchy'!E35*0.25 -> 0.083333333 | F34: ='Economic Hierarchy NO HHI'!F34*0.25+'Security Hierarchy'!F35*0.25+'Political Hierarchy'!F35*0.25+'PublicSocial Hierarchy'!F35*0.25 -> 0 | G34: ='Economic Hierarchy NO HHI'!G34*0.25+'Security Hierarchy'!G35*0.25+'Political Hierarchy'!G35*0.25+'PublicSocial Hierarchy'!G35*0.25 -> 0 | H34: ='Economic Hierarchy NO HHI'!H34*0.25+'Security Hierarchy'!H35*0.25+'Political Hierarchy'!H35*0.25+'PublicSocial Hierarchy'!H35*0.25 -> 0 | I34: ='Economic Hierarchy NO HHI'!I34*0.25+'Security Hierarchy'!I35*0.25+'Political Hierarchy'!I35*0.25+'PublicSocial Hierarchy'!I35*0.25 -> 0 | ... AN34: ='Economic Hierarchy NO HHI'!AN34*0.25+'Security Hierarchy'!AN35*0.25+'Political Hierarchy'!AN35*0.25+'PublicSocial Hierarchy'!AN35*0.25 -> 0
A35: 1994 | B35: ='Economic Hierarchy NO HHI'!B35*0.25+'Security Hierarchy'!B36*0.25+'Political Hierarchy'!B36*0.25+'PublicSocial Hierarchy'!B36*0.25 -> 0.25 | C35: ='Economic Hierarchy NO HHI'!C35*0.25+'Security Hierarchy'!C36*0.25+'Political Hierarchy'!C36*0.25+'PublicSocial Hierarchy'!C36*0.25 -> 0 | D35: ='Economic Hierarchy NO HHI'!D35*0.25+'Security Hierarchy'!D36*0.25+'Political Hierarchy'!D36*0.25+'PublicSocial Hierarchy'!D36*0.25 -> 0.16666667 | E35: ='Economic Hierarchy NO HHI'!E35*0.25+'Security Hierarchy'!E36*0.25+'Political Hierarchy'!E36*0.25+'PublicSocial Hierarchy'!E36*0.25 -> 0.16666667 | F35: ='Economic Hierarchy NO HHI'!F35*0.25+'Security Hierarchy'!F36*0.25+'Political Hierarchy'!F36*0.25+'PublicSocial Hierarchy'!F36*0.25 -> 0 | G35: ='Economic Hierarchy NO HHI'!G35*0.25+'Security Hierarchy'!G36*0.25+'Political Hierarchy'!G36*0.25+'PublicSocial Hierarchy'!G36*0.25 -> 0 | H35: ='Economic Hierarchy NO HHI'!H35*0.25+'Security Hierarchy'!H36*0.25+'Political Hierarchy'!H36*0.25+'PublicSocial Hierarchy'!H36*0.25 -> 0 | I35: ='Economic Hierarchy NO HHI'!I35*0.25+'Security Hierarchy'!I36*0.25+'Political Hierarchy'!I36*0.25+'PublicSocial Hierarchy'!I36*0.25 -> 0 | ... AN35: ='Economic Hierarchy NO HHI'!AN35*0.25+'Security Hierarchy'!AN36*0.25+'Political Hierarchy'!AN36*0.25+'PublicSocial Hierarchy'!AN36*0.25 -> 0.16666667
A36: 1995 | B36: ='Economic Hierarchy NO HHI'!B36*0.25+'Security Hierarchy'!B37*0.25+'Political Hierarchy'!B37*0.25+'PublicSocial Hierarchy'!B37*0.25 -> 0.25 | C36: ='Economic Hierarchy NO HHI'!C36*0.25+'Security Hierarchy'!C37*0.25+'Political Hierarchy'!C37*0.25+'PublicSocial Hierarchy'!C37*0.25 -> 0 | D36: ='Economic Hierarchy NO HHI'!D36*0.25+'Security Hierarchy'!D37*0.25+'Political Hierarchy'!D37*0.25+'PublicSocial Hierarchy'!D37*0.25 -> 0.16666667 | E36: ='Economic Hierarchy NO HHI'!E36*0.25+'Security Hierarchy'!E37*0.25+'Political Hierarchy'!E37*0.25+'PublicSocial Hierarchy'!E37*0.25 -> 0.16666667 | F36: ='Economic Hierarchy NO HHI'!F36*0.25+'Security Hierarchy'!F37*0.25+'Political Hierarchy'!F37*0.25+'PublicSocial Hierarchy'!F37*0.25 -> 0 | G36: ='Economic Hierarchy NO HHI'!G36*0.25+'Security Hierarchy'!G37*0.25+'Political Hierarchy'!G37*0.25+'PublicSocial Hierarchy'!G37*0.25 -> 0.083333333 | H36: ='Economic Hierarchy NO HHI'!H36*0.25+'Security Hierarchy'!H37*0.25+'Political Hierarchy'!H37*0.25+'PublicSocial Hierarchy'!H37*0.25 -> 0 | I36: ='Economic Hierarchy NO HHI'!I36*0.25+'Security Hierarchy'!I37*0.25+'Political Hierarchy'!I37*0.25+'PublicSocial Hierarchy'!I37*0.25 -> 0.083333333 | ... AN36: ='Economic Hierarchy NO HHI'!AN36*0.25+'Security Hierarchy'!AN37*0.25+'Political Hierarchy'!AN37*0.25+'PublicSocial Hierarchy'!AN37*0.25 -> 0.16666667
A37: 1996 | B37: ='Economic Hierarchy NO HHI'!B37*0.25+'Security Hierarchy'!B38*0.25+'Political Hierarchy'!B38*0.25+'PublicSocial Hierarchy'!B38*0.25 -> 0.16666667 | C37: ='Economic Hierarchy NO HHI'!C37*0.25+'Security Hierarchy'!C38*0.25+'Political Hierarchy'!C38*0.25+'PublicSocial Hierarchy'!C38*0.25 -> 0 | D37: ='Economic Hierarchy NO HHI'!D37*0.25+'Security Hierarchy'!D38*0.25+'Political Hierarchy'!D38*0.25+'PublicSocial Hierarchy'!D38*0.25 -> 0.16666667 | E37: ='Economic Hierarchy NO HHI'!E37*0.25+'Security Hierarchy'!E38*0.25+'Political Hierarchy'!E38*0.25+'PublicSocial Hierarchy'!E38*0.25 -> 0.25 | F37: ='Economic Hierarchy NO HHI'!F37*0.25+'Security Hierarchy'!F38*0.25+'Political Hierarchy'!F38*0.25+'PublicSocial Hierarchy'!F38*0.25 -> 0 | G37: ='Economic Hierarchy NO HHI'!G37*0.25+'Security Hierarchy'!G38*0.25+'Political Hierarchy'!G38*0.25+'PublicSocial Hierarchy'!G38*0.25 -> 0 | H37: ='Economic Hierarchy NO HHI'!H37*0.25+'Security Hierarchy'!H38*0.25+'Political Hierarchy'!H38*0.25+'PublicSocial Hierarchy'!H38*0.25 -> 0 | I37: ='Economic Hierarchy NO HHI'!I37*0.25+'Security Hierarchy'!I38*0.25+'Political Hierarchy'!I38*0.25+'PublicSocial Hierarchy'!I38*0.25 -> 0.083333333 | ... AN37: ='Economic Hierarchy NO HHI'!AN37*0.25+'Security Hierarchy'!AN38*0.25+'Political Hierarchy'!AN38*0.25+'PublicSocial Hierarchy'!AN38*0.25 -> 0.16666667
A38: 1997 | B38: ='Economic Hierarchy NO HHI'!B38*0.25+'Security Hierarchy'!B39*0.25+'Political Hierarchy'!B39*0.25+'PublicSocial Hierarchy'!B39*0.25 -> 0.16666667 | C38: ='Economic Hierarchy NO HHI'!C38*0.25+'Security Hierarchy'!C39*0.25+'Political Hierarchy'!C39*0.25+'PublicSocial Hierarchy'!C39*0.25 -> 0 | D38: ='Economic Hierarchy NO HHI'!D38*0.25+'Security Hierarchy'!D39*0.25+'Political Hierarchy'!D39*0.25+'PublicSocial Hierarchy'!D39*0.25 -> 0.16666667 | E38: ='Economic Hierarchy NO HHI'!E38*0.25+'Security Hierarchy'!E39*0.25+'Political Hierarchy'!E39*0.25+'PublicSocial Hierarchy'!E39*0.25 -> 0.16666667 | F38: ='Economic Hierarchy NO HHI'!F38*0.25+'Security Hierarchy'!F39*0.25+'Political Hierarchy'!F39*0.25+'PublicSocial Hierarchy'!F39*0.25 -> 0 | G38: ='Economic Hierarchy NO HHI'!G38*0.25+'Security Hierarchy'!G39*0.25+'Political Hierarchy'!G39*0.25+'PublicSocial Hierarchy'!G39*0.25 -> 0 | H38: ='Economic Hierarchy NO HHI'!H38*0.25+'Security Hierarchy'!H39*0.25+'Political Hierarchy'!H39*0.25+'PublicSocial Hierarchy'!H39*0.25 -> 0 | I38: ='Economic Hierarchy NO HHI'!I38*0.25+'Security Hierarchy'!I39*0.25+'Political Hierarchy'!I39*0.25+'PublicSocial Hierarchy'!I39*0.25 -> 0 | ... AN38: ='Economic Hierarchy NO HHI'!AN38*0.25+'Security Hierarchy'!AN39*0.25+'Political Hierarchy'!AN39*0.25+'PublicSocial Hierarchy'!AN39*0.25 -> 0.16666667
A39: 1998 | B39: ='Economic Hierarchy NO HHI'!B39*0.25+'Security Hierarchy'!B40*0.25+'Political Hierarchy'!B40*0.25+'PublicSocial Hierarchy'!B40*0.25 -> 0.16666667 | C39: ='Economic Hierarchy NO HHI'!C39*0.25+'Security Hierarchy'!C40*0.25+'Political Hierarchy'!C40*0.25+'PublicSocial Hierarchy'!C40*0.25 -> 0 | D39: ='Economic Hierarchy NO HHI'!D39*0.25+'Security Hierarchy'!D40*0.25+'Political Hierarchy'!D40*0.25+'PublicSocial Hierarchy'!D40*0.25 -> 0.16666667 | E39: ='Economic Hierarchy NO HHI'!E39*0.25+'Security Hierarchy'!E40*0.25+'Political Hierarchy'!E40*0.25+'PublicSocial Hierarchy'!E40*0.25 -> 0.16666667 | F39: ='Economic Hierarchy NO HHI'!F39*0.25+'Security Hierarchy'!F40*0.25+'Political Hierarchy'!F40*0.25+'PublicSocial Hierarchy'!F40*0.25 -> 0 | G39: ='Economic Hierarchy NO HHI'!G39*0.25+'Security Hierarchy'!G40*0.25+'Political Hierarchy'!G40*0.25+'PublicSocial Hierarchy'!G40*0.25 -> 0 | H39: ='Economic Hierarchy NO HHI'!H39*0.25+'Security Hierarchy'!H40*0.25+'Political Hierarchy'!H40*0.25+'PublicSocial Hierarchy'!H40*0.25 -> 0 | I39: ='Economic Hierarchy NO HHI'!I39*0.25+'Security Hierarchy'!I40*0.25+'Political Hierarchy'!I40*0.25+'PublicSocial Hierarchy'!I40*0.25 -> 0 | ... AN39: ='Economic Hierarchy NO HHI'!AN39*0.25+'Security Hierarchy'!AN40*0.25+'Political Hierarchy'!AN40*0.25+'PublicSocial Hierarchy'!AN40*0.25 -> 0.16666667
A40: 1999 | B40: ='Economic Hierarchy NO HHI'!B40*0.25+'Security Hierarchy'!B41*0.25+'Political Hierarchy'!B41*0.25+'PublicSocial Hierarchy'!B41*0.25 -> 0.16666667 | C40: ='Economic Hierarchy NO HHI'!C40*0.25+'Security Hierarchy'!C41*0.25+'Political Hierarchy'!C41*0.25+'PublicSocial Hierarchy'!C41*0.25 -> 0 | D40: ='Economic Hierarchy NO HHI'!D40*0.25+'Security Hierarchy'!D41*0.25+'Political Hierarchy'!D41*0.25+'PublicSocial Hierarchy'!D41*0.25 -> 0.16666667 | E40: ='Economic Hierarchy NO HHI'!E40*0.25+'Security Hierarchy'!E41*0.25+'Political Hierarchy'!E41*0.25+'PublicSocial Hierarchy'!E41*0.25 -> 0.16666667 | F40: ='Economic Hierarchy NO HHI'!F40*0.25+'Security Hierarchy'!F41*0.25+'Political Hierarchy'!F41*0.25+'PublicSocial Hierarchy'!F41*0.25 -> 0 | G40: ='Economic Hierarchy NO HHI'!G40*0.25+'Security Hierarchy'!G41*0.25+'Political Hierarchy'!G41*0.25+'PublicSocial Hierarchy'!G41*0.25 -> 0 | H40: ='Economic Hierarchy NO HHI'!H40*0.25+'Security Hierarchy'!H41*0.25+'Political Hierarchy'!H41*0.25+'PublicSocial Hierarchy'!H41*0.25 -> 0 | I40: ='Economic Hierarchy NO HHI'!I40*0.25+'Security Hierarchy'!I41*0.25+'Political Hierarchy'!I41*0.25+'PublicSocial Hierarchy'!I41*0.25 -> 0.083333333 | ... AN40: ='Economic Hierarchy NO HHI'!AN40*0.25+'Security Hierarchy'!AN41*0.25+'Political Hierarchy'!AN41*0.25+'PublicSocial Hierarchy'!AN41*0.25 -> 0.16666667
A41: 2000 | B41: ='Economic Hierarchy NO HHI'!B41*0.25+'Security Hierarchy'!B42*0.25+'Political Hierarchy'!B42*0.25+'PublicSocial Hierarchy'!B42*0.25 -> 0.20112917 | C41: ='Economic Hierarchy NO HHI'!C41*0.25+'Security Hierarchy'!C42*0.25+'Political Hierarchy'!C42*0.25+'PublicSocial Hierarchy'!C42*0.25 -> 0.0030183354 | D41: ='Economic Hierarchy NO HHI'!D41*0.25+'Security Hierarchy'!D42*0.25+'Political Hierarchy'!D42*0.25+'PublicSocial Hierarchy'!D42*0.25 -> 0.10705833 | E41: ='Economic Hierarchy NO HHI'!E41*0.25+'Security Hierarchy'!E42*0.25+'Political Hierarchy'!E42*0.25+'PublicSocial Hierarchy'!E42*0.25 -> 0.30851667 | F41: ='Economic Hierarchy NO HHI'!F41*0.25+'Security Hierarchy'!F42*0.25+'Political Hierarchy'!F42*0.25+'PublicSocial Hierarchy'!F42*0.25 -> 0.0016281618 | G41: ='Economic Hierarchy NO HHI'!G41*0.25+'Security Hierarchy'!G42*0.25+'Political Hierarchy'!G42*0.25+'PublicSocial Hierarchy'!G42*0.25 -> 0.032010692 | H41: ='Economic Hierarchy NO HHI'!H41*0.25+'Security Hierarchy'!H42*0.25+'Political Hierarchy'!H42*0.25+'PublicSocial Hierarchy'!H42*0.25 -> 0.0075450914 | I41: ='Economic Hierarchy NO HHI'!I41*0.25+'Security Hierarchy'!I42*0.25+'Political Hierarchy'!I42*0.25+'PublicSocial Hierarchy'!I42*0.25 -> 0.01024161 | ... AN41: ='Economic Hierarchy NO HHI'!AN41*0.25+'Security Hierarchy'!AN42*0.25+'Political Hierarchy'!AN42*0.25+'PublicSocial Hierarchy'!AN42*0.25 -> 0.0607375
A42: 2001 | B42: ='Economic Hierarchy NO HHI'!B42*0.25+'Security Hierarchy'!B43*0.25+'Political Hierarchy'!B43*0.25+'PublicSocial Hierarchy'!B43*0.25 -> 0.20196667 | C42: ='Economic Hierarchy NO HHI'!C42*0.25+'Security Hierarchy'!C43*0.25+'Political Hierarchy'!C43*0.25+'PublicSocial Hierarchy'!C43*0.25 -> 0.0031863483 | D42: ='Economic Hierarchy NO HHI'!D42*0.25+'Security Hierarchy'!D43*0.25+'Political Hierarchy'!D43*0.25+'PublicSocial Hierarchy'!D43*0.25 -> 0.098833333 | E42: ='Economic Hierarchy NO HHI'!E42*0.25+'Security Hierarchy'!E43*0.25+'Political Hierarchy'!E43*0.25+'PublicSocial Hierarchy'!E43*0.25 -> 0.30926667 | F42: ='Economic Hierarchy NO HHI'!F42*0.25+'Security Hierarchy'!F43*0.25+'Political Hierarchy'!F43*0.25+'PublicSocial Hierarchy'!F43*0.25 -> 0.0019003529 | G42: ='Economic Hierarchy NO HHI'!G42*0.25+'Security Hierarchy'!G43*0.25+'Political Hierarchy'!G43*0.25+'PublicSocial Hierarchy'!G43*0.25 -> 0.027193165 | H42: ='Economic Hierarchy NO HHI'!H42*0.25+'Security Hierarchy'!H43*0.25+'Political Hierarchy'!H43*0.25+'PublicSocial Hierarchy'!H43*0.25 -> 0.0070006325 | I42: ='Economic Hierarchy NO HHI'!I42*0.25+'Security Hierarchy'!I43*0.25+'Political Hierarchy'!I43*0.25+'PublicSocial Hierarchy'!I43*0.25 -> 0.092660819 | ... AN42: ='Economic Hierarchy NO HHI'!AN42*0.25+'Security Hierarchy'!AN43*0.25+'Political Hierarchy'!AN43*0.25+'PublicSocial Hierarchy'!AN43*0.25 -> 0.14347083
A43: 2002 | B43: ='Economic Hierarchy NO HHI'!B43*0.25+'Security Hierarchy'!B44*0.25+'Political Hierarchy'!B44*0.25+'PublicSocial Hierarchy'!B44*0.25 -> #VALUE! | C43: ='Economic Hierarchy NO HHI'!C43*0.25+'Security Hierarchy'!C44*0.25+'Political Hierarchy'!C44*0.25+'PublicSocial Hierarchy'!C44*0.25 -> 0.1203126 | D43: ='Economic Hierarchy NO HHI'!D43*0.25+'Security Hierarchy'!D44*0.25+'Political Hierarchy'!D44*0.25+'PublicSocial Hierarchy'!D44*0.25 -> 0.32683787 | E43: ='Economic Hierarchy NO HHI'!E43*0.25+'Security Hierarchy'!E44*0.25+'Political Hierarchy'!E44*0.25+'PublicSocial Hierarchy'!E44*0.25 -> 0.55036422 | F43: ='Economic Hierarchy NO HHI'!F43*0.25+'Security Hierarchy'!F44*0.25+'Political Hierarchy'!F44*0.25+'PublicSocial Hierarchy'!F44*0.25 -> 0.09955684 | G43: ='Economic Hierarchy NO HHI'!G43*0.25+'Security Hierarchy'!G44*0.25+'Political Hierarchy'!G44*0.25+'PublicSocial Hierarchy'!G44*0.25 -> 0.1530999 | H43: ='Economic Hierarchy NO HHI'!H43*0.25+'Security Hierarchy'!H44*0.25+'Political Hierarchy'!H44*0.25+'PublicSocial Hierarchy'!H44*0.25 -> 0.13386076 | I43: ='Economic Hierarchy NO HHI'!I43*0.25+'Security Hierarchy'!I44*0.25+'Political Hierarchy'!I44*0.25+'PublicSocial Hierarchy'!I44*0.25 -> #VALUE! | ... AN43: ='Economic Hierarchy NO HHI'!AN43*0.25+'Security Hierarchy'!AN44*0.25+'Political Hierarchy'!AN44*0.25+'PublicSocial Hierarchy'!AN44*0.25 -> 0.30734085
... A58: 2017 | B58: ='Economic Hierarchy NO HHI'!B58*0.25+'Security Hierarchy'!B59*0.25+'Political Hierarchy'!B59*0.25+'PublicSocial Hierarchy'!B59*0.25 -> 0.46865628 | C58: ='Economic Hierarchy NO HHI'!C58*0.25+'Security Hierarchy'!C59*0.25+'Political Hierarchy'!C59*0.25+'PublicSocial Hierarchy'!C59*0.25 -> 0.062325578 | D58: ='Economic Hierarchy NO HHI'!D58*0.25+'Security Hierarchy'!D59*0.25+'Political Hierarchy'!D59*0.25+'PublicSocial Hierarchy'!D59*0.25 -> 0.33714276 | E58: ='Economic Hierarchy NO HHI'!E58*0.25+'Security Hierarchy'!E59*0.25+'Political Hierarchy'!E59*0.25+'PublicSocial Hierarchy'!E59*0.25 -> 0.61796676 | F58: ='Economic Hierarchy NO HHI'!F58*0.25+'Security Hierarchy'!F59*0.25+'Political Hierarchy'!F59*0.25+'PublicSocial Hierarchy'!F59*0.25 -> 0.060417023 | G58: ='Economic Hierarchy NO HHI'!G58*0.25+'Security Hierarchy'!G59*0.25+'Political Hierarchy'!G59*0.25+'PublicSocial Hierarchy'!G59*0.25 -> 0.21170063 | H58: ='Economic Hierarchy NO HHI'!H58*0.25+'Security Hierarchy'!H59*0.25+'Political Hierarchy'!H59*0.25+'PublicSocial Hierarchy'!H59*0.25 -> 0.15040803 | I58: ='Economic Hierarchy NO HHI'!I58*0.25+'Security Hierarchy'!I59*0.25+'Political Hierarchy'!I59*0.25+'PublicSocial Hierarchy'!I59*0.25 -> 0.089842256 | ... AN58: ='Economic Hierarchy NO HHI'!AN58*0.25+'Security Hierarchy'!AN59*0.25+'Political Hierarchy'!AN59*0.25+'PublicSocial Hierarchy'!AN59*0.25 -> 0.26488289
A61: China | B61: Armenia | C61: Austria | D61: Azerbaijan | E61: Belarus | F61: Belgium | G61: Bulgaria | H61: Croatia | I61: Cyprus | J61: Czech | K61: Denmark | L61: Estonia | M61: Finland | N61: France | O61: Georgia | P61: Germany | Q61: Greece | R61: Hungary | S61: Ireland | T61: Italy | U61: Kazakhstan | V61: Kyrgyzstan | W61: latvia | X61: Lithuania | Y61: Luxembourg | Z61: Malta | AA61: Moldova | AB61: Netherlands | AC61: Poland | AD61: Portugal | AE61: Romania | AF61: Slovakia | AG61: Slovenia | AH61: Spain | AI61: Sweden | AJ61: Tajikistan | AK61: Turkmenistan | AL61: UK | AM61: Ukraine | AN61: Uzbekistan
A62: 1991 | B62: ='Economic Hierarchy NO HHI'!B62*0.25+'Security Hierarchy'!B64*0.25+'Political Hierarchy'!B64*0.25+'PublicSocial Hierarchy'!B64*0.25 -> 0 | C62: ='Economic Hierarchy NO HHI'!C62*0.25+'Security Hierarchy'!C64*0.25+'Political Hierarchy'!C64*0.25+'PublicSocial Hierarchy'!C64*0.25 -> 0 | D62: ='Economic Hierarchy NO HHI'!D62*0.25+'Security Hierarchy'!D64*0.25+'Political Hierarchy'!D64*0.25+'PublicSocial Hierarchy'!D64*0.25 -> 0 | E62: ='Economic Hierarchy NO HHI'!E62*0.25+'Security Hierarchy'!E64*0.25+'Political Hierarchy'!E64*0.25+'PublicSocial Hierarchy'!E64*0.25 -> 0 | F62: ='Economic Hierarchy NO HHI'!F62*0.25+'Security Hierarchy'!F64*0.25+'Political Hierarchy'!F64*0.25+'PublicSocial Hierarchy'!F64*0.25 -> 0 | G62: ='Economic Hierarchy NO HHI'!G62*0.25+'Security Hierarchy'!G64*0.25+'Political Hierarchy'!G64*0.25+'PublicSocial Hierarchy'!G64*0.25 -> 0 | H62: ='Economic Hierarchy NO HHI'!H62*0.25+'Security Hierarchy'!H64*0.25+'Political Hierarchy'!H64*0.25+'PublicSocial Hierarchy'!H64*0.25 -> 0 | I62: ='Economic Hierarchy NO HHI'!I62*0.25+'Security Hierarchy'!I64*0.25+'Political Hierarchy'!I64*0.25+'PublicSocial Hierarchy'!I64*0.25 -> 0 | ... AN62: ='Economic Hierarchy NO HHI'!AN62*0.25+'Security Hierarchy'!AN64*0.25+'Political Hierarchy'!AN64*0.25+'PublicSocial Hierarchy'!AN64*0.25 -> 0
A63: 1992 | B63: ='Economic Hierarchy NO HHI'!B63*0.25+'Security Hierarchy'!B65*0.25+'Political Hierarchy'!B65*0.25+'PublicSocial Hierarchy'!B65*0.25 -> 0 | C63: ='Economic Hierarchy NO HHI'!C63*0.25+'Security Hierarchy'!C65*0.25+'Political Hierarchy'!C65*0.25+'PublicSocial Hierarchy'!C65*0.25 -> 0 | D63: ='Economic Hierarchy NO HHI'!D63*0.25+'Security Hierarchy'!D65*0.25+'Political Hierarchy'!D65*0.25+'PublicSocial Hierarchy'!D65*0.25 -> 0 | E63: ='Economic Hierarchy NO HHI'!E63*0.25+'Security Hierarchy'!E65*0.25+'Political Hierarchy'!E65*0.25+'PublicSocial Hierarchy'!E65*0.25 -> 0 | F63: ='Economic Hierarchy NO HHI'!F63*0.25+'Security Hierarchy'!F65*0.25+'Political Hierarchy'!F65*0.25+'PublicSocial Hierarchy'!F65*0.25 -> 0 | G63: ='Economic Hierarchy NO HHI'!G63*0.25+'Security Hierarchy'!G65*0.25+'Political Hierarchy'!G65*0.25+'PublicSocial Hierarchy'!G65*0.25 -> 0 | H63: ='Economic Hierarchy NO HHI'!H63*0.25+'Security Hierarchy'!H65*0.25+'Political Hierarchy'!H65*0.25+'PublicSocial Hierarchy'!H65*0.25 -> 0 | I63: ='Economic Hierarchy NO HHI'!I63*0.25+'Security Hierarchy'!I65*0.25+'Political Hierarchy'!I65*0.25+'PublicSocial Hierarchy'!I65*0.25 -> 0 | ... AN63: ='Economic Hierarchy NO HHI'!AN63*0.25+'Security Hierarchy'!AN65*0.25+'Political Hierarchy'!AN65*0.25+'PublicSocial Hierarchy'!AN65*0.25 -> 0
A64: 1993 | B64: ='Economic Hierarchy NO HHI'!B64*0.25+'Security Hierarchy'!B66*0.25+'Political Hierarchy'!B66*0.25+'PublicSocial Hierarchy'!B66*0.25 -> 0 | C64: ='Economic Hierarchy NO HHI'!C64*0.25+'Security Hierarchy'!C66*0.25+'Political Hierarchy'!C66*0.25+'PublicSocial Hierarchy'!C66*0.25 -> 0 | D64: ='Economic Hierarchy NO HHI'!D64*0.25+'Security Hierarchy'!D66*0.25+'Political Hierarchy'!D66*0.25+'PublicSocial Hierarchy'!D66*0.25 -> 0 | E64: ='Economic Hierarchy NO HHI'!E64*0.25+'Security Hierarchy'!E66*0.25+'Political Hierarchy'!E66*0.25+'PublicSocial Hierarchy'!E66*0.25 -> 0 | F64: ='Economic Hierarchy NO HHI'!F64*0.25+'Security Hierarchy'!F66*0.25+'Political Hierarchy'!F66*0.25+'PublicSocial Hierarchy'!F66*0.25 -> 0 | G64: ='Economic Hierarchy NO HHI'!G64*0.25+'Security Hierarchy'!G66*0.25+'Political Hierarchy'!G66*0.25+'PublicSocial Hierarchy'!G66*0.25 -> 0 | H64: ='Economic Hierarchy NO HHI'!H64*0.25+'Security Hierarchy'!H66*0.25+'Political Hierarchy'!H66*0.25+'PublicSocial Hierarchy'!H66*0.25 -> 0 | I64: ='Economic Hierarchy NO HHI'!I64*0.25+'Security Hierarchy'!I66*0.25+'Political Hierarchy'!I66*0.25+'PublicSocial Hierarchy'!I66*0.25 -> 0 | ... AN64: ='Economic Hierarchy NO HHI'!AN64*0.25+'Security Hierarchy'!AN66*0.25+'Political Hierarchy'!AN66*0.25+'PublicSocial Hierarchy'!AN66*0.25 -> 0
A65: 1994 | B65: ='Economic Hierarchy NO HHI'!B65*0.25+'Security Hierarchy'!B67*0.25+'Political Hierarchy'!B67*0.25+'PublicSocial Hierarchy'!B67*0.25 -> 0 | C65: ='Economic Hierarchy NO HHI'!C65*0.25+'Security Hierarchy'!C67*0.25+'Political Hierarchy'!C67*0.25+'PublicSocial Hierarchy'!C67*0.25 -> 0 | D65: ='Economic Hierarchy NO HHI'!D65*0.25+'Security Hierarchy'!D67*0.25+'Political Hierarchy'!D67*0.25+'PublicSocial Hierarchy'!D67*0.25 -> 0 | E65: ='Economic Hierarchy NO HHI'!E65*0.25+'Security Hierarchy'!E67*0.25+'Political Hierarchy'!E67*0.25+'PublicSocial Hierarchy'!E67*0.25 -> 0 | F65: ='Economic Hierarchy NO HHI'!F65*0.25+'Security Hierarchy'!F67*0.25+'Political Hierarchy'!F67*0.25+'PublicSocial Hierarchy'!F67*0.25 -> 0 | G65: ='Economic Hierarchy NO HHI'!G65*0.25+'Security Hierarchy'!G67*0.25+'Political Hierarchy'!G67*0.25+'PublicSocial Hierarchy'!G67*0.25 -> 0 | H65: ='Economic Hierarchy NO HHI'!H65*0.25+'Security Hierarchy'!H67*0.25+'Political Hierarchy'!H67*0.25+'PublicSocial Hierarchy'!H67*0.25 -> 0 | I65: ='Economic Hierarchy NO HHI'!I65*0.25+'Security Hierarchy'!I67*0.25+'Political Hierarchy'!I67*0.25+'PublicSocial Hierarchy'!I67*0.25 -> 0 | ... AN65: ='Economic Hierarchy NO HHI'!AN65*0.25+'Security Hierarchy'!AN67*0.25+'Political Hierarchy'!AN67*0.25+'PublicSocial Hierarchy'!AN67*0.25 -> 0
A66: 1995 | B66: ='Economic Hierarchy NO HHI'!B66*0.25+'Security Hierarchy'!B68*0.25+'Political Hierarchy'!B68*0.25+'PublicSocial Hierarchy'!B68*0.25 -> 0 | C66: ='Economic Hierarchy NO HHI'!C66*0.25+'Security Hierarchy'!C68*0.25+'Political Hierarchy'!C68*0.25+'PublicSocial Hierarchy'!C68*0.25 -> 0 | D66: ='Economic Hierarchy NO HHI'!D66*0.25+'Security Hierarchy'!D68*0.25+'Political Hierarchy'!D68*0.25+'PublicSocial Hierarchy'!D68*0.25 -> 0 | E66: ='Economic Hierarchy NO HHI'!E66*0.25+'Security Hierarchy'!E68*0.25+'Political Hierarchy'!E68*0.25+'PublicSocial Hierarchy'!E68*0.25 -> 0 | F66: ='Economic Hierarchy NO HHI'!F66*0.25+'Security Hierarchy'!F68*0.25+'Political Hierarchy'!F68*0.25+'PublicSocial Hierarchy'!F68*0.25 -> 0 | G66: ='Economic Hierarchy NO HHI'!G66*0.25+'Security Hierarchy'!G68*0.25+'Political Hierarchy'!G68*0.25+'PublicSocial Hierarchy'!G68*0.25 -> 0 | H66: ='Economic Hierarchy NO HHI'!H66*0.25+'Security Hierarchy'!H68*0.25+'Political Hierarchy'!H68*0.25+'PublicSocial Hierarchy'!H68*0.25 -> 0 | I66: ='Economic Hierarchy NO HHI'!I66*0.25+'Security Hierarchy'!I68*0.25+'Political Hierarchy'!I68*0.25+'PublicSocial Hierarchy'!I68*0.25 -> 0 | ... AN66: ='Economic Hierarchy NO HHI'!AN66*0.25+'Security Hierarchy'!AN68*0.25+'Political Hierarchy'!AN68*0.25+'PublicSocial Hierarchy'!AN68*0.25 -> 0
A67: 1996 | B67: ='Economic Hierarchy NO HHI'!B67*0.25+'Security Hierarchy'!B69*0.25+'Political Hierarchy'!B69*0.25+'PublicSocial Hierarchy'!B69*0.25 -> 0 | C67: ='Economic Hierarchy NO HHI'!C67*0.25+'Security Hierarchy'!C69*0.25+'Political Hierarchy'!C69*0.25+'PublicSocial Hierarchy'!C69*0.25 -> 0 | D67: ='Economic Hierarchy NO HHI'!D67*0.25+'Security Hierarchy'!D69*0.25+'Political Hierarchy'!D69*0.25+'PublicSocial Hierarchy'!D69*0.25 -> 0 | E67: ='Economic Hierarchy NO HHI'!E67*0.25+'Security Hierarchy'!E69*0.25+'Political Hierarchy'!E69*0.25+'PublicSocial Hierarchy'!E69*0.25 -> 0 | F67: ='Economic Hierarchy NO HHI'!F67*0.25+'Security Hierarchy'!F69*0.25+'Political Hierarchy'!F69*0.25+'PublicSocial Hierarchy'!F69*0.25 -> 0 | G67: ='Economic Hierarchy NO HHI'!G67*0.25+'Security Hierarchy'!G69*0.25+'Political Hierarchy'!G69*0.25+'PublicSocial Hierarchy'!G69*0.25 -> 0 | H67: ='Economic Hierarchy NO HHI'!H67*0.25+'Security Hierarchy'!H69*0.25+'Political Hierarchy'!H69*0.25+'PublicSocial Hierarchy'!H69*0.25 -> 0 | I67: ='Economic Hierarchy NO HHI'!I67*0.25+'Security Hierarchy'!I69*0.25+'Political Hierarchy'!I69*0.25+'PublicSocial Hierarchy'!I69*0.25 -> 0 | ... AN67: ='Economic Hierarchy NO HHI'!AN67*0.25+'Security Hierarchy'!AN69*0.25+'Political Hierarchy'!AN69*0.25+'PublicSocial Hierarchy'!AN69*0.25 -> 0
A68: 1997 | B68: ='Economic Hierarchy NO HHI'!B68*0.25+'Security Hierarchy'!B70*0.25+'Political Hierarchy'!B70*0.25+'PublicSocial Hierarchy'!B70*0.25 -> 0 | C68: ='Economic Hierarchy NO HHI'!C68*0.25+'Security Hierarchy'!C70*0.25+'Political Hierarchy'!C70*0.25+'PublicSocial Hierarchy'!C70*0.25 -> 0 | D68: ='Economic Hierarchy NO HHI'!D68*0.25+'Security Hierarchy'!D70*0.25+'Political Hierarchy'!D70*0.25+'PublicSocial Hierarchy'!D70*0.25 -> 0 | E68: ='Economic Hierarchy NO HHI'!E68*0.25+'Security Hierarchy'!E70*0.25+'Political Hierarchy'!E70*0.25+'PublicSocial Hierarchy'!E70*0.25 -> 0 | F68: ='Economic Hierarchy NO HHI'!F68*0.25+'Security Hierarchy'!F70*0.25+'Political Hierarchy'!F70*0.25+'PublicSocial Hierarchy'!F70*0.25 -> 0 | G68: ='Economic Hierarchy NO HHI'!G68*0.25+'Security Hierarchy'!G70*0.25+'Political Hierarchy'!G70*0.25+'PublicSocial Hierarchy'!G70*0.25 -> 0 | H68: ='Economic Hierarchy NO HHI'!H68*0.25+'Security Hierarchy'!H70*0.25+'Political Hierarchy'!H70*0.25+'PublicSocial Hierarchy'!H70*0.25 -> 0 | I68: ='Economic Hierarchy NO HHI'!I68*0.25+'Security Hierarchy'!I70*0.25+'Political Hierarchy'!I70*0.25+'PublicSocial Hierarchy'!I70*0.25 -> 0 | ... AN68: ='Economic Hierarchy NO HHI'!AN68*0.25+'Security Hierarchy'!AN70*0.25+'Political Hierarchy'!AN70*0.25+'PublicSocial Hierarchy'!AN70*0.25 -> 0
A69: 1998 | B69: ='Economic Hierarchy NO HHI'!B69*0.25+'Security Hierarchy'!B71*0.25+'Political Hierarchy'!B71*0.25+'PublicSocial Hierarchy'!B71*0.25 -> 0 | C69: ='Economic Hierarchy NO HHI'!C69*0.25+'Security Hierarchy'!C71*0.25+'Political Hierarchy'!C71*0.25+'PublicSocial Hierarchy'!C71*0.25 -> 0 | D69: ='Economic Hierarchy NO HHI'!D69*0.25+'Security Hierarchy'!D71*0.25+'Political Hierarchy'!D71*0.25+'PublicSocial Hierarchy'!D71*0.25 -> 0 | E69: ='Economic Hierarchy NO HHI'!E69*0.25+'Security Hierarchy'!E71*0.25+'Political Hierarchy'!E71*0.25+'PublicSocial Hierarchy'!E71*0.25 -> 0 | F69: ='Economic Hierarchy NO HHI'!F69*0.25+'Security Hierarchy'!F71*0.25+'Political Hierarchy'!F71*0.25+'PublicSocial Hierarchy'!F71*0.25 -> 0 | G69: ='Economic Hierarchy NO HHI'!G69*0.25+'Security Hierarchy'!G71*0.25+'Political Hierarchy'!G71*0.25+'PublicSocial Hierarchy'!G71*0.25 -> 0 | H69: ='Economic Hierarchy NO HHI'!H69*0.25+'Security Hierarchy'!H71*0.25+'Political Hierarchy'!H71*0.25+'PublicSocial Hierarchy'!H71*0.25 -> 0 | I69: ='Economic Hierarchy NO HHI'!I69*0.25+'Security Hierarchy'!I71*0.25+'Political Hierarchy'!I71*0.25+'PublicSocial Hierarchy'!I71*0.25 -> 0 | ... AN69: ='Economic Hierarchy NO HHI'!AN69*0.25+'Security Hierarchy'!AN71*0.25+'Political Hierarchy'!AN71*0.25+'PublicSocial Hierarchy'!AN71*0.25 -> 0
A70: 1999 | B70: ='Economic Hierarchy NO HHI'!B70*0.25+'Security Hierarchy'!B72*0.25+'Political Hierarchy'!B72*0.25+'PublicSocial Hierarchy'!B72*0.25 -> 0 | C70: ='Economic Hierarchy NO HHI'!C70*0.25+'Security Hierarchy'!C72*0.25+'Political Hierarchy'!C72*0.25+'PublicSocial Hierarchy'!C72*0.25 -> 0 | D70: ='Economic Hierarchy NO HHI'!D70*0.25+'Security Hierarchy'!D72*0.25+'Political Hierarchy'!D72*0.25+'PublicSocial Hierarchy'!D72*0.25 -> 0 | E70: ='Economic Hierarchy NO HHI'!E70*0.25+'Security Hierarchy'!E72*0.25+'Political Hierarchy'!E72*0.25+'PublicSocial Hierarchy'!E72*0.25 -> 0 | F70: ='Economic Hierarchy NO HHI'!F70*0.25+'Security Hierarchy'!F72*0.25+'Political Hierarchy'!F72*0.25+'PublicSocial Hierarchy'!F72*0.25 -> 0 | G70: ='Economic Hierarchy NO HHI'!G70*0.25+'Security Hierarchy'!G72*0.25+'Political Hierarchy'!G72*0.25+'PublicSocial Hierarchy'!G72*0.25 -> 0 | H70: ='Economic Hierarchy NO HHI'!H70*0.25+'Security Hierarchy'!H72*0.25+'Political Hierarchy'!H72*0.25+'PublicSocial Hierarchy'!H72*0.25 -> 0 | I70: ='Economic Hierarchy NO HHI'!I70*0.25+'Security Hierarchy'!I72*0.25+'Political Hierarchy'!I72*0.25+'PublicSocial Hierarchy'!I72*0.25 -> 0 | ... AN70: ='Economic Hierarchy NO HHI'!AN70*0.25+'Security Hierarchy'!AN72*0.25+'Political Hierarchy'!AN72*0.25+'PublicSocial Hierarchy'!AN72*0.25 -> 0
A71: 2000 | B71: ='Economic Hierarchy NO HHI'!B71*0.25+'Security Hierarchy'!B73*0.25+'Political Hierarchy'!B73*0.25+'PublicSocial Hierarchy'!B73*0.25 -> 0.00105 | C71: ='Economic Hierarchy NO HHI'!C71*0.25+'Security Hierarchy'!C73*0.25+'Political Hierarchy'!C73*0.25+'PublicSocial Hierarchy'!C73*0.25 -> 0.0023417481 | D71: ='Economic Hierarchy NO HHI'!D71*0.25+'Security Hierarchy'!D73*0.25+'Political Hierarchy'!D73*0.25+'PublicSocial Hierarchy'!D73*0.25 -> 0.0022 | E71: ='Economic Hierarchy NO HHI'!E71*0.25+'Security Hierarchy'!E73*0.25+'Political Hierarchy'!E73*0.25+'PublicSocial Hierarchy'!E73*0.25 -> 0.00345 | F71: ='Economic Hierarchy NO HHI'!F71*0.25+'Security Hierarchy'!F73*0.25+'Political Hierarchy'!F73*0.25+'PublicSocial Hierarchy'!F73*0.25 -> 0.0034297051 | G71: ='Economic Hierarchy NO HHI'!G71*0.25+'Security Hierarchy'!G73*0.25+'Political Hierarchy'!G73*0.25+'PublicSocial Hierarchy'!G73*0.25 -> 0.0015930082 | H71: ='Economic Hierarchy NO HHI'!H71*0.25+'Security Hierarchy'!H73*0.25+'Political Hierarchy'!H73*0.25+'PublicSocial Hierarchy'!H73*0.25 -> 0.0015037083 | I71: ='Economic Hierarchy NO HHI'!I71*0.25+'Security Hierarchy'!I73*0.25+'Political Hierarchy'!I73*0.25+'PublicSocial Hierarchy'!I73*0.25 -> 0.0049265839 | ... AN71: ='Economic Hierarchy NO HHI'!AN71*0.25+'Security Hierarchy'!AN73*0.25+'Political Hierarchy'!AN73*0.25+'PublicSocial Hierarchy'!AN73*0.25 -> 0.0036375
A72: 2001 | B72: ='Economic Hierarchy NO HHI'!B72*0.25+'Security Hierarchy'!B74*0.25+'Political Hierarchy'!B74*0.25+'PublicSocial Hierarchy'!B74*0.25 -> 0.0005875 | C72: ='Economic Hierarchy NO HHI'!C72*0.25+'Security Hierarchy'!C74*0.25+'Political Hierarchy'!C74*0.25+'PublicSocial Hierarchy'!C74*0.25 -> 0.0029537691 | D72: ='Economic Hierarchy NO HHI'!D72*0.25+'Security Hierarchy'!D74*0.25+'Political Hierarchy'!D74*0.25+'PublicSocial Hierarchy'!D74*0.25 -> 0.0032875 | E72: ='Economic Hierarchy NO HHI'!E72*0.25+'Security Hierarchy'!E74*0.25+'Political Hierarchy'!E74*0.25+'PublicSocial Hierarchy'!E74*0.25 -> 0.00345 | F72: ='Economic Hierarchy NO HHI'!F72*0.25+'Security Hierarchy'!F74*0.25+'Political Hierarchy'!F74*0.25+'PublicSocial Hierarchy'!F74*0.25 -> 0.0036986859 | G72: ='Economic Hierarchy NO HHI'!G72*0.25+'Security Hierarchy'!G74*0.25+'Political Hierarchy'!G74*0.25+'PublicSocial Hierarchy'!G74*0.25 -> 0.0017389157 | H72: ='Economic Hierarchy NO HHI'!H72*0.25+'Security Hierarchy'!H74*0.25+'Political Hierarchy'!H74*0.25+'PublicSocial Hierarchy'!H74*0.25 -> 0.0020271098 | I72: ='Economic Hierarchy NO HHI'!I72*0.25+'Security Hierarchy'!I74*0.25+'Political Hierarchy'!I74*0.25+'PublicSocial Hierarchy'!I74*0.25 -> 0.0050638959 | ... AN72: ='Economic Hierarchy NO HHI'!AN72*0.25+'Security Hierarchy'!AN74*0.25+'Political Hierarchy'!AN74*0.25+'PublicSocial Hierarchy'!AN74*0.25 -> 0.0037
...

Sheet Security Model
A1: US | B1: Armenia | C1: Austria | D1: Azerbaijan | E1: Belarus | F1: Belgium | G1: Bulgaria | H1: Croatia | I1: Cyprus | J1: Czech | K1: Denmark | L1: Estonia | M1: Finland | N1: France | O1: Georgia | P1: Germany | Q1: Greece | R1: Hungary | S1: Ireland | T1: Italy | U1: Kazakhstan | V1: Kyrgyzstan | W1: latvia | X1: Lithuania | Y1: Luxembourg | Z1: Malta | AA1: Moldova | AB1: Netherlands | AC1: Poland | AD1: Portugal | AE1: Romania | AF1: Slovakia | AG1: Slovenia | AH1: Spain | AI1: Sweden | AJ1: Tajikistan | AK1: Turkmenistan | AL1: UK | AM1: Ukraine | AN1: Uzbekistan
A2: 1991 | B2: ='Economic Hierarchy NO HHI'!B2*(1/6)+'Security Hierarchy'!B2*0.5+'Political Hierarchy'!B2*(1/6)+'PublicSocial Hierarchy'!B2*(1/6) -> 0 | C2: ='Economic Hierarchy NO HHI'!C2*(1/6)+'Security Hierarchy'!C2*0.5+'Political Hierarchy'!C2*(1/6)+'PublicSocial Hierarchy'!C2*(1/6) -> 0 | D2: ='Economic Hierarchy NO HHI'!D2*(1/6)+'Security Hierarchy'!D2*0.5+'Political Hierarchy'!D2*(1/6)+'PublicSocial Hierarchy'!D2*(1/6) -> 0 | E2: ='Economic Hierarchy NO HHI'!E2*(1/6)+'Security Hierarchy'!E2*0.5+'Political Hierarchy'!E2*(1/6)+'PublicSocial Hierarchy'!E2*(1/6) -> 0 | F2: ='Economic Hierarchy NO HHI'!F2*(1/6)+'Security Hierarchy'!F2*0.5+'Political Hierarchy'!F2*(1/6)+'PublicSocial Hierarchy'!F2*(1/6) -> 0.33333333 | G2: ='Economic Hierarchy NO HHI'!G2*(1/6)+'Security Hierarchy'!G2*0.5+'Political Hierarchy'!G2*(1/6)+'PublicSocial Hierarchy'!G2*(1/6) -> 0 | H2: ='Economic Hierarchy NO HHI'!H2*(1/6)+'Security Hierarchy'!H2*0.5+'Political Hierarchy'!H2*(1/6)+'PublicSocial Hierarchy'!H2*(1/6) -> 0 | I2: ='Economic Hierarchy NO HHI'!I2*(1/6)+'Security Hierarchy'!I2*0.5+'Political Hierarchy'!I2*(1/6)+'PublicSocial Hierarchy'!I2*(1/6) -> 0 | ... AN2: ='Economic Hierarchy NO HHI'!AN2*(1/6)+'Security Hierarchy'!AN2*0.5+'Political Hierarchy'!AN2*(1/6)+'PublicSocial Hierarchy'!AN2*(1/6) -> 0
A3: 1992 | B3: ='Economic Hierarchy NO HHI'!B3*(1/6)+'Security Hierarchy'!B3*0.5+'Political Hierarchy'!B3*(1/6)+'PublicSocial Hierarchy'!B3*(1/6) -> 0 | C3: ='Economic Hierarchy NO HHI'!C3*(1/6)+'Security Hierarchy'!C3*0.5+'Political Hierarchy'!C3*(1/6)+'PublicSocial Hierarchy'!C3*(1/6) -> 0.16666667 | D3: ='Economic Hierarchy NO HHI'!D3*(1/6)+'Security Hierarchy'!D3*0.5+'Political Hierarchy'!D3*(1/6)+'PublicSocial Hierarchy'!D3*(1/6) -> 0 | E3: ='Economic Hierarchy NO HHI'!E3*(1/6)+'Security Hierarchy'!E3*0.5+'Political Hierarchy'!E3*(1/6)+'PublicSocial Hierarchy'!E3*(1/6) -> 0 | F3: ='Economic Hierarchy NO HHI'!F3*(1/6)+'Security Hierarchy'!F3*0.5+'Political Hierarchy'!F3*(1/6)+'PublicSocial Hierarchy'!F3*(1/6) -> 0.33333333 | G3: ='Economic Hierarchy NO HHI'!G3*(1/6)+'Security Hierarchy'!G3*0.5+'Political Hierarchy'!G3*(1/6)+'PublicSocial Hierarchy'!G3*(1/6) -> 0 | H3: ='Economic Hierarchy NO HHI'!H3*(1/6)+'Security Hierarchy'!H3*0.5+'Political Hierarchy'!H3*(1/6)+'PublicSocial Hierarchy'!H3*(1/6) -> 0 | I3: ='Economic Hierarchy NO HHI'!I3*(1/6)+'Security Hierarchy'!I3*0.5+'Political Hierarchy'!I3*(1/6)+'PublicSocial Hierarchy'!I3*(1/6) -> 0 | ... AN3: ='Economic Hierarchy NO HHI'!AN3*(1/6)+'Security Hierarchy'!AN3*0.5+'Political Hierarchy'!AN3*(1/6)+'PublicSocial Hierarchy'!AN3*(1/6) -> 0
A4: 1993 | B4: ='Economic Hierarchy NO HHI'!B4*(1/6)+'Security Hierarchy'!B4*0.5+'Political Hierarchy'!B4*(1/6)+'PublicSocial Hierarchy'!B4*(1/6) -> 0 | C4: ='Economic Hierarchy NO HHI'!C4*(1/6)+'Security Hierarchy'!C4*0.5+'Political Hierarchy'!C4*(1/6)+'PublicSocial Hierarchy'!C4*(1/6) -> 0 | D4: ='Economic Hierarchy NO HHI'!D4*(1/6)+'Security Hierarchy'!D4*0.5+'Political Hierarchy'!D4*(1/6)+'PublicSocial Hierarchy'!D4*(1/6) -> 0 | E4: ='Economic Hierarchy NO HHI'!E4*(1/6)+'Security Hierarchy'!E4*0.5+'Political Hierarchy'!E4*(1/6)+'PublicSocial Hierarchy'!E4*(1/6) -> 0 | F4: ='Economic Hierarchy NO HHI'!F4*(1/6)+'Security Hierarchy'!F4*0.5+'Political Hierarchy'!F4*(1/6)+'PublicSocial Hierarchy'!F4*(1/6) -> 0.5 | G4: ='Economic Hierarchy NO HHI'!G4*(1/6)+'Security Hierarchy'!G4*0.5+'Political Hierarchy'!G4*(1/6)+'PublicSocial Hierarchy'!G4*(1/6) -> 0 | H4: ='Economic Hierarchy NO HHI'!H4*(1/6)+'Security Hierarchy'!H4*0.5+'Political Hierarchy'!H4*(1/6)+'PublicSocial Hierarchy'!H4*(1/6) -> 0 | I4: ='Economic Hierarchy NO HHI'!I4*(1/6)+'Security Hierarchy'!I4*0.5+'Political Hierarchy'!I4*(1/6)+'PublicSocial Hierarchy'!I4*(1/6) -> 0 | ... AN4: ='Economic Hierarchy NO HHI'!AN4*(1/6)+'Security Hierarchy'!AN4*0.5+'Political Hierarchy'!AN4*(1/6)+'PublicSocial Hierarchy'!AN4*(1/6) -> 0
A5: 1994 | B5: ='Economic Hierarchy NO HHI'!B5*(1/6)+'Security Hierarchy'!B5*0.5+'Political Hierarchy'!B5*(1/6)+'PublicSocial Hierarchy'!B5*(1/6) -> 0 | C5: ='Economic Hierarchy NO HHI'!C5*(1/6)+'Security Hierarchy'!C5*0.5+'Political Hierarchy'!C5*(1/6)+'PublicSocial Hierarchy'!C5*(1/6) -> 0 | D5: ='Economic Hierarchy NO HHI'!D5*(1/6)+'Security Hierarchy'!D5*0.5+'Political Hierarchy'!D5*(1/6)+'PublicSocial Hierarchy'!D5*(1/6) -> 0 | E5: ='Economic Hierarchy NO HHI'!E5*(1/6)+'Security Hierarchy'!E5*0.5+'Political Hierarchy'!E5*(1/6)+'PublicSocial Hierarchy'!E5*(1/6) -> 0 | F5: ='Economic Hierarchy NO HHI'!F5*(1/6)+'Security Hierarchy'!F5*0.5+'Political Hierarchy'!F5*(1/6)+'PublicSocial Hierarchy'!F5*(1/6) -> 0.33333333 | G5: ='Economic Hierarchy NO HHI'!G5*(1/6)+'Security Hierarchy'!G5*0.5+'Political Hierarchy'!G5*(1/6)+'PublicSocial Hierarchy'!G5*(1/6) -> 0 | H5: ='Economic Hierarchy NO HHI'!H5*(1/6)+'Security Hierarchy'!H5*0.5+'Political Hierarchy'!H5*(1/6)+'PublicSocial Hierarchy'!H5*(1/6) -> 0 | I5: ='Economic Hierarchy NO HHI'!I5*(1/6)+'Security Hierarchy'!I5*0.5+'Political Hierarchy'!I5*(1/6)+'PublicSocial Hierarchy'!I5*(1/6) -> 0 | ... AN5: ='Economic Hierarchy NO HHI'!AN5*(1/6)+'Security Hierarchy'!AN5*0.5+'Political Hierarchy'!AN5*(1/6)+'PublicSocial Hierarchy'!AN5*(1/6) -> 0
A6: 1995 | B6: ='Economic Hierarchy NO HHI'!B6*(1/6)+'Security Hierarchy'!B6*0.5+'Political Hierarchy'!B6*(1/6)+'PublicSocial Hierarchy'!B6*(1/6) -> 0 | C6: ='Economic Hierarchy NO HHI'!C6*(1/6)+'Security Hierarchy'!C6*0.5+'Political Hierarchy'!C6*(1/6)+'PublicSocial Hierarchy'!C6*(1/6) -> 0.16666667 | D6: ='Economic Hierarchy NO HHI'!D6*(1/6)+'Security Hierarchy'!D6*0.5+'Political Hierarchy'!D6*(1/6)+'PublicSocial Hierarchy'!D6*(1/6) -> 0 | E6: ='Economic Hierarchy NO HHI'!E6*(1/6)+'Security Hierarchy'!E6*0.5+'Political Hierarchy'!E6*(1/6)+'PublicSocial Hierarchy'!E6*(1/6) -> 0 | F6: ='Economic Hierarchy NO HHI'!F6*(1/6)+'Security Hierarchy'!F6*0.5+'Political Hierarchy'!F6*(1/6)+'PublicSocial Hierarchy'!F6*(1/6) -> 0.5 | G6: ='Economic Hierarchy NO HHI'!G6*(1/6)+'Security Hierarchy'!G6*0.5+'Political Hierarchy'!G6*(1/6)+'PublicSocial Hierarchy'!G6*(1/6) -> 0 | H6: ='Economic Hierarchy NO HHI'!H6*(1/6)+'Security Hierarchy'!H6*0.5+'Political Hierarchy'!H6*(1/6)+'PublicSocial Hierarchy'!H6*(1/6) -> 0 | I6: ='Economic Hierarchy NO HHI'!I6*(1/6)+'Security Hierarchy'!I6*0.5+'Political Hierarchy'!I6*(1/6)+'PublicSocial Hierarchy'!I6*(1/6) -> 0 | ... AN6: ='Economic Hierarchy NO HHI'!AN6*(1/6)+'Security Hierarchy'!AN6*0.5+'Political Hierarchy'!AN6*(1/6)+'PublicSocial Hierarchy'!AN6*(1/6) -> 0
