Workbook

Sheet Political Hierarchy
A1: US | B1: Armenia | C1: Austria | D1: Azerbaijan | E1: Belarus | F1: Belgium | G1: Bulgaria | H1: Croatia | I1: Cyprus | J1: Czech | K1: Denmark | L1: Estonia | M1: Finland | N1: France | O1: Georgia | P1: Germany | Q1: Greece | R1: Hungary | S1: Ireland | T1: Italy | U1: Kazakhstan | V1: Kyrgyzstan | W1: latvia | X1: Lithuania | Y1: Luxembourg | Z1: Malta | AA1: Moldova | AB1: Netherlands | AC1: Poland | AD1: Portugal | AE1: Romania | AF1: Slovakia | AG1: Slovenia | AH1: Spain | AI1: Sweden | AJ1: Tajikistan | AK1: Turkmenistan | AL1: Ukraine | AM1: UK | AN1: Uzbekistan
A2: 1991
A3: 1992
A4: 1993
A5: 1994
A6: 1995
A7: 1996
A8: 1997
A9: 1998
A10: 1999
A11: 2000
A12: 2001
A13: 2002
A14: 2003 | B14: ='UNGA Voting'!B14*(1/2)+'HeadofState Meetings'!B14*(1/2) -> 0.095 | C14: ='UNGA Voting'!C14*(1/2)+'HeadofState Meetings'!C14*(1/2) -> 0.1644737 | D14: ='UNGA Voting'!D14*(1/2)+'HeadofState Meetings'!D14*(1/2) -> 0.32 | E14: ='UNGA Voting'!E14*(1/2)+'HeadofState Meetings'!E14*(1/2) -> 0.075 | F14: ='UNGA Voting'!F14*(1/2)+'HeadofState Meetings'!F14*(1/2) -> 0.19333335 | G14: ='UNGA Voting'!G14*(1/2)+'HeadofState Meetings'!G14*(1/2) -> 0.43421055 | H14: ='UNGA Voting'!H14*(1/2)+'HeadofState Meetings'!H14*(1/2) -> 0.1644737 | I14: ='UNGA Voting'!I14*(1/2)+'HeadofState Meetings'!I14*(1/2) -> 0.15789475 | ... AN14: ='UNGA Voting'!AN14*(1/2)+'HeadofState Meetings'!AN14*(1/2) -> 0.105
A15: 2004 | B15: ='UNGA Voting'!B15*(1/2)+'HeadofState Meetings'!B15*(1/2) -> 0.08 | C15: ='UNGA Voting'!C15*(1/2)+'HeadofState Meetings'!C15*(1/2) -> 0.17605635 | D15: ='UNGA Voting'!D15*(1/2)+'HeadofState Meetings'!D15*(1/2) -> 0.06 | E15: ='UNGA Voting'!E15*(1/2)+'HeadofState Meetings'!E15*(1/2) -> 0.03 | F15: ='UNGA Voting'!F15*(1/2)+'HeadofState Meetings'!F15*(1/2) -> 0.42391305 | G15: ='UNGA Voting'!G15*(1/2)+'HeadofState Meetings'!G15*(1/2) -> 0.67605635 | H15: ='UNGA Voting'!H15*(1/2)+'HeadofState Meetings'!H15*(1/2) -> 0.42605635 | I15: ='UNGA Voting'!I15*(1/2)+'HeadofState Meetings'!I15*(1/2) -> 0.1690141 | ... AN15: ='UNGA Voting'!AN15*(1/2)+'HeadofState Meetings'!AN15*(1/2) -> 0.05
A16: 2005 | B16: ='UNGA Voting'!B16*(1/2)+'HeadofState Meetings'!B16*(1/2) -> 0.07 | C16: ='UNGA Voting'!C16*(1/2)+'HeadofState Meetings'!C16*(1/2) -> 0.40753425 | D16: ='UNGA Voting'!D16*(1/2)+'HeadofState Meetings'!D16*(1/2) -> 0.05 | E16: ='UNGA Voting'!E16*(1/2)+'HeadofState Meetings'!E16*(1/2) -> 0.05 | F16: ='UNGA Voting'!F16*(1/2)+'HeadofState Meetings'!F16*(1/2) -> 0.41438355 | G16: ='UNGA Voting'!G16*(1/2)+'HeadofState Meetings'!G16*(1/2) -> 0.66438355 | H16: ='UNGA Voting'!H16*(1/2)+'HeadofState Meetings'!H16*(1/2) -> 0.15753425 | I16: ='UNGA Voting'!I16*(1/2)+'HeadofState Meetings'!I16*(1/2) -> 0.15068495 | ... AN16: ='UNGA Voting'!AN16*(1/2)+'HeadofState Meetings'!AN16*(1/2) -> 0.04
A17: 2006 | B17: ='UNGA Voting'!B17*(1/2)+'HeadofState Meetings'!B17*(1/2) -> 0.045 | C17: ='UNGA Voting'!C17*(1/2)+'HeadofState Meetings'!C17*(1/2) -> 0.36494255 | D17: ='UNGA Voting'!D17*(1/2)+'HeadofState Meetings'!D17*(1/2) -> 0.29 | E17: ='UNGA Voting'!E17*(1/2)+'HeadofState Meetings'!E17*(1/2) -> 0.035 | F17: ='UNGA Voting'!F17*(1/2)+'HeadofState Meetings'!F17*(1/2) -> 0.622093 | G17: ='UNGA Voting'!G17*(1/2)+'HeadofState Meetings'!G17*(1/2) -> 0.3821839 | H17: ='UNGA Voting'!H17*(1/2)+'HeadofState Meetings'!H17*(1/2) -> 0.37068965 | I17: ='UNGA Voting'!I17*(1/2)+'HeadofState Meetings'!I17*(1/2) -> 0.11764705 | ... AN17: ='UNGA Voting'!AN17*(1/2)+'HeadofState Meetings'!AN17*(1/2) -> 0.035
A18: 2007 | B18: ='UNGA Voting'!B18*(1/2)+'HeadofState Meetings'!B18*(1/2) -> 0.06 | C18: ='UNGA Voting'!C18*(1/2)+'HeadofState Meetings'!C18*(1/2) -> 0.13636365 | D18: ='UNGA Voting'!D18*(1/2)+'HeadofState Meetings'!D18*(1/2) -> 0.035 | E18: ='UNGA Voting'!E18*(1/2)+'HeadofState Meetings'!E18*(1/2) -> 0.025 | F18: ='UNGA Voting'!F18*(1/2)+'HeadofState Meetings'!F18*(1/2) -> 0.14935065 | G18: ='UNGA Voting'!G18*(1/2)+'HeadofState Meetings'!G18*(1/2) -> 0.39285715 | H18: ='UNGA Voting'!H18*(1/2)+'HeadofState Meetings'!H18*(1/2) -> 0.14473685 | I18: ='UNGA Voting'!I18*(1/2)+'HeadofState Meetings'!I18*(1/2) -> 0.14285715 | ... AN18: ='UNGA Voting'!AN18*(1/2)+'HeadofState Meetings'!AN18*(1/2) -> 0.035
A19: 2008 | B19: ='UNGA Voting'!B19*(1/2)+'HeadofState Meetings'!B19*(1/2) -> 0.055 | C19: ='UNGA Voting'!C19*(1/2)+'HeadofState Meetings'!C19*(1/2) -> 0.125 | D19: ='UNGA Voting'!D19*(1/2)+'HeadofState Meetings'!D19*(1/2) -> 0.035 | E19: ='UNGA Voting'!E19*(1/2)+'HeadofState Meetings'!E19*(1/2) -> 0.03 | F19: ='UNGA Voting'!F19*(1/2)+'HeadofState Meetings'!F19*(1/2) -> 0.38194445 | G19: ='UNGA Voting'!G19*(1/2)+'HeadofState Meetings'!G19*(1/2) -> 0.6338028 | H19: ='UNGA Voting'!H19*(1/2)+'HeadofState Meetings'!H19*(1/2) -> 0.38194445 | I19: ='UNGA Voting'!I19*(1/2)+'HeadofState Meetings'!I19*(1/2) -> 0.13194445 | ... AN19: ='UNGA Voting'!AN19*(1/2)+'HeadofState Meetings'!AN19*(1/2) -> 0.03
A20: 2009 | B20: ='UNGA Voting'!B20*(1/2)+'HeadofState Meetings'!B20*(1/2) -> 0.09 | C20: ='UNGA Voting'!C20*(1/2)+'HeadofState Meetings'!C20*(1/2) -> 0.19402985 | D20: ='UNGA Voting'!D20*(1/2)+'HeadofState Meetings'!D20*(1/2) -> 0.055 | E20: ='UNGA Voting'!E20*(1/2)+'HeadofState Meetings'!E20*(1/2) -> 0.04 | F20: ='UNGA Voting'!F20*(1/2)+'HeadofState Meetings'!F20*(1/2) -> 0.4589552 | G20: ='UNGA Voting'!G20*(1/2)+'HeadofState Meetings'!G20*(1/2) -> 0.4621212 | H20: ='UNGA Voting'!H20*(1/2)+'HeadofState Meetings'!H20*(1/2) -> 0.4469697 | I20: ='UNGA Voting'!I20*(1/2)+'HeadofState Meetings'!I20*(1/2) -> 0.19402985 | ... AN20: ='UNGA Voting'!AN20*(1/2)+'HeadofState Meetings'!AN20*(1/2) -> 0.05
A21: 2010 | B21: ='UNGA Voting'!B21*(1/2)+'HeadofState Meetings'!B21*(1/2) -> 0.33 | C21: ='UNGA Voting'!C21*(1/2)+'HeadofState Meetings'!C21*(1/2) -> 0.4242424 | D21: ='UNGA Voting'!D21*(1/2)+'HeadofState Meetings'!D21*(1/2) -> 0.305 | E21: ='UNGA Voting'!E21*(1/2)+'HeadofState Meetings'!E21*(1/2) -> 0.055 | F21: ='UNGA Voting'!F21*(1/2)+'HeadofState Meetings'!F21*(1/2) -> 0.6969697 | G21: ='UNGA Voting'!G21*(1/2)+'HeadofState Meetings'!G21*(1/2) -> 0.4423077 | H21: ='UNGA Voting'!H21*(1/2)+'HeadofState Meetings'!H21*(1/2) -> 0.4269231 | I21: ='UNGA Voting'!I21*(1/2)+'HeadofState Meetings'!I21*(1/2) -> 0.1742424 | ... AN21: ='UNGA Voting'!AN21*(1/2)+'HeadofState Meetings'!AN21*(1/2) -> 0.055
A22: 2011 | B22: ='UNGA Voting'!B22*(1/2)+'HeadofState Meetings'!B22*(1/2) -> 0.12 | C22: ='UNGA Voting'!C22*(1/2)+'HeadofState Meetings'!C22*(1/2) -> 0.23076925 | D22: ='UNGA Voting'!D22*(1/2)+'HeadofState Meetings'!D22*(1/2) -> 0.095 | E22: ='UNGA Voting'!E22*(1/2)+'HeadofState Meetings'!E22*(1/2) -> 0.065 | F22: ='UNGA Voting'!F22*(1/2)+'HeadofState Meetings'!F22*(1/2) -> 0.25384615 | G22: ='UNGA Voting'!G22*(1/2)+'HeadofState Meetings'!G22*(1/2) -> 0.25 | H22: ='UNGA Voting'!H22*(1/2)+'HeadofState Meetings'!H22*(1/2) -> 0.26271185 | I22: ='UNGA Voting'!I22*(1/2)+'HeadofState Meetings'!I22*(1/2) -> 0.23846155 | ... AN22: ='UNGA Voting'!AN22*(1/2)+'HeadofState Meetings'!AN22*(1/2) -> 0.07
A23: 2012 | B23: ='UNGA Voting'!B23*(1/2)+'HeadofState Meetings'!B23*(1/2) -> 0.09 | C23: ='UNGA Voting'!C23*(1/2)+'HeadofState Meetings'!C23*(1/2) -> 0.41911765 | D23: ='UNGA Voting'!D23*(1/2)+'HeadofState Meetings'!D23*(1/2) -> 0.32 | E23: ='UNGA Voting'!E23*(1/2)+'HeadofState Meetings'!E23*(1/2) -> 0.06 | F23: ='UNGA Voting'!F23*(1/2)+'HeadofState Meetings'!F23*(1/2) -> 0.43656715 | G23: ='UNGA Voting'!G23*(1/2)+'HeadofState Meetings'!G23*(1/2) -> 0.6792453 | H23: ='UNGA Voting'!H23*(1/2)+'HeadofState Meetings'!H23*(1/2) -> 0.4216418 | I23: ='UNGA Voting'!I23*(1/2)+'HeadofState Meetings'!I23*(1/2) -> 0.1764706 | ... AN23: ='UNGA Voting'!AN23*(1/2)+'HeadofState Meetings'!AN23*(1/2) -> 0.07
A24: 2013 | B24: ='UNGA Voting'!B24*(1/2)+'HeadofState Meetings'!B24*(1/2) -> 0.085 | C24: ='UNGA Voting'!C24*(1/2)+'HeadofState Meetings'!C24*(1/2) -> 0.1953125 | D24: ='UNGA Voting'!D24*(1/2)+'HeadofState Meetings'!D24*(1/2) -> 0.085 | E24: ='UNGA Voting'!E24*(1/2)+'HeadofState Meetings'!E24*(1/2) -> 0.07 | F24: ='UNGA Voting'!F24*(1/2)+'HeadofState Meetings'!F24*(1/2) -> 0.2142857 | G24: ='UNGA Voting'!G24*(1/2)+'HeadofState Meetings'!G24*(1/2) -> 0.2109375 | H24: ='UNGA Voting'!H24*(1/2)+'HeadofState Meetings'!H24*(1/2) -> 0.2063492 | I24: ='UNGA Voting'!I24*(1/2)+'HeadofState Meetings'!I24*(1/2) -> 0.1953125 | ... AN24: ='UNGA Voting'!AN24*(1/2)+'HeadofState Meetings'!AN24*(1/2) -> 0.065
A25: 2014 | B25: ='UNGA Voting'!B25*(1/2)+'HeadofState Meetings'!B25*(1/2) -> 0.105 | C25: ='UNGA Voting'!C25*(1/2)+'HeadofState Meetings'!C25*(1/2) -> 0.18382355 | D25: ='UNGA Voting'!D25*(1/2)+'HeadofState Meetings'!D25*(1/2) -> 0.1 | E25: ='UNGA Voting'!E25*(1/2)+'HeadofState Meetings'!E25*(1/2) -> 0.085 | F25: ='UNGA Voting'!F25*(1/2)+'HeadofState Meetings'!F25*(1/2) -> 0.69402985 | G25: ='UNGA Voting'!G25*(1/2)+'HeadofState Meetings'!G25*(1/2) -> 0.44117645 | H25: ='UNGA Voting'!H25*(1/2)+'HeadofState Meetings'!H25*(1/2) -> 0.4346154 | I25: ='UNGA Voting'!I25*(1/2)+'HeadofState Meetings'!I25*(1/2) -> 0.18382355 | ... AN25: ='UNGA Voting'!AN25*(1/2)+'HeadofState Meetings'!AN25*(1/2) -> 0.075
A26: 2015 | B26: ='UNGA Voting'!B26*(1/2)+'HeadofState Meetings'!B26*(1/2) -> 0.125 | C26: ='UNGA Voting'!C26*(1/2)+'HeadofState Meetings'!C26*(1/2) -> 0.19863015 | D26: ='UNGA Voting'!D26*(1/2)+'HeadofState Meetings'!D26*(1/2) -> 0.075 | E26: ='UNGA Voting'!E26*(1/2)+'HeadofState Meetings'!E26*(1/2) -> 0.08 | F26: ='UNGA Voting'!F26*(1/2)+'HeadofState Meetings'!F26*(1/2) -> 0.23972605 | G26: ='UNGA Voting'!G26*(1/2)+'HeadofState Meetings'!G26*(1/2) -> 0.2260274 | H26: ='UNGA Voting'!H26*(1/2)+'HeadofState Meetings'!H26*(1/2) -> 0.2328767 | I26: ='UNGA Voting'!I26*(1/2)+'HeadofState Meetings'!I26*(1/2) -> 0.2112676 | ... AN26: ='UNGA Voting'!AN26*(1/2)+'HeadofState Meetings'!AN26*(1/2) -> 0.085
A27: 2016
A28: 2017
A29: 2018
A32: Russia | B32: Armenia | C32: Austria | D32: Azerbaijan | E32: Belarus | F32: Belgium | G32: Bulgaria | H32: Croatia | I32: Cyprus | J32: Czech | K32: Denmark | L32: Estonia | M32: Finland | N32: France | O32: Georgia | P32: Germany | Q32: Greece | R32: Hungary | S32: Ireland | T32: Italy | U32: Kazakhstan | V32: Kyrgyzstan | W32: latvia | X32: Lithuania | Y32: Luxembourg | Z32: Malta | AA32: Moldova | AB32: Netherlands | AC32: Poland | AD32: Portugal | AE32: Romania | AF32: Slovakia | AG32: Slovenia | AH32: Spain | AI32: Sweden | AJ32: Tajikistan | AK32: Turkmenistan | AL32: Ukraine | AM32: UK | AN32: Uzbekistan
A33: 1991
A34: 1992
A35: 1993
A36: 1994
A37: 1995
A38: 1996
A39: 1997
A40: 1998
A41: 1999
A42: 2000
...

Sheet UNGA Voting
A1: US | B1: Armenia | C1: Austria | D1: Azerbaijan | E1: Belarus | F1: Belgium | G1: Bulgaria | H1: Croatia | I1: Cyprus | J1: Czech | K1: Denmark | L1: Estonia | M1: Finland | N1: France | O1: Georgia | P1: Germany | Q1: Greece | R1: Hungary | S1: Ireland | T1: Italy | U1: Kazakhstan | V1: Kyrgyzstan | W1: latvia | X1: Lithuania | Y1: Luxembourg | Z1: Malta | AA1: Moldova | AB1: Netherlands | AC1: Poland | AD1: Portugal | AE1: Romania | AF1: Slovakia | AG1: Slovenia | AH1: Spain | AI1: Sweden | AJ1: Tajikistan | AK1: Turkmenistan | AL1: Ukraine | AM1: UK | AN1: Uzbekistan
A2: 1991
A3: 1992 | B3: 0.31 | C3: 0.3013699 | D3: 0.23 | E3: 0.21 | F3: 0.369863 | G3: 0.3333333 | H3: 0.4411765 | I3: 0.1666667 | J3: NA | K3: 0.3287671 | L3: 0.2898551 | M3: 0.3013699 | N3: 0.3888889 | O3: NA | P3: 0.369863 | Q3: 0.2739726 | R3: 0.3521127 | S3: 0.2916667 | T3: 0.369863 | U3: 0.24 | V3: 0.2 | W3: 0.3142857 | X3: 0.3 | Y3: 0.369863 | Z3: 0.2916667 | AA3: 0.3 | AB3: 0.369863 | AC3: 0.3194444 | AD3: 0.3287671 | AE3: 0.3472222 | AF3: NA | AG3: 0.3508772 | AH3: 0.3013699 | AI3: 0.3013699 | AJ3: 0.1 | AK3: 0.21 | AL3: 0.23 | AM3: 0.5068493 | AN3: NA
A4: 1993 | B4: 0.25 | C4: 0.3650794 | D4: 0.22 | E4: 0.19 | F4: 0.40625 | G4: 0.3650794 | H4: 0.3902439 | I4: 0.1875 | J4: 0.40625 | K4: 0.375 | L4: 0.2881356 | M4: 0.359375 | N4: 0.483871 | O4: 0.33 | P4: 0.4375 | Q4: 0.328125 | R4: 0.3650794 | S4: 0.3492063 | T4: 0.40625 | U4: 0.21 | V4: 0.27 | W4: 0.3389831 | X4: 0.3275862 | Y4: 0.40625 | Z4: 0.3225806 | AA4: 0.35 | AB4: 0.421875 | AC4: 0.359375 | AD4: 0.390625 | AE4: 0.3606557 | AF4: 0.3650794 | AG4: 0.3278689 | AH4: 0.3650794 | AI4: 0.359375 | AJ4: 0.24 | AK4: 0.21 | AL4: 0.2 | AM4: 0.546875 | AN4: NA
A5: 1994 | B5: 0.31 | C5: 0.4117647 | D5: 0.3 | E5: 0.28 | F5: 0.4411765 | G5: 0.3880597 | H5: 0.3442623 | I5: 0.2941176 | J5: 0.4179104 | K5: 0.4411765 | L5: 0.328125 | M5: 0.4264706 | N5: 0.5757576 | O5: 0.34 | P5: 0.4477612 | Q5: 0.4117647 | R5: 0.4558824 | S5: 0.3823529 | T5: 0.4411765 | U5: 0.29 | V5: 0.27 | W5: 0.40625 | X5: 0.4137931 | Y5: 0.4411765 | Z5: 0.4117647 | AA5: 0.35 | AB5: 0.4477612 | AC5: 0.4117647 | AD5: 0.4411765 | AE5: 0.4029851 | AF5: 0.4262295 | AG5: 0.3787879 | AH5: 0.4264706 | AI5: 0.3823529 | AJ5: 0.32 | AK5: 0.29 | AL5: 0.3 | AM5: 0.641791 | AN5: 0.3
A6: 1995 | B6: 0.32 | C6: 0.382716 | D6: 0.25 | E6: 0.26 | F6: 0.4074074 | G6: 0.382716 | H6: 0.3421053 | I6: 0.2469136 | J6: 0.4 | K6: 0.4074074 | L6: 0.3815789 | M6: 0.3950617 | N6: 0.4556962 | O6: 0.51 | P6: 0.4197531 | Q6: 0.3580247 | R6: 0.4459459 | S6: 0.3703704 | T6: 0.4125 | U6: 0.28 | V6: 0.3 | W6: 0.4558824 | X6: 0.3875 | Y6: 0.4074074 | Z6: 0.345679 | AA6: 0.38 | AB6: 0.4197531 | AC6: 0.4177215 | AD6: 0.3950617 | AE6: 0.375 | AF6: 0.3950617 | AG6: 0.3846154 | AH6: 0.3950617 | AI6: 0.382716 | AJ6: 0.47 | AK6: 0.54 | AL6: 0.25 | AM6: 0.6666667 | AN6: 0.52
A7: 1996 | B7: 0.33 | C7: 0.4594595 | D7: 0.25 | E7: 0.27 | F7: 0.4794521 | G7: 0.4324324 | H7: 0.4492754 | I7: 0.3783784 | J7: 0.5 | K7: 0.5 | L7: 0.4444444 | M7: 0.5 | N7: 0.5342466 | O7: 0.34 | P7: 0.5 | Q7: 0.2142857 | R7: 0.5068493 | S7: 0.4459459 | T7: 0.5 | U7: 0.34 | V7: 0.29 | W7: 0.4782609 | X7: 0.4657534 | Y7: 0.5 | Z7: 0.3611111 | AA7: 0.41 | AB7: 0.5068493 | AC7: 0.4794521 | AD7: 0.4931507 | AE7: 0.4657534 | AF7: 0.4794521 | AG7: 0.4861111 | AH7: 0.4794521 | AI7: 0.472973 | AJ7: 0.37 | AK7: 0.5 | AL7: 0.33 | AM7: 0.6081081 | AN7: 0.41
A8: 1997 | B8: 0.32 | C8: 0.4637681 | D8: 0.28 | E8: 0.25 | F8: 0.4782609 | G8: 0.4264706 | H8: 0.4242424 | I8: 0.3478261 | J8: 0.4637681 | K8: 0.4782609 | L8: 0.4411765 | M8: 0.4637681 | N8: 0.5217391 | O8: 0.31 | P8: 0.4782609 | Q8: 0.4492754 | R8: 0.4626866 | S8: 0.4492754 | T8: 0.4782609 | U8: 0.29 | V8: 0.29 | W8: 0.4626866 | X8: 0.4347826 | Y8: 0.4852941 | Z8: 0.3382353 | AA8: 0.41 | AB8: 0.4927536 | AC8: 0.4637681 | AD8: 0.4637681 | AE8: 0.4347826 | AF8: 0.4347826 | AG8: 0.4411765 | AH8: 0.4637681 | AI8: 0.4782609 | AJ8: 0.33 | AK8: 0.3 | AL8: 0.3 | AM8: 0.5797101 | AN8: 0.51
A9: 1998 | B9: 0.2 | C9: 0.4098361 | D9: 0.24 | E9: 0.2 | F9: 0.4262295 | G9: 0.4333333 | H9: 0.3898305 | I9: 0.3114754 | J9: 0.4333333 | K9: 0.4098361 | L9: 0.4098361 | M9: 0.4098361 | N9: 0.4666667 | O9: 0.24 | P9: 0.4262295 | Q9: 0.4098361 | R9: 0.442623 | S9: 0.3934426 | T9: 0.4262295 | U9: 0.27 | V9: 0.24 | W9: 0.4237288 | X9: 0.4098361 | Y9: 0.4262295 | Z9: 0.3278689 | AA9: 0.37 | AB9: 0.4262295 | AC9: 0.4262295 | AD9: 0.4098361 | AE9: 0.4333333 | AF9: 0.4262295 | AG9: 0.4098361 | AH9: 0.4098361 | AI9: 0.4098361 | AJ9: 0.27 | AK9: 0.29 | AL9: 0.25 | AM9: 0.5245902 | AN9: 0.29
A10: 1999 | B10: 0.23 | C10: 0.3970588 | D10: 0.25 | E10: 0.17 | F10: 0.4264706 | G10: 0.4307692 | H10: 0.3787879 | I10: 0.3676471 | J10: 0.4117647 | K10: 0.4411765 | L10: 0.4264706 | M10: 0.4117647 | N10: 0.4705882 | O10: 0.32 | P10: 0.4558824 | Q10: 0.4117647 | R10: 0.4558824 | S10: 0.3823529 | T10: 0.4117647 | U10: 0.33 | V10: NA | W10: 0.3939394 | X10: 0.4117647 | Y10: 0.4264706 | Z10: 0.3970588 | AA10: 0.38 | AB10: 0.4411765 | AC10: 0.4264706 | AD10: 0.4117647 | AE10: 0.4264706 | AF10: 0.4117647 | AG10: 0.4179104 | AH10: 0.4117647 | AI10: 0.4117647 | AJ10: 0.2 | AK10: 0.31 | AL10: 0.28 | AM10: 0.5294118 | AN10: 0.33
A11: 2000 | B11: 0.23 | C11: 0.3939394 | D11: 0.24 | E11: 0.22 | F11: 0.4179104 | G11: 0.4029851 | H11: 0.358209 | I11: 0.3432836 | J11: 0.4179104 | K11: 0.4179104 | L11: 0.4126984 | M11: 0.4029851 | N11: 0.4179104 | O11: 0.34 | P11: 0.4179104 | Q11: 0.4029851 | R11: 0.4179104 | S11: 0.3731343 | T11: 0.3939394 | U11: 0.27 | V11: 0.21 | W11: 0.4153846 | X11: 0.4090909 | Y11: 0.4179104 | Z11: 0.3880597 | AA11: 0.39 | AB11: 0.4179104 | AC11: 0.4179104 | AD11: 0.4029851 | AE11: 0.4029851 | AF11: 0.4029851 | AG11: 0.4029851 | AH11: 0.4029851 | AI11: 0.3880597 | AJ11: 0.29 | AK11: 0.27 | AL11: 0.31 | AM11: 0.5074627 | AN11: 0.38
A12: 2001 | B12: 0.22 | C12: 0.358209 | D12: 0.13 | E12: 0.14 | F12: 0.3880597 | G12: 0.3787879 | H12: 0.3333333 | I12: 0.3283582 | J12: 0.3880597 | K12: 0.4029851 | L12: 0.3809524 | M12: 0.3731343 | N12: 0.4461538 | O12: 0.28 | P12: 0.3880597 | Q12: 0.3731343 | R12: 0.40625 | S12: 0.3432836 | T12: 0.3846154 | U12: 0.17 | V12: NA | W12: 0.3692308 | X12: 0.390625 | Y12: 0.3939394 | Z12: 0.3636364 | AA12: 0.35 | AB12: 0.3880597 | AC12: 0.3880597 | AD12: 0.3731343 | AE12: 0.3787879 | AF12: 0.358209 | AG12: 0.3846154 | AH12: 0.3731343 | AI12: 0.358209 | AJ12: NA | AK12: 0.13 | AL12: 0.27 | AM12: 0.4776119 | AN12: NA
A13: 2002 | B13: 0.17 | C13: 0.3055556 | D13: 0.11 | E13: 0.09 | F13: 0.3239437 | G13: 0.3239437 | H13: 0.2916667 | I13: 0.2916667 | J13: 0.3239437 | K13: 0.3239437 | L13: 0.3098592 | M13: 0.3055556 | N13: 0.3888889 | O13: 0.27 | P13: 0.3142857 | Q13: 0.3194444 | R13: 0.3239437 | S13: 0.2777778 | T13: 0.3472222 | U13: 0.18 | V13: 0.2 | W13: 0.3 | X13: 0.3055556 | Y13: 0.3194444 | Z13: 0.3055556 | AA13: 0.3 | AB13: 0.3239437 | AC13: 0.3333333 | AD13: 0.3382353 | AE13: 0.3239437 | AF13: 0.3194444 | AG13: 0.3055556 | AH13: 0.3333333 | AI13: 0.2916667 | AJ13: 0.15 | AK13: 0.08 | AL13: 0.22 | AM13: 0.4305556 | AN13: 0.18
A14: 2003 | B14: 0.19 | C14: 0.3289474 | D14: 0.14 | E14: 0.15 | F14: 0.3866667 | G14: 0.3684211 | H14: 0.3289474 | I14: 0.3157895 | J14: 0.3684211 | K14: 0.3815789 | L14: 0.36 | M14: 0.3684211 | N14: 0.4342105 | O14: 0.31 | P14: 0.3947368 | Q14: 0.3552632 | R14: 0.3684211 | S14: 0.3157895 | T14: 0.3815789 | U14: 0.18 | V14: 0.16 | W14: 0.3684211 | X14: 0.3947368 | Y14: 0.3947368 | Z14: 0.3421053 | AA14: 0.25 | AB14: 0.3815789 | AC14: 0.4054054 | AD14: 0.36 | AE14: 0.3513514 | AF14: 0.3552632 | AG14: 0.3466667 | AH14: 0.3552632 | AI14: 0.3552632 | AJ14: 0.22 | AK14: 0.1 | AL14: 0.22 | AM14: 0.4868421 | AN14: 0.21
A15: 2004 | B15: 0.16 | C15: 0.3521127 | D15: 0.12 | E15: 0.06 | F15: 0.3478261 | G15: 0.3521127 | H15: 0.3521127 | I15: 0.3380282 | J15: 0.3571429 | K15: 0.3661972 | L15: 0.3188406 | M15: 0.3521127 | N15: 0.4 | O15: 0.27 | P15: 0.3714286 | Q15: 0.3623188 | R15: 0.3571429 | S15: 0.3380282 | T15: 0.3571429 | U15: 0.12 | V15: 0.11 | W15: 0.3823529 | X15: 0.3521127 | Y15: 0.3478261 | Z15: 0.3428571 | AA15: 0.26 | AB15: 0.3521127 | AC15: 0.3857143 | AD15: 0.3661972 | AE15: 0.3521127 | AF15: 0.3661972 | AG15: 0.3661972 | AH15: 0.3521127 | AI15: 0.3380282 | AJ15: 0.11 | AK15: 0.02 | AL15: 0.2 | AM15: 0.4507042 | AN15: 0.1
A16: 2005 | B16: 0.14 | C16: 0.3150685 | D16: 0.1 | E16: 0.1 | F16: 0.3287671 | G16: 0.3287671 | H16: 0.3150685 | I16: 0.3013699 | J16: 0.3287671 | K16: 0.3424658 | L16: 0.3055556 | M16: 0.3287671 | N16: 0.3835616 | O16: 0.31 | P16: 0.3150685 | Q16: 0.3150685 | R16: 0.3287671 | S16: 0.3013699 | T16: 0.3194444 | U16: 0.14 | V16: 0.11 | W16: 0.3424658 | X16: 0.3287671 | Y16: 0.3287671 | Z16: 0.2876712 | AA16: 0.27 | AB16: 0.3424658 | AC16: 0.3287671 | AD16: 0.3150685 | AE16: 0.3287671 | AF16: 0.3287671 | AG16: 0.3287671 | AH16: 0.3150685 | AI16: 0.3150685 | AJ16: 0.07 | AK16: 0.07 | AL16: 0.21 | AM16: 0.4520548 | AN16: 0.08
A17: 2006 | B17: 0.09 | C17: 0.2298851 | D17: 0.08 | E17: 0.07 | F17: 0.244186 | G17: 0.2643678 | H17: 0.2413793 | I17: 0.2352941 | J17: 0.2758621 | K17: 0.2643678 | L17: 0.2413793 | M17: 0.2413793 | N17: 0.3218391 | O17: 0.24 | P17: 0.2528736 | Q17: 0.2528736 | R17: 0.2528736 | S17: 0.2298851 | T17: 0.2413793 | U17: 0.1 | V17: 0.06 | W17: 0.2643678 | X17: 0.2643678 | Y17: 0.2674419 | Z17: 0.2470588 | AA17: 0.27 | AB17: 0.2528736 | AC17: 0.255814 | AD17: 0.2643678 | AE17: 0.2470588 | AF17: 0.2470588 | AG17: 0.2528736 | AH17: 0.2643678 | AI17: 0.2298851 | AJ17: 0.06 | AK17: 0.07 | AL17: 0.25 | AM17: 0.3563218 | AN17: 0.07
A18: 2007 | B18: 0.12 | C18: 0.2727273 | D18: 0.07 | E18: 0.05 | F18: 0.2987013 | G18: 0.2857143 | H18: 0.2894737 | I18: 0.2857143 | J18: 0.3289474 | K18: 0.2987013 | L18: 0.2987013 | M18: 0.2857143 | N18: 0.4078947 | O18: 0.29 | P18: 0.2987013 | Q18: 0.2987013 | R18: 0.3380282 | S18: 0.2727273 | T18: 0.2987013 | U18: 0.09 | V18: 0.05 | W18: 0.3116883 | X18: 0.3116883 | Y18: 0.2987013 | Z18: 0.2727273 | AA18: 0.27 | AB18: 0.3116883 | AC18: 0.3116883 | AD18: 0.2987013 | AE18: 0.2857143 | AF18: 0.3116883 | AG18: 0.2987013 | AH18: 0.2857143 | AI18: 0.2857143 | AJ18: 0.03 | AK18: 0.04 | AL18: 0.31 | AM18: 0.3896104 | AN18: 0.07
A19: 2008 | B19: 0.11 | C19: 0.25 | D19: 0.07 | E19: 0.06 | F19: 0.2638889 | G19: 0.2676056 | H19: 0.2638889 | I19: 0.2638889 | J19: 0.2777778 | K19: 0.2816901 | L19: 0.2638889 | M19: 0.2638889 | N19: 0.3472222 | O19: 0.24 | P19: 0.2638889 | Q19: 0.2638889 | R19: 0.2638889 | S19: 0.25 | T19: 0.2638889 | U19: 0.11 | V19: 0.08 | W19: 0.2676056 | X19: 0.2638889 | Y19: 0.2676056 | Z19: 0.2535211 | AA19: 0.26 | AB19: 0.2816901 | AC19: 0.2777778 | AD19: 0.2638889 | AE19: 0.2777778 | AF19: 0.2638889 | AG19: 0.2676056 | AH19: 0.2638889 | AI19: 0.25 | AJ19: 0.06 | AK19: 0.08 | AL19: 0.28 | AM19: 0.3943662 | AN19: 0.06
A20: 2009 | B20: 0.18 | C20: 0.3880597 | D20: 0.11 | E20: 0.08 | F20: 0.4179104 | G20: 0.4242424 | H20: 0.3939394 | I20: 0.3880597 | J20: 0.4626866 | K20: 0.4477612 | L20: 0.4328358 | M20: 0.3880597 | N20: 0.4776119 | O20: 0.4 | P20: 0.4477612 | Q20: 0.4179104 | R20: 0.4242424 | S20: 0.3880597 | T20: 0.4328358 | U20: 0.15 | V20: 0.09 | W20: 0.4179104 | X20: 0.4328358 | Y20: 0.4242424 | Z20: 0.3880597 | AA20: 0.4 | AB20: 0.4626866 | AC20: 0.4626866 | AD20: 0.4029851 | AE20: 0.4179104 | AF20: 0.4477612 | AG20: 0.4029851 | AH20: 0.4029851 | AI20: 0.4029851 | AJ20: 0.08 | AK20: 0.08 | AL20: 0.41 | AM20: 0.5373134 | AN20: 0.1
A21: 2010 | B21: 0.16 | C21: 0.3484848 | D21: 0.11 | E21: 0.11 | F21: 0.3939394 | G21: 0.3846154 | H21: 0.3538462 | I21: 0.3484848 | J21: 0.3939394 | K21: 0.3939394 | L21: 0.3939394 | M21: 0.3636364 | N21: 0.469697 | O21: 0.34 | P21: 0.3939394 | Q21: 0.1428571 | R21: 0.3939394 | S21: 0.3484848 | T21: 0.3709677 | U21: 0.16 | V21: 0.16 | W21: 0.390625 | X21: 0.3939394 | Y21: 0.3787879 | Z21: 0.3484848 | AA21: 0.36 | AB21: 0.3939394 | AC21: 0.3846154 | AD21: 0.3787879 | AE21: 0.3636364 | AF21: 0.3787879 | AG21: 0.3787879 | AH21: 0.3636364 | AI21: 0.3636364 | AJ21: 0.15 | AK21: 0.13 | AL21: 0.35 | AM21: 0.5454545 | AN21: 0.11
A22: 2011 | B22: 0.24 | C22: 0.4615385 | D22: 0.19 | E22: 0.13 | F22: 0.5076923 | G22: 0.5 | H22: 0.5254237 | I22: 0.4769231 | J22: 0.5076923 | K22: 0.5076923 | L22: 0.5076923 | M22: 0.4769231 | N22: 0.5538462 | O22: 0.5 | P22: 0.4923077 | Q22: 0.4923077 | R22: 0.5076923 | S22: 0.4769231 | T22: 0.4923077 | U22: 0.26 | V22: 0.19 | W22: 0.5076923 | X22: 0.5076923 | Y22: 0.4923077 | Z22: 0.4615385 | AA22: 0.48 | AB22: 0.515625 | AC22: 0.5076923 | AD22: 0.4923077 | AE22: 0.484375 | AF22: 0.5076923 | AG22: 0.4923077 | AH22: 0.5076923 | AI22: 0.484375 | AJ22: 0.17 | AK22: 0.13 | AL22: 0.45 | AM22: 0.6 | AN22: 0.14
A23: 2012 | B23: 0.18 | C23: 0.3382353 | D23: 0.14 | E23: 0.12 | F23: 0.3731343 | G23: 0.3584906 | H23: 0.3432836 | I23: 0.3529412 | J23: 0.3970588 | K23: 0.3676471 | L23: 0.3731343 | M23: 0.3529412 | N23: 0.4852941 | O23: 0.31 | P23: 0.3676471 | Q23: 0.358209 | R23: 0.3676471 | S23: 0.3382353 | T23: 0.3676471 | U23: 0.17 | V23: 0.15 | W23: 0.358209 | X23: 0.3676471 | Y23: 0.3676471 | Z23: 0.3382353 | AA23: 0.35 | AB23: 0.3676471 | AC23: 0.3676471 | AD23: 0.3676471 | AE23: 0.3529412 | AF23: 0.3676471 | AG23: 0.3676471 | AH23: 0.3676471 | AI23: 0.3382353 | AJ23: 0.14 | AK23: 0.12 | AL23: 0.33 | AM23: 0.5396825 | AN23: 0.14
A24: 2013 | B24: 0.17 | C24: 0.390625 | D24: 0.17 | E24: 0.14 | F24: 0.4285714 | G24: 0.421875 | H24: 0.4126984 | I24: 0.390625 | J24: 0.46875 | K24: 0.4375 | L24: 0.4285714 | M24: 0.4375 | N24: 0.515625 | O24: 0.37 | P24: 0.4603175 | Q24: 0.4126984 | R24: 0.453125 | S24: 0.3968254 | T24: 0.4375 | U24: 0.16 | V24: 0.14 | W24: 0.4354839 | X24: 0.4375 | Y24: 0.4375 | Z24: 0.3809524 | AA24: 0.4 | AB24: 0.4375 | AC24: 0.4285714 | AD24: 0.4126984 | AE24: 0.40625 | AF24: 0.4375 | AG24: 0.421875 | AH24: 0.421875 | AI24: 0.40625 | AJ24: 0.12 | AK24: 0.09 | AL24: 0.39 | AM24: 0.59375 | AN24: 0.13
... A26: 2015 | B26: 0.25 | C26: 0.3972603 | D26: 0.15 | E26: 0.16 | F26: 0.4794521 | G26: 0.4520548 | H26: 0.4657534 | I26: 0.4225352 | J26: 0.5138889 | K26: 0.4794521 | L26: 0.5205479 | M26: 0.4383562 | N26: 0.5753425 | O26: 0.4 | P26: 0.5070423 | Q26: 0.4246575 | R26: 0.5068493 | S26: 0.3972603 | T26: 0.4794521 | U26: 0.21 | V26: 0.18 | W26: 0.5205479 | X26: 0.5068493 | Y26: 0.4794521 | Z26: 0.3888889 | AA26: 0.4 | AB26: 0.4794521 | AC26: 0.5205479 | AD26: 0.4383562 | AE26: 0.4657534 | AF26: 0.4794521 | AG26: 0.4657534 | AH26: 0.4861111 | AI26: 0.3972603 | AJ26: 0.19 | AK26: 0.12 | AL26: 0.46 | AM26: 0.630137 | AN26: 0.17
A27: 2016
A28: 2017
A29: 2018
A32: Russia | B32: Armenia | C32: Austria | D32: Azerbaijan | E32: Belarus | F32: Belgium | G32: Bulgaria | H32: Croatia | I32: Cyprus | J32: Czech | K32: Denmark | L32: Estonia | M32: Finland | N32: France | O32: Georgia | P32: Germany | Q32: Greece | R32: Hungary | S32: Ireland | T32: Italy | U32: Kazakhstan | V32: Kyrgyzstan | W32: latvia | X32: Lithuania | Y32: Luxembourg | Z32: Malta | AA32: Moldova | AB32: Netherlands | AC32: Poland | AD32: Portugal | AE32: Romania | AF32: Slovakia | AG32: Slovenia | AH32: Spain | AI32: Sweden | AJ32: Tajikistan | AK32: Turkmenistan | AL32: Ukraine | AM32: UK | AN32: Uzbekistan
A33: 1991
A34: 1992 | B34: 0.69 | C34: 0.7123288 | D34: 0.58 | E34: 0.66 | F34: 0.6986301 | G34: 0.7083333 | H34: 0.7647059 | I34: 0.4444444 | J34: NA | K34: 0.739726 | L34: 0.6666667 | M34: 0.7534247 | N34: 0.6527778 | O34: NA | P34: 0.6986301 | Q34: 0.6849315 | R34: 0.7183099 | S34: 0.7222222 | T34: 0.6986301 | U34: 0.73 | V34: 0.87 | W34: 0.6714286 | X34: 0.6857143 | Y34: 0.6986301 | Z34: 0.6666667 | AA34: 0.66 | AB34: 0.6986301 | AC34: 0.7083333 | AD34: 0.7123288 | AE34: 0.6805556 | AF34: NA | AG34: 0.7192982 | AH34: 0.6575342 | AI34: 0.739726 | AJ34: 0.71 | AK34: 0.79 | AL34: 0.66 | AM34: 0.5890411 | AN34: NA
A35: 1993 | B35: 0.67 | C35: 0.7142857 | D35: 0.53 | E35: 0.62 | F35: 0.6875 | G35: 0.6984127 | H35: 0.7804878 | I35: 0.46875 | J35: 0.71875 | K35: 0.75 | L35: 0.6779661 | M35: 0.6875 | N35: 0.5967742 | O35: 0.73 | P35: 0.703125 | Q35: 0.671875 | R35: 0.6984127 | S35: 0.7142857 | T35: 0.703125 | U35: 0.62 | V35: 0.64 | W35: 0.7288136 | X35: 0.7413793 | Y35: 0.703125 | Z35: 0.6451613 | AA35: 0.67 | AB35: 0.71875 | AC35: 0.734375 | AD35: 0.71875 | AE35: 0.7377049 | AF35: 0.7142857 | AG35: 0.704918 | AH35: 0.6666667 | AI35: 0.71875 | AJ35: 0.71 | AK35: 0.72 | AL35: 0.55 | AM35: 0.625 | AN35: NA
A36: 1994 | B36: 0.65 | C36: 0.6764706 | D36: 0.52 | E36: 0.74 | F36: 0.6617647 | G36: 0.6567164 | H36: 0.6721311 | I36: 0.5 | J36: 0.641791 | K36: 0.6911765 | L36: 0.671875 | M36: 0.6470588 | N36: 0.5 | O36: 0.74 | P36: 0.6567164 | Q36: 0.6617647 | R36: 0.6323529 | S36: 0.6617647 | T36: 0.6176471 | U36: 0.61 | V36: 0.44 | W36: 0.6875 | X36: 0.6551724 | Y36: 0.6617647 | Z36: 0.6323529 | AA36: 0.62 | AB36: 0.6567164 | AC36: 0.6323529 | AD36: 0.6617647 | AE36: 0.6268657 | AF36: 0.6393443 | AG36: 0.6666667 | AH36: 0.6470588 | AI36: 0.6764706 | AJ36: 0.78 | AK36: 0.58 | AL36: 0.67 | AM36: 0.5223881 | AN36: 0.61
A37: 1995 | B37: 0.76 | C37: 0.7160494 | D37: 0.65 | E37: 0.72 | F37: 0.5679012 | G37: 0.7530864 | H37: 0.7368421 | I37: 0.6049383 | J37: 0.7375 | K37: 0.7160494 | L37: 0.75 | M37: 0.7037037 | N37: 0.5189873 | O37: 0.62 | P37: 0.7283951 | Q37: 0.5802469 | R37: 0.7432432 | S37: 0.7160494 | T37: 0.725 | U37: 0.7 | V37: 0.5 | W37: 0.5735294 | X37: 0.75 | Y37: 0.7037037 | Z37: 0.6790123 | AA37: 0.74 | AB37: 0.691358 | AC37: 0.7594937 | AD37: 0.7283951 | AE37: 0.7625 | AF37: 0.7407407 | AG37: 0.7435897 | AH37: 0.7407407 | AI37: 0.7160494 | AJ37: 0.75 | AK37: 0.85 | AL37: 0.69 | AM37: 0.4938272 | AN37: 0.65
A38: 1996 | B38: 0.72 | C38: 0.6712329 | D38: 0.7 | E38: 0.74 | F38: 0.7083333 | G38: 0.6575342 | H38: 0.6764706 | I38: 0.6712329 | J38: 0.6712329 | K38: 0.6712329 | L38: 0.6056338 | M38: 0.6849315 | N38: 0.7083333 | O38: 0.7 | P38: 0.6986301 | Q38: 0.7857143 | R38: 0.6944444 | S38: 0.6712329 | T38: 0.6849315 | U38: 0.75 | V38: 0.68 | W38: 0.6764706 | X38: 0.6111111 | Y38: 0.7123288 | Z38: 0.6619718 | AA38: 0.63 | AB38: 0.6944444 | AC38: 0.6944444 | AD38: 0.6805556 | AE38: 0.6944444 | AF38: 0.6805556 | AG38: 0.6760563 | AH38: 0.6666667 | AI38: 0.6575342 | AJ38: 0.71 | AK38: 0.5 | AL38: 0.68 | AM38: 0.6712329 | AN38: 0.55
A39: 1997 | B39: 0.76 | C39: 0.6956522 | D39: 0.8 | E39: 0.72 | F39: 0.7246377 | G39: 0.6470588 | H39: 0.6818182 | I39: 0.6956522 | J39: 0.6956522 | K39: 0.7101449 | L39: 0.6617647 | M39: 0.6956522 | N39: 0.6811594 | O39: 0.75 | P39: 0.7246377 | Q39: 0.6956522 | R39: 0.7164179 | S39: 0.6956522 | T39: 0.7101449 | U39: 0.75 | V39: 0.69 | W39: 0.6865672 | X39: 0.6811594 | Y39: 0.7058824 | Z39: 0.6911765 | AA39: 0.73 | AB39: 0.7246377 | AC39: 0.7101449 | AD39: 0.7101449 | AE39: 0.6811594 | AF39: 0.6956522 | AG39: 0.7058824 | AH39: 0.7101449 | AI39: 0.6956522 | AJ39: 0.71 | AK39: 0.7 | AL39: 0.74 | AM39: 0.6521739 | AN39: 0.49
A40: 1998 | B40: 0.69 | C40: 0.6833333 | D40: 0.7 | E40: 0.75 | F40: 0.7166667 | G40: 0.7118644 | H40: 0.6949153 | I40: 0.6833333 | J40: 0.7288136 | K40: 0.6833333 | L40: 0.7166667 | M40: 0.7 | N40: 0.6949153 | O40: 0.75 | P40: 0.7166667 | Q40: 0.7 | R40: 0.7333333 | S40: 0.6833333 | T40: 0.7 | U40: 0.73 | V40: 0.67 | W40: 0.6896552 | X40: 0.7 | Y40: 0.7166667 | Z40: 0.7166667 | AA40: 0.67 | AB40: 0.7166667 | AC40: 0.7166667 | AD40: 0.7 | AE40: 0.7118644 | AF40: 0.7166667 | AG40: 0.7 | AH40: 0.7 | AI40: 0.6833333 | AJ40: 0.63 | AK40: 0.67 | AL40: 0.67 | AM40: 0.6666667 | AN40: 0.49
A41: 1999 | B41: 0.72 | C41: 0.6764706 | D41: 0.7 | E41: 0.77 | F41: 0.6764706 | G41: 0.7076923 | H41: 0.6969697 | I41: 0.6911765 | J41: 0.6911765 | K41: 0.6911765 | L41: 0.6764706 | M41: 0.6764706 | N41: 0.6617647 | O41: 0.65 | P41: 0.6764706 | Q41: 0.6911765 | R41: 0.6911765 | S41: 0.7058824 | T41: 0.6911765 | U41: 0.75 | V41: NA | W41: 0.6363636 | X41: 0.6764706 | Y41: 0.6764706 | Z41: 0.6617647 | AA41: 0.71 | AB41: 0.6764706 | AC41: 0.7058824 | AD41: 0.6911765 | AE41: 0.7058824 | AF41: 0.6911765 | AG41: 0.6865672 | AH41: 0.6911765 | AI41: 0.6911765 | AJ41: 0.74 | AK41: 0.72 | AL41: 0.7 | AM41: 0.6323529 | AN41: 0.52
A42: 2000 | B42: 0.78 | C42: 0.6515152 | D42: 0.77 | E42: 0.77 | F42: 0.6515152 | G42: 0.6818182 | H42: 0.6363636 | I42: 0.6818182 | J42: 0.6666667 | K42: 0.6666667 | L42: 0.6190476 | M42: 0.6363636 | N42: 0.6363636 | O42: 0.66 | P42: 0.6515152 | Q42: 0.6666667 | R42: 0.6515152 | S42: 0.6969697 | T42: 0.6615385 | U42: 0.75 | V42: 0.84 | W42: 0.625 | X42: 0.6461538 | Y42: 0.6515152 | Z42: 0.6363636 | AA42: 0.67 | AB42: 0.6515152 | AC42: 0.6666667 | AD42: 0.6818182 | AE42: 0.6666667 | AF42: 0.6666667 | AG42: 0.6666667 | AH42: 0.6969697 | AI42: 0.6666667 | AJ42: 0.74 | AK42: 0.68 | AL42: 0.7 | AM42: 0.5909091 | AN42: 0.62
A43: 2001 | B43: 0.76 | C43: 0.6515152 | D43: 0.8 | E43: 0.84 | F43: 0.6515152 | G43: 0.6515152 | H43: 0.6923077 | I43: 0.6515152 | J43: 0.6515152 | K43: 0.6515152 | L43: 0.6190476 | M43: 0.6363636 | N43: 0.578125 | O43: 0.66 | P43: 0.6363636 | Q43: 0.6515152 | R43: 0.640625 | S43: 0.6969697 | T43: 0.65625 | U43: 0.84 | V43: NA | W43: 0.6153846 | X43: 0.65625 | Y43: 0.6461538 | Z43: 0.6212121 | AA43: 0.68 | AB43: 0.6363636 | AC43: 0.6515152 | AD43: 0.6666667 | AE43: 0.6615385 | AF43: 0.6666667 | AG43: 0.65625 | AH43: 0.6818182 | AI43: 0.6818182 | AJ43: NA | AK43: 0.75 | AL43: 0.71 | AM43: 0.5757576 | AN43: NA
...

Sheet HeadofState Meetings
A1: US | B1: Armenia | C1: Austria | D1: Azerbaijan | E1: Belarus | F1: Belgium | G1: Bulgaria | H1: Croatia | I1: Cyprus | J1: Czech | K1: Denmark | L1: Estonia | M1: Finland | N1: France | O1: Georgia | P1: Germany | Q1: Greece | R1: Hungary | S1: Ireland | T1: Italy | U1: Kazakhstan | V1: Kyrgyzstan | W1: latvia | X1: Lithuania | Y1: Luxembourg | Z1: Malta | AA1: Moldova | AB1: Netherlands | AC1: Poland | AD1: Portugal | AE1: Romania | AF1: Slovakia | AG1: Slovenia | AH1: Spain | AI1: Sweden | AJ1: Tajikistan | AK1: Turkmenistan | AL1: Ukraine | AM1: UK | AN1: Uzbekistan
A2: 1991 | B2: 0 | C2: 0.5 | D2: 0 | E2: 0 | F2: 0 | G2: 0 | H2: 0 | I2: 0.5 | J2: 0 | K2: 0.5 | L2: 0 | M2: 0.5 | N2: 1 | O2: 0 | P2: 1 | Q2: 1 | R2: 1 | S2: 0 | T2: 1 | U2: 0 | V2: 0 | W2: 0 | X2: 0 | Y2: 0 | Z2: 0 | AA2: 0 | AB2: 0.5 | AC2: 0 | AD2: 0 | AE2: 0 | AF2: 0 | AG2: 0 | AH2: 1 | AI2: 0 | AJ2: 0 | AK2: 0 | AL2: 0 | AM2: 1 | AN2: 0
A3: 1992 | B3: 0 | C3: 0.5 | D3: 0 | E3: 0 | F3: 0.5 | G3: 0.5 | H3: 0 | I3: 0.5 | J3: 0 | K3: 0 | L3: 0 | M3: 1 | N3: 0.5 | O3: 0 | P3: 1 | Q3: 0.5 | R3: 0 | S3: 0 | T3: 0.5 | U3: 0.5 | V3: 0 | W3: 0 | X3: 0 | Y3: 0 | Z3: 0 | AA3: 0.5 | AB3: 0 | AC3: 1 | AD3: 0 | AE3: 0 | AF3: 0 | AG3: 0 | AH3: 0.5 | AI3: 0.5 | AJ3: 0 | AK3: 0 | AL3: 0.5 | AM3: 1 | AN3: 0
A4: 1993 | B4: 0 | C4: 0 | D4: 0 | E4: 0 | F4: 0 | G4: 0.5 | H4: 0.5 | I4: 0.5 | J4: 0.5 | K4: 0.5 | L4: 0.5 | M4: 0 | N4: 1 | O4: 0 | P4: 1 | Q4: 0 | R4: 0.5 | S4: 0.5 | T4: 0 | U4: 0 | V4: 0 | W4: 0.5 | X4: 0.5 | Y4: 0 | Z4: 0 | AA4: 0.5 | AB4: 0 | AC4: 1 | AD4: 0.5 | AE4: 0.5 | AF4: 0.5 | AG4: 0.5 | AH4: 1 | AI4: 0.5 | AJ4: 0 | AK4: 0 | AL4: 0 | AM4: 0.5 | AN4: 0
A5: 1994 | B5: 0.5 | C5: 0.5 | D5: 0.5 | E5: 0 | F5: 0.5 | G5: 0 | H5: 0.5 | I5: 0 | J5: 0.5 | K5: 0.5 | L5: 0 | M5: 0.5 | N5: 1 | O5: 0.5 | P5: 1 | Q5: 1 | R5: 1 | S5: 0.5 | T5: 1 | U5: 0.5 | V5: 0 | W5: 1 | X5: 0.5 | Y5: 0.5 | Z5: 0 | AA5: 0 | AB5: 1 | AC5: 1 | AD5: 1 | AE5: 0 | AF5: 0.5 | AG5: 0 | AH5: 0.5 | AI5: 0 | AJ5: 0 | AK5: 0 | AL5: 1 | AM5: 1 | AN5: 0
A6: 1995 | B6: 0 | C6: 0.5 | D6: 0 | E6: 0 | F6: 0.5 | G6: 0.5 | H6: 1 | I6: 0 | J6: 1 | K6: 0 | L6: 0 | M6: 0 | N6: 1 | O6: 0 | P6: 1 | Q6: 0 | R6: 0 | S6: 1 | T6: 0.5 | U6: 0 | V6: 0 | W6: 0 | X6: 0 | Y6: 0.5 | Z6: 0 | AA6: 0.5 | AB6: 0.5 | AC6: 0 | AD6: 0.5 | AE6: 0.5 | AF6: 0.5 | AG6: 0.5 | AH6: 0.5 | AI6: 0 | AJ6: 0 | AK6: 0 | AL6: 0.5 | AM6: 1 | AN6: 0
A7: 1996 | B7: 0 | C7: 0 | D7: 0 | E7: 0 | F7: 0 | G7: 0 | H7: 1 | I7: 0.5 | J7: 0.5 | K7: 0 | L7: 0.5 | M7: 0 | N7: 1 | O7: 0 | P7: 0.5 | Q7: 1 | R7: 0.5 | S7: 1 | T7: 1 | U7: 0 | V7: 0 | W7: 0.5 | X7: 0.5 | Y7: 0 | Z7: 0 | AA7: 0 | AB7: 0 | AC7: 0.5 | AD7: 0 | AE7: 0 | AF7: 0 | AG7: 0 | AH7: 0 | AI7: 0.5 | AJ7: 0 | AK7: 0 | AL7: 0.5 | AM7: 0 | AN7: 0.5
A8: 1997 | B8: 0 | C8: 0.5 | D8: 0.5 | E8: 0 | F8: 0.5 | G8: 0.5 | H8: 0 | I8: 0 | J8: 0.5 | K8: 1 | L8: 0.5 | M8: 1 | N8: 1 | O8: 0.5 | P8: 1 | Q8: 0.5 | R8: 0.5 | S8: 1 | T8: 1 | U8: 0.5 | V8: 0 | W8: 0.5 | X8: 0.5 | Y8: 1 | Z8: 0 | AA8: 0 | AB8: 1 | AC8: 1 | AD8: 1 | AE8: 1 | AF8: 0.5 | AG8: 0.5 | AH8: 0.5 | AI8: 0 | AJ8: 0 | AK8: 0 | AL8: 0.5 | AM8: 1 | AN8: 0
A9: 1998 | B9: 0 | C9: 0.5 | D9: 0 | E9: 0 | F9: 0 | G9: 1 | H9: 0 | I9: 0 | J9: 0.5 | K9: 0 | L9: 0.5 | M9: 0 | N9: 0.5 | O9: 0 | P9: 1 | Q9: 0 | R9: 1 | S9: 1 | T9: 1 | U9: 0 | V9: 0 | W9: 0.5 | X9: 0.5 | Y9: 0 | Z9: 0 | AA9: 0 | AB9: 0 | AC9: 0.5 | AD9: 0 | AE9: 0.5 | AF9: 0 | AG9: 0.5 | AH9: 0 | AI9: 0 | AJ9: 0 | AK9: 0.5 | AL9: 0 | AM9: 1 | AN9: 0
A10: 1999 | B10: 0.5 | C10: 0.5 | D10: 0.5 | E10: 0 | F10: 1 | G10: 1 | H10: 0 | I10: 0 | J10: 1 | K10: 1 | L10: 0.5 | M10: 0.5 | N10: 1 | O10: 1 | P10: 1 | Q10: 1 | R10: 1 | S10: 0.5 | T10: 1 | U10: 1 | V10: 0 | W10: 0.5 | X10: 0.5 | Y10: 0.5 | Z10: 0 | AA10: 0.5 | AB10: 0.5 | AC10: 1 | AD10: 0.5 | AE10: 0.5 | AF10: 1 | AG10: 1 | AH10: 0.5 | AI10: 0.5 | AJ10: 0.5 | AK10: 0 | AL10: 1 | AM10: 0.5 | AN10: 0.5
A11: 2000 | B11: 0.5 | C11: 0 | D11: 0.5 | E11: 0 | F11: 0 | G11: 0 | H11: 0.5 | I11: 0 | J11: 0 | K11: 0 | L11: 0 | M11: 0.5 | N11: 1 | O11: 0 | P11: 0.5 | Q11: 0 | R11: 0 | S11: 1 | T11: 1 | U11: 0 | V11: 0 | W11: 0 | X11: 0 | Y11: 0 | Z11: 0 | AA11: 0 | AB11: 0.5 | AC11: 0 | AD11: 0.5 | AE11: 0 | AF11: 0 | AG11: 0 | AH11: 0.5 | AI11: 0 | AJ11: 0 | AK11: 0 | AL11: 0.5 | AM11: 1 | AN11: 0
A12: 2001 | B12: 0.5 | C12: 0.5 | D12: 0.5 | E12: 0 | F12: 1 | G12: 0 | H12: 0 | I12: 0 | J12: 1 | K12: 0.5 | L12: 0 | M12: 0 | N12: 1 | O12: 0.5 | P12: 1 | Q12: 0.5 | R12: 0.5 | S12: 1 | T12: 1 | U12: 0.5 | V12: 0 | W12: 0 | X12: 0 | Y12: 0.5 | Z12: 0 | AA12: 0 | AB12: 0.5 | AC12: 1 | AD12: 0.5 | AE12: 0.5 | AF12: 0 | AG12: 0 | AH12: 1 | AI12: 1 | AJ12: 0 | AK12: 0 | AL12: 0 | AM12: 1 | AN12: 0
A13: 2002 | B13: 0 | C13: 0 | D13: 0 | E13: 0 | F13: 0.5 | G13: 0.5 | H13: 0.5 | I13: 0 | J13: 1 | K13: 1 | L13: 0.5 | M13: 1 | N13: 1 | O13: 0 | P13: 1 | Q13: 1 | R13: 1 | S13: 0.5 | T13: 1 | U13: 0 | V13: 0.5 | W13: 0.5 | X13: 1 | Y13: 1 | Z13: 0 | AA13: 0.5 | AB13: 0.5 | AC13: 1 | AD13: 1 | AE13: 0.5 | AF13: 0.5 | AG13: 1 | AH13: 1 | AI13: 0 | AJ13: 0.5 | AK13: 0 | AL13: 0 | AM13: 1 | AN13: 0.5
... A29: 2018 | B29: 0 | C29: 0 | D29: 0 | E29: 0 | F29: 0.5 | G29: 0.5 | H29: 0.5 | I29: 0 | J29: 0.5 | K29: 0.5 | L29: 0.5 | M29: 0.5 | N29: 0.5 | O29: 0 | P29: 0.5 | Q29: 0.5 | R29: 0.5 | S29: 0 | T29: 0.5 | U29: 0 | V29: 0 | W29: 0.5 | X29: 0.5 | Y29: 0.5 | Z29: 0 | AA29: 0 | AB29: 0.5 | AC29: 0.5 | AD29: 0.5 | AE29: 0.5 | AF29: 0.5 | AG29: 0.5 | AH29: 0.5 | AI29: 0 | AJ29: 0 | AK29: 0 | AL29: 0 | AM29: 0.5 | AN29: 0
A32: Russia | B32: Armenia | C32: Austria | D32: Azerbaijan | E32: Belarus | F32: Belgium | G32: Bulgaria | H32: Croatia | I32: Cyprus | J32: Czech | K32: Denmark | L32: Estonia | M32: Finland | N32: France | O32: Georgia | P32: Germany | Q32: Greece | R32: Hungary | S32: Ireland | T32: Italy | U32: Kazakhstan | V32: Kyrgyzstan | W32: latvia | X32: Lithuania | Y32: Luxembourg | Z32: Malta | AA32: Moldova | AB32: Netherlands | AC32: Poland | AD32: Portugal | AE32: Romania | AF32: Slovakia | AG32: Slovenia | AH32: Spain | AI32: Sweden | AJ32: Tajikistan | AK32: Turkmenistan | AL32: Ukraine | AM32: UK | AN32: Uzbekistan
A33: 1991
A34: 1992
A35: 1993
A36: 1994
A37: 1995
A38: 1996
A39: 1997
A40: 1998
A41: 1999
A42: 2000 | B42: 1 | C42: 0 | D42: 1 | E42: 1 | F42: 0.5 | G42: 0 | H42: 0 | I42: 0.5 | J42: 0 | K42: 0 | L42: 0 | M42: 0.5 | N42: 1 | O42: 1 | P42: 1 | Q42: 0.5 | R42: 0 | S42: 0 | T42: 1 | U42: 1 | V42: 1 | W42: 0 | X42: 0 | Y42: 0 | Z42: 0 | AA42: 1 | AB42: 0 | AC42: 0.5 | AD42: 0 | AE42: 0 | AF42: 0 | AG42: 0 | AH42: 0.5 | AI42: 0.5 | AJ42: 1 | AK42: 1 | AL42: 1 | AM42: 1 | AN42: 1
A43: 2001 | B43: 1 | C43: 0.5 | D43: 1 | E43: 1 | F43: 0.5 | G43: 0 | H43: 0 | I43: 0 | J43: 0 | K43: 0 | L43: 0 | M43: 0.5 | N43: 1 | O43: 1 | P43: 1 | Q43: 0.5 | R43: 0 | S43: 0 | T43: 0.5 | U43: 1 | V43: 1 | W43: 0.5 | X43: 0.5 | Y43: 0 | Z43: 0 | AA43: 1 | AB43: 0.5 | AC43: 1 | AD43: 0.5 | AE43: 0 | AF43: 1 | AG43: 1 | AH43: 0.5 | AI43: 0.5 | AJ43: 1 | AK43: 0 | AL43: 1 | AM43: 1 | AN43: 1
A44: 2002 | B44: 1 | C44: 0 | D44: 1 | E44: 1 | F44: 0.5 | G44: 0.5 | H44: 0.5 | I44: 0 | J44: 0 | K44: 0.5 | L44: 0 | M44: 1 | N44: 1 | O44: 1 | P44: 1 | Q44: 0 | R44: 0.5 | S44: 0 | T44: 0.5 | U44: 1 | V44: 1 | W44: 0 | X44: 0 | Y44: 0.5 | Z44: 0 | AA44: 1 | AB44: 0 | AC44: 1 | AD44: 0 | AE44: 0 | AF44: 0.5 | AG44: 0.5 | AH44: 0.5 | AI44: 0.5 | AJ44: 1 | AK44: 1 | AL44: 1 | AM44: 1 | AN44: 1
A45: 2003 | B45: 1 | C45: 0 | D45: 0 | E45: 1 | F45: 0 | G45: 1 | H45: 0.5 | I45: 0 | J45: 0.5 | K45: 0 | L45: 0.5 | M45: 0 | N45: 1 | O45: 0.5 | P45: 1 | Q45: 0 | R45: 0.5 | S45: 0 | T45: 1 | U45: 1 | V45: 1 | W45: 0 | X45: 0 | Y45: 0 | Z45: 0 | AA45: 1 | AB45: 0 | AC45: 0.5 | AD45: 0 | AE45: 0.5 | AF45: 0 | AG45: 0 | AH45: 0 | AI45: 0 | AJ45: 1 | AK45: 0.5 | AL45: 1 | AM45: 1 | AN45: 1
A46: 2004 | B46: 1 | C46: 0.5 | D46: 1 | E46: 1 | F46: 0 | G46: 0.5 | H46: 0 | I46: 0 | J46: 0 | K46: 0 | L46: 0 | M46: 0.5 | N46: 1 | O46: 0.5 | P46: 1 | Q46: 0.5 | R46: 0 | S46: 0 | T46: 0 | U46: 1 | V46: 1 | W46: 0 | X46: 0 | Y46: 0.5 | Z46: 0 | AA46: 0.5 | AB46: 0.5 | AC46: 0.5 | AD46: 0.5 | AE46: 0 | AF46: 0 | AG46: 0 | AH46: 0 | AI46: 0 | AJ46: 1 | AK46: 0 | AL46: 1 | AM46: 0.5 | AN46: 1
A47: 2005 | B47: 1 | C47: 0 | D47: 1 | E47: 1 | F47: 0.5 | G47: 0 | H47: 0 | I47: 0 | J47: 0 | K47: 0 | L47: 0.5 | M47: 1 | N47: 1 | O47: 0 | P47: 1 | Q47: 0.5 | R47: 0 | S47: 0 | T47: 0 | U47: 1 | V47: 1 | W47: 0 | X47: 0 | Y47: 0 | Z47: 0 | AA47: 0 | AB47: 0.5 | AC47: 0.5 | AD47: 0 | AE47: 0.5 | AF47: 0.5 | AG47: 0 | AH47: 0.5 | AI47: 0 | AJ47: 1 | AK47: 0 | AL47: 1 | AM47: 1 | AN47: 1
A48: 2006 | B48: 1 | C48: 0 | D48: 1 | E48: 1 | F48: 0 | G48: 0.5 | H48: 0 | I48: 0.5 | J48: 0.5 | K48: 0 | L48: 0 | M48: 1 | N48: 1 | O48: 0.5 | P48: 1 | Q48: 0.5 | R48: 1 | S48: 0 | T48: 0 | U48: 1 | V48: 1 | W48: 0 | X48: 0 | Y48: 0 | Z48: 0 | AA48: 1 | AB48: 0 | AC48: 0 | AD48: 0 | AE48: 0 | AF48: 0.5 | AG48: 0 | AH48: 1 | AI48: 0 | AJ48: 0 | AK48: 0.5 | AL48: 1 | AM48: 0.5 | AN48: 1
A49: 2007 | B49: 1 | C49: 0.5 | D49: 1 | E49: 0.5 | F49: 1 | G49: 0.5 | H49: 0.5 | I49: 0 | J49: 0.5 | K49: 0 | L49: 0 | M49: 0 | N49: 0.5 | O49: 0.5 | P49: 1 | Q49: 0.5 | R49: 0.5 | S49: 0 | T49: 0.5 | U49: 1 | V49: 1 | W49: 0 | X49: 0 | Y49: 0.5 | Z49: 0 | AA49: 1 | AB49: 0.5 | AC49: 0 | AD49: 0.5 | AE49: 0 | AF49: 0 | AG49: 0 | AH49: 0 | AI49: 0 | AJ49: 0.5 | AK49: 1 | AL49: 1 | AM49: 0 | AN49: 1
A50: 2008 | B50: 1 | C50: 0 | D50: 1 | E50: 1 | F50: 0 | G50: 0.5 | H50: 0 | I50: 0.5 | J50: 0 | K50: 0 | L50: 0.5 | M50: 0.5 | N50: 1 | O50: 1 | P50: 1 | Q50: 1 | R50: 0 | S50: 0 | T50: 1 | U50: 1 | V50: 1 | W50: 0 | X50: 0 | Y50: 0.5 | Z50: 0 | AA50: 1 | AB50: 0 | AC50: 0 | AD50: 0.5 | AE50: 0.5 | AF50: 0 | AG50: 0.5 | AH50: 0.5 | AI50: 0 | AJ50: 1 | AK50: 1 | AL50: 1 | AM50: 0.5 | AN50: 1
A51: 2009 | B51: 1 | C51: 0.5 | D51: 1 | E51: 1 | F51: 0 | G51: 0.5 | H51: 0.5 | I51: 0 | J51: 1 | K51: 1 | L51: 0 | M51: 1 | N51: 0.5 | O51: 0 | P51: 1 | Q51: 0 | R51: 0.5 | S51: 0 | T51: 1 | U51: 1 | V51: 1 | W51: 0 | X51: 0 | Y51: 0 | Z51: 0 | AA51: 1 | AB51: 0.5 | AC51: 0 | AD51: 0 | AE51: 0 | AF51: 0 | AG51: 0.5 | AH51: 0.5 | AI51: 0.5 | AJ51: 1 | AK51: 1 | AL51: 0 | AM51: 1 | AN51: 1
A52: 2010 | B52: 1 | C52: 0 | D52: 1 | E52: 1 | F52: 0.5 | G52: 0 | H52: 0 | I52: 0.5 | J52: 0.5 | K52: 0.5 | L52: 0 | M52: 1 | N52: 1 | O52: 0 | P52: 1 | Q52: 0.5 | R52: 0 | S52: 0.5 | T52: 0.5 | U52: 1 | V52: 1 | W52: 0.5 | X52: 0 | Y52: 0.5 | Z52: 0 | AA52: 0.5 | AB52: 0 | AC52: 1 | AD52: 0.5 | AE52: 0 | AF52: 0.5 | AG52: 0.5 | AH52: 0 | AI52: 0.5 | AJ52: 1 | AK52: 1 | AL52: 1 | AM52: 0.5 | AN52: 1
A53: 2011 | B53: 1 | C53: 0.5 | D53: 1 | E53: 1 | F53: 1 | G53: 0 | H53: 0 | I53: 0 | J53: 0.5 | K53: 0 | L53: 0 | M53: 0.5 | N53: 1 | O53: 0 | P53: 1 | Q53: 0 | R53: 0 | S53: 0 | T53: 0.5 | U53: 1 | V53: 1 | W53: 0 | X53: 0 | Y53: 0 | Z53: 0 | AA53: 0.5 | AB53: 0.5 | AC53: 0.5 | AD53: 0 | AE53: 0 | AF53: 0 | AG53: 0.5 | AH53: 0.5 | AI53: 0 | AJ53: 1 | AK53: 1 | AL53: 1 | AM53: 1 | AN53: 1
... A60: 2018 | B60: 0.5 | C60: 0.5 | D60: 1 | E60: 1 | F60: 0.5 | G60: 0.5 | H60: 0.5 | I60: 0 | J60: 0 | K60: 0 | L60: 0 | M60: 1 | N60: 1 | O60: 0 | P60: 1 | Q60: 0.5 | R60: 1 | S60: 0 | T60: 0.5 | U60: 1 | V60: 1 | W60: 0 | X60: 0 | Y60: 0 | Z60: 0 | AA60: 1 | AB60: 0 | AC60: 0 | AD60: 0.5 | AE60: 0 | AF60: 0 | AG60: 0 | AH60: 0 | AI60: 0 | AJ60: 1 | AK60: 0.5 | AL60: 0 | AM60: 0 | AN60: 1
A63: China | B63: Armenia | C63: Austria | D63: Azerbaijan | E63: Belarus | F63: Belgium | G63: Bulgaria | H63: Croatia | I63: Cyprus | J63: Czech | K63: Denmark | L63: Estonia | M63: Finland | N63: France | O63: Georgia | P63: Germany | Q63: Greece | R63: Hungary | S63: Ireland | T63: Italy | U63: Kazakhstan | V63: Kyrgyzstan | W63: latvia | X63: Lithuania | Y63: Luxembourg | Z63: Malta | AA63: Moldova | AB63: Netherlands | AC63: Poland | AD63: Portugal | AE63: Romania | AF63: Slovakia | AG63: Slovenia | AH63: Spain | AI63: Sweden | AJ63: Tajikistan | AK63: Turkmenistan | AL63: Ukraine | AM63: UK | AN63: Uzbekistan
A64: 1991
A65: 1992
...
